Workbook
Name LIST_CATEGORY: '08_Lists_Config'!$B$6:$B$15
Name LIST_TOPIC_STATUS: '08_Lists_Config'!$C$6:$C$8
Name LIST_PRIORITY: '08_Lists_Config'!$D$6:$D$9
Name LIST_YESNO: '08_Lists_Config'!$E$6:$E$7
Name LIST_ACTION_STATUS: '08_Lists_Config'!$F$6:$F$12
Name LIST_PQCP_STATUS: '08_Lists_Config'!$G$6:$G$12
Name LIST_EVIDENCE_AVAIL: '08_Lists_Config'!$H$6:$H$8
Name LIST_DOC_TYPE: '08_Lists_Config'!$I$6:$I$16
Name LIST_DOC_STATUS: '08_Lists_Config'!$J$6:$J$10
Name LIST_APPROVED: '08_Lists_Config'!$K$6:$K$8
Name DUE_SOON_DAYS: '08_Lists_Config'!$C$21

Sheet 00_Dashboard
B2: Commissioning Dashboard | O2: As of: | P2: =TODAY()
B3: Live counts pulled from the Topic, Action and PQCP registers. Nothing to fill in on this sheet.
B5: =COUNTIFS('02_Topic_Register'!$B$4:$B$33,"<>",'02_Topic_Register'!$H$4:$H$33,"<>Closed") | E5: =COUNTIFS('03_Action_Register'!$B$4:$B$33,"<>",'03_Action_Register'!$I$4:$I$33,"<>Closed") | H5: =COUNTIFS('03_Action_Register'!$B$4:$B$33,"<>",'03_Action_Register'!$L$4:$L$33,"Yes") | K5: =COUNTIFS('03_Action_Register'!$B$4:$B$33,"<>",'03_Action_Register'!$I$4:$I$33,"<>Closed",'03_Action_Register'!$L$4:$L$33,"<>Yes",'03_Action_Register'!$H$4:$H$33,">="&TODAY(),'03_Action_Register'!$H$4:$H$33,"<="&(TODAY()+DUE_SOON_DAYS)) | N5: =COUNTIFS('03_Action_Register'!$B$4:$B$33,"<>",'03_Action_Register'!$I$4:$I$33,"Closed")
B8: Open Topics | E8: Open Actions | H8: Overdue Actions | K8: Actions Due Soon | N8: Closed Actions
B10: =IFERROR(COUNTIFS('05_PQCP_Tracker'!$B$4:$B$33,"<>",'05_PQCP_Tracker'!$H$4:$H$33,"Complete")/COUNTIFS('05_PQCP_Tracker'!$B$4:$B$33,"<>"),"") | E10: =COUNTIFS('05_PQCP_Tracker'!$B$4:$B$33,"<>",'05_PQCP_Tracker'!$H$4:$H$33,"Complete") | H10: =COUNTIFS('05_PQCP_Tracker'!$B$4:$B$33,"<>",'05_PQCP_Tracker'!$H$4:$H$33,"In Progress") | K10: =COUNTIFS('05_PQCP_Tracker'!$B$4:$B$33,"<>",'05_PQCP_Tracker'!$J$4:$J$33,"No") | N10: =COUNTIFS('05_PQCP_Tracker'!$B$4:$B$33,"<>",'05_PQCP_Tracker'!$H$4:$H$33,"Not Started")
B13: PQCP Completion % | E13: PQCP Items Complete | H13: PQCP Items In Progress | K13: PQCP Missing Evidence | N13: PQCP Not Started
B14: Overall Readiness | C14: =IFERROR(COUNTIFS('05_PQCP_Tracker'!$B$4:$B$33,"<>",'05_PQCP_Tracker'!$H$4:$H$33,"Complete")/COUNTIFS('05_PQCP_Tracker'!$B$4:$B$33,"<>"),"")
B17: Top 5 Blockers / Critical Open Items
B18: Action ID | C18: Action | D18: Owner | E18: Due Date | F18: Status | G18: Priority
B19: {=IF(IFERROR(MATCH(1,'03_Action_Register'!$T$4:$T$33,0)+3,"")="","",INDEX('03_Action_Register'!$B$4:$B$33,(IFERROR(MATCH(1,'03_Action_Register'!$T$4:$T$33,0)+3,"")-3)))} | C19: {=IF(IFERROR(MATCH(1,'03_Action_Register'!$T$4:$T$33,0)+3,"")="","",INDEX('03_Action_Register'!$D$4:$D$33,(IFERROR(MATCH(1,'03_Action_Register'!$T$4:$T$33,0)+3,"")-3)))} | D19: {=IF(IFERROR(MATCH(1,'03_Action_Register'!$T$4:$T$33,0)+3,"")="","",INDEX('03_Action_Register'!$E$4:$E$33,(IFERROR(MATCH(1,'03_Action_Register'!$T$4:$T$33,0)+3,"")-3)))} | E19: {=IF(IFERROR(MATCH(1,'03_Action_Register'!$T$4:$T$33,0)+3,"")="","",INDEX('03_Action_Register'!$H$4:$H$33,(IFERROR(MATCH(1,'03_Action_Register'!$T$4:$T$33,0)+3,"")-3)))} | F19: {=IF(IFERROR(MATCH(1,'03_Action_Register'!$T$4:$T$33,0)+3,"")="","",INDEX('03_Action_Register'!$I$4:$I$33,(IFERROR(MATCH(1,'03_Action_Register'!$T$4:$T$33,0)+3,"")-3)))} | G19: {=IF(IFERROR(MATCH(1,'03_Action_Register'!$T$4:$T$33,0)+3,"")="","",INDEX('03_Action_Register'!$J$4:$J$33,(IFERROR(MATCH(1,'03_Action_Register'!$T$4:$T$33,0)+3,"")-3)))}
B20: {=IF(IFERROR(MATCH(2,'03_Action_Register'!$T$4:$T$33,0)+3,"")="","",INDEX('03_Action_Register'!$B$4:$B$33,(IFERROR(MATCH(2,'03_Action_Register'!$T$4:$T$33,0)+3,"")-3)))} | C20: {=IF(IFERROR(MATCH(2,'03_Action_Register'!$T$4:$T$33,0)+3,"")="","",INDEX('03_Action_Register'!$D$4:$D$33,(IFERROR(MATCH(2,'03_Action_Register'!$T$4:$T$33,0)+3,"")-3)))} | D20: {=IF(IFERROR(MATCH(2,'03_Action_Register'!$T$4:$T$33,0)+3,"")="","",INDEX('03_Action_Register'!$E$4:$E$33,(IFERROR(MATCH(2,'03_Action_Register'!$T$4:$T$33,0)+3,"")-3)))} | E20: {=IF(IFERROR(MATCH(2,'03_Action_Register'!$T$4:$T$33,0)+3,"")="","",INDEX('03_Action_Register'!$H$4:$H$33,(IFERROR(MATCH(2,'03_Action_Register'!$T$4:$T$33,0)+3,"")-3)))} | F20: {=IF(IFERROR(MATCH(2,'03_Action_Register'!$T$4:$T$33,0)+3,"")="","",INDEX('03_Action_Register'!$I$4:$I$33,(IFERROR(MATCH(2,'03_Action_Register'!$T$4:$T$33,0)+3,"")-3)))} | G20: {=IF(IFERROR(MATCH(2,'03_Action_Register'!$T$4:$T$33,0)+3,"")="","",INDEX('03_Action_Register'!$J$4:$J$33,(IFERROR(MATCH(2,'03_Action_Register'!$T$4:$T$33,0)+3,"")-3)))}
B21: {=IF(IFERROR(MATCH(3,'03_Action_Register'!$T$4:$T$33,0)+3,"")="","",INDEX('03_Action_Register'!$B$4:$B$33,(IFERROR(MATCH(3,'03_Action_Register'!$T$4:$T$33,0)+3,"")-3)))} | C21: {=IF(IFERROR(MATCH(3,'03_Action_Register'!$T$4:$T$33,0)+3,"")="","",INDEX('03_Action_Register'!$D$4:$D$33,(IFERROR(MATCH(3,'03_Action_Register'!$T$4:$T$33,0)+3,"")-3)))} | D21: {=IF(IFERROR(MATCH(3,'03_Action_Register'!$T$4:$T$33,0)+3,"")="","",INDEX('03_Action_Register'!$E$4:$E$33,(IFERROR(MATCH(3,'03_Action_Register'!$T$4:$T$33,0)+3,"")-3)))} | E21: {=IF(IFERROR(MATCH(3,'03_Action_Register'!$T$4:$T$33,0)+3,"")="","",INDEX('03_Action_Register'!$H$4:$H$33,(IFERROR(MATCH(3,'03_Action_Register'!$T$4:$T$33,0)+3,"")-3)))} | F21: {=IF(IFERROR(MATCH(3,'03_Action_Register'!$T$4:$T$33,0)+3,"")="","",INDEX('03_Action_Register'!$I$4:$I$33,(IFERROR(MATCH(3,'03_Action_Register'!$T$4:$T$33,0)+3,"")-3)))} | G21: {=IF(IFERROR(MATCH(3,'03_Action_Register'!$T$4:$T$33,0)+3,"")="","",INDEX('03_Action_Register'!$J$4:$J$33,(IFERROR(MATCH(3,'03_Action_Register'!$T$4:$T$33,0)+3,"")-3)))}
B22: {=IF(IFERROR(MATCH(4,'03_Action_Register'!$T$4:$T$33,0)+3,"")="","",INDEX('03_Action_Register'!$B$4:$B$33,(IFERROR(MATCH(4,'03_Action_Register'!$T$4:$T$33,0)+3,"")-3)))} | C22: {=IF(IFERROR(MATCH(4,'03_Action_Register'!$T$4:$T$33,0)+3,"")="","",INDEX('03_Action_Register'!$D$4:$D$33,(IFERROR(MATCH(4,'03_Action_Register'!$T$4:$T$33,0)+3,"")-3)))} | D22: {=IF(IFERROR(MATCH(4,'03_Action_Register'!$T$4:$T$33,0)+3,"")="","",INDEX('03_Action_Register'!$E$4:$E$33,(IFERROR(MATCH(4,'03_Action_Register'!$T$4:$T$33,0)+3,"")-3)))} | E22: {=IF(IFERROR(MATCH(4,'03_Action_Register'!$T$4:$T$33,0)+3,"")="","",INDEX('03_Action_Register'!$H$4:$H$33,(IFERROR(MATCH(4,'03_Action_Register'!$T$4:$T$33,0)+3,"")-3)))} | F22: {=IF(IFERROR(MATCH(4,'03_Action_Register'!$T$4:$T$33,0)+3,"")="","",INDEX('03_Action_Register'!$I$4:$I$33,(IFERROR(MATCH(4,'03_Action_Register'!$T$4:$T$33,0)+3,"")-3)))} | G22: {=IF(IFERROR(MATCH(4,'03_Action_Register'!$T$4:$T$33,0)+3,"")="","",INDEX('03_Action_Register'!$J$4:$J$33,(IFERROR(MATCH(4,'03_Action_Register'!$T$4:$T$33,0)+3,"")-3)))}
B23: {=IF(IFERROR(MATCH(5,'03_Action_Register'!$T$4:$T$33,0)+3,"")="","",INDEX('03_Action_Register'!$B$4:$B$33,(IFERROR(MATCH(5,'03_Action_Register'!$T$4:$T$33,0)+3,"")-3)))} | C23: {=IF(IFERROR(MATCH(5,'03_Action_Register'!$T$4:$T$33,0)+3,"")="","",INDEX('03_Action_Register'!$D$4:$D$33,(IFERROR(MATCH(5,'03_Action_Register'!$T$4:$T$33,0)+3,"")-3)))} | D23: {=IF(IFERROR(MATCH(5,'03_Action_Register'!$T$4:$T$33,0)+3,"")="","",INDEX('03_Action_Register'!$E$4:$E$33,(IFERROR(MATCH(5,'03_Action_Register'!$T$4:$T$33,0)+3,"")-3)))} | E23: {=IF(IFERROR(MATCH(5,'03_Action_Register'!$T$4:$T$33,0)+3,"")="","",INDEX('03_Action_Register'!$H$4:$H$33,(IFERROR(MATCH(5,'03_Action_Register'!$T$4:$T$33,0)+3,"")-3)))} | F23: {=IF(IFERROR(MATCH(5,'03_Action_Register'!$T$4:$T$33,0)+3,"")="","",INDEX('03_Action_Register'!$I$4:$I$33,(IFERROR(MATCH(5,'03_Action_Register'!$T$4:$T$33,0)+3,"")-3)))} | G23: {=IF(IFERROR(MATCH(5,'03_Action_Register'!$T$4:$T$33,0)+3,"")="","",INDEX('03_Action_Register'!$J$4:$J$33,(IFERROR(MATCH(5,'03_Action_Register'!$T$4:$T$33,0)+3,"")-3)))}
B25: Legend: Blue text = fill in yourself | Black text = automatic formula, do not overtype | Grey columns = automation helpers, do not edit

Sheet 01_Next_Meeting
B2: Legend: Blue text = fill in yourself | Black text = automatic formula, do not overtype | Grey columns = automation helpers, do not edit
B3: Chair the meeting directly from this sheet. Rows below fill in automatically for every topic flagged 'Discuss at Next Meeting = Yes', with an overdue action, or with an open question - nothing to maintain here.
B5: Meeting Date: | C5: 46239 | E5: Topics on agenda: | G5: =COUNTA(B9:B28)
B8: Topic ID | C8: Topic | D8: Current Position | E8: Latest Update | F8: Open Point / Question | G8: Action | H8: Owner | I8: Due Date | J8: Input / Decision Required
B9: {=IF(IFERROR(MATCH(1,'02_Topic_Register'!$R$4:$R$33,0)+3,"")="","",INDEX('02_Topic_Register'!$B$4:$B$33,(IFERROR(MATCH(1,'02_Topic_Register'!$R$4:$R$33,0)+3,"")-3)))} | C9: {=IF($B9="","",INDEX('02_Topic_Register'!$E$4:$E$33,(IFERROR(MATCH(1,'02_Topic_Register'!$R$4:$R$33,0)+3,"")-3)))} | D9: {=IF($B9="","",INDEX('02_Topic_Register'!$F$4:$F$33,(IFERROR(MATCH(1,'02_Topic_Register'!$R$4:$R$33,0)+3,"")-3)))} | E9: {=IF($B9="","",IF(IFERROR(MAX(IF('04_Update_History'!$D$4:$D$153=INDEX('02_Topic_Register'!$B$4:$B$33,(IFERROR(MATCH(1,'02_Topic_Register'!$R$4:$R$33,0)+3,"")-3)),ROW('04_Update_History'!$D$4:$D$153))),0)=0,"",INDEX('04_Update_History'!$F$4:$F$153,(IFERROR(MAX(IF('04_Update_History'!$D$4:$D$153=INDEX('02_Topic_Register'!$B$4:$B$33,(IFERROR(MATCH(1,'02_Topic_Register'!$R$4:$R$33,0)+3,"")-3)),ROW('04_Update_History'!$D$4:$D$153))),0)-3))))} | F9: {=IF($B9="","",INDEX('02_Topic_Register'!$G$4:$G$33,(IFERROR(MATCH(1,'02_Topic_Register'!$R$4:$R$33,0)+3,"")-3)))} | G9: {=IF($B9="","",IF(IFERROR(MATCH(IFERROR(INDEX('02_Topic_Register'!$N$4:$N$33,(IFERROR(MATCH(1,'02_Topic_Register'!$R$4:$R$33,0)+3,"")-3)),""),'03_Action_Register'!$B$4:$B$33,0),"")="","",INDEX('03_Action_Register'!$D$4:$D$33,IFERROR(MATCH(IFERROR(INDEX('02_Topic_Register'!$N$4:$N$33,(IFERROR(MATCH(1,'02_Topic_Register'!$R$4:$R$33,0)+3,"")-3)),""),'03_Action_Register'!$B$4:$B$33,0),""))))} | H9: {=IF($B9="","",IF(IFERROR(MATCH(IFERROR(INDEX('02_Topic_Register'!$N$4:$N$33,(IFERROR(MATCH(1,'02_Topic_Register'!$R$4:$R$33,0)+3,"")-3)),""),'03_Action_Register'!$B$4:$B$33,0),"")="","",INDEX('03_Action_Register'!$E$4:$E$33,IFERROR(MATCH(IFERROR(INDEX('02_Topic_Register'!$N$4:$N$33,(IFERROR(MATCH(1,'02_Topic_Register'!$R$4:$R$33,0)+3,"")-3)),""),'03_Action_Register'!$B$4:$B$33,0),""))))} | I9: {=IF($B9="","",IF(IFERROR(MATCH(IFERROR(INDEX('02_Topic_Register'!$N$4:$N$33,(IFERROR(MATCH(1,'02_Topic_Register'!$R$4:$R$33,0)+3,"")-3)),""),'03_Action_Register'!$B$4:$B$33,0),"")="","",INDEX('03_Action_Register'!$H$4:$H$33,IFERROR(MATCH(IFERROR(INDEX('02_Topic_Register'!$N$4:$N$33,(IFERROR(MATCH(1,'02_Topic_Register'!$R$4:$R$33,0)+3,"")-3)),""),'03_Action_Register'!$B$4:$B$33,0),""))))} | J9: =IF($B9="","",IF($F9<>"","Yes - input needed","Update only"))
B10: {=IF(IFERROR(MATCH(2,'02_Topic_Register'!$R$4:$R$33,0)+3,"")="","",INDEX('02_Topic_Register'!$B$4:$B$33,(IFERROR(MATCH(2,'02_Topic_Register'!$R$4:$R$33,0)+3,"")-3)))} | C10: {=IF($B10="","",INDEX('02_Topic_Register'!$E$4:$E$33,(IFERROR(MATCH(2,'02_Topic_Register'!$R$4:$R$33,0)+3,"")-3)))} | D10: {=IF($B10="","",INDEX('02_Topic_Register'!$F$4:$F$33,(IFERROR(MATCH(2,'02_Topic_Register'!$R$4:$R$33,0)+3,"")-3)))} | E10: {=IF($B10="","",IF(IFERROR(MAX(IF('04_Update_History'!$D$4:$D$153=INDEX('02_Topic_Register'!$B$4:$B$33,(IFERROR(MATCH(2,'02_Topic_Register'!$R$4:$R$33,0)+3,"")-3)),ROW('04_Update_History'!$D$4:$D$153))),0)=0,"",INDEX('04_Update_History'!$F$4:$F$153,(IFERROR(MAX(IF('04_Update_History'!$D$4:$D$153=INDEX('02_Topic_Register'!$B$4:$B$33,(IFERROR(MATCH(2,'02_Topic_Register'!$R$4:$R$33,0)+3,"")-3)),ROW('04_Update_History'!$D$4:$D$153))),0)-3))))} | F10: {=IF($B10="","",INDEX('02_Topic_Register'!$G$4:$G$33,(IFERROR(MATCH(2,'02_Topic_Register'!$R$4:$R$33,0)+3,"")-3)))} | G10: {=IF($B10="","",IF(IFERROR(MATCH(IFERROR(INDEX('02_Topic_Register'!$N$4:$N$33,(IFERROR(MATCH(2,'02_Topic_Register'!$R$4:$R$33,0)+3,"")-3)),""),'03_Action_Register'!$B$4:$B$33,0),"")="","",INDEX('03_Action_Register'!$D$4:$D$33,IFERROR(MATCH(IFERROR(INDEX('02_Topic_Register'!$N$4:$N$33,(IFERROR(MATCH(2,'02_Topic_Register'!$R$4:$R$33,0)+3,"")-3)),""),'03_Action_Register'!$B$4:$B$33,0),""))))} | H10: {=IF($B10="","",IF(IFERROR(MATCH(IFERROR(INDEX('02_Topic_Register'!$N$4:$N$33,(IFERROR(MATCH(2,'02_Topic_Register'!$R$4:$R$33,0)+3,"")-3)),""),'03_Action_Register'!$B$4:$B$33,0),"")="","",INDEX('03_Action_Register'!$E$4:$E$33,IFERROR(MATCH(IFERROR(INDEX('02_Topic_Register'!$N$4:$N$33,(IFERROR(MATCH(2,'02_Topic_Register'!$R$4:$R$33,0)+3,"")-3)),""),'03_Action_Register'!$B$4:$B$33,0),""))))} | I10: {=IF($B10="","",IF(IFERROR(MATCH(IFERROR(INDEX('02_Topic_Register'!$N$4:$N$33,(IFERROR(MATCH(2,'02_Topic_Register'!$R$4:$R$33,0)+3,"")-3)),""),'03_Action_Register'!$B$4:$B$33,0),"")="","",INDEX('03_Action_Register'!$H$4:$H$33,IFERROR(MATCH(IFERROR(INDEX('02_Topic_Register'!$N$4:$N$33,(IFERROR(MATCH(2,'02_Topic_Register'!$R$4:$R$33,0)+3,"")-3)),""),'03_Action_Register'!$B$4:$B$33,0),""))))} | J10: =IF($B10="","",IF($F10<>"","Yes - input needed","Update only"))
B11: {=IF(IFERROR(MATCH(3,'02_Topic_Register'!$R$4:$R$33,0)+3,"")="","",INDEX('02_Topic_Register'!$B$4:$B$33,(IFERROR(MATCH(3,'02_Topic_Register'!$R$4:$R$33,0)+3,"")-3)))} | C11: {=IF($B11="","",INDEX('02_Topic_Register'!$E$4:$E$33,(IFERROR(MATCH(3,'02_Topic_Register'!$R$4:$R$33,0)+3,"")-3)))} | D11: {=IF($B11="","",INDEX('02_Topic_Register'!$F$4:$F$33,(IFERROR(MATCH(3,'02_Topic_Register'!$R$4:$R$33,0)+3,"")-3)))} | E11: {=IF($B11="","",IF(IFERROR(MAX(IF('04_Update_History'!$D$4:$D$153=INDEX('02_Topic_Register'!$B$4:$B$33,(IFERROR(MATCH(3,'02_Topic_Register'!$R$4:$R$33,0)+3,"")-3)),ROW('04_Update_History'!$D$4:$D$153))),0)=0,"",INDEX('04_Update_History'!$F$4:$F$153,(IFERROR(MAX(IF('04_Update_History'!$D$4:$D$153=INDEX('02_Topic_Register'!$B$4:$B$33,(IFERROR(MATCH(3,'02_Topic_Register'!$R$4:$R$33,0)+3,"")-3)),ROW('04_Update_History'!$D$4:$D$153))),0)-3))))} | F11: {=IF($B11="","",INDEX('02_Topic_Register'!$G$4:$G$33,(IFERROR(MATCH(3,'02_Topic_Register'!$R$4:$R$33,0)+3,"")-3)))} | G11: {=IF($B11="","",IF(IFERROR(MATCH(IFERROR(INDEX('02_Topic_Register'!$N$4:$N$33,(IFERROR(MATCH(3,'02_Topic_Register'!$R$4:$R$33,0)+3,"")-3)),""),'03_Action_Register'!$B$4:$B$33,0),"")="","",INDEX('03_Action_Register'!$D$4:$D$33,IFERROR(MATCH(IFERROR(INDEX('02_Topic_Register'!$N$4:$N$33,(IFERROR(MATCH(3,'02_Topic_Register'!$R$4:$R$33,0)+3,"")-3)),""),'03_Action_Register'!$B$4:$B$33,0),""))))} | H11: {=IF($B11="","",IF(IFERROR(MATCH(IFERROR(INDEX('02_Topic_Register'!$N$4:$N$33,(IFERROR(MATCH(3,'02_Topic_Register'!$R$4:$R$33,0)+3,"")-3)),""),'03_Action_Register'!$B$4:$B$33,0),"")="","",INDEX('03_Action_Register'!$E$4:$E$33,IFERROR(MATCH(IFERROR(INDEX('02_Topic_Register'!$N$4:$N$33,(IFERROR(MATCH(3,'02_Topic_Register'!$R$4:$R$33,0)+3,"")-3)),""),'03_Action_Register'!$B$4:$B$33,0),""))))} | I11: {=IF($B11="","",IF(IFERROR(MATCH(IFERROR(INDEX('02_Topic_Register'!$N$4:$N$33,(IFERROR(MATCH(3,'02_Topic_Register'!$R$4:$R$33,0)+3,"")-3)),""),'03_Action_Register'!$B$4:$B$33,0),"")="","",INDEX('03_Action_Register'!$H$4:$H$33,IFERROR(MATCH(IFERROR(INDEX('02_Topic_Register'!$N$4:$N$33,(IFERROR(MATCH(3,'02_Topic_Register'!$R$4:$R$33,0)+3,"")-3)),""),'03_Action_Register'!$B$4:$B$33,0),""))))} | J11: =IF($B11="","",IF($F11<>"","Yes - input needed","Update only"))
B12: {=IF(IFERROR(MATCH(4,'02_Topic_Register'!$R$4:$R$33,0)+3,"")="","",INDEX('02_Topic_Register'!$B$4:$B$33,(IFERROR(MATCH(4,'02_Topic_Register'!$R$4:$R$33,0)+3,"")-3)))} | C12: {=IF($B12="","",INDEX('02_Topic_Register'!$E$4:$E$33,(IFERROR(MATCH(4,'02_Topic_Register'!$R$4:$R$33,0)+3,"")-3)))} | D12: {=IF($B12="","",INDEX('02_Topic_Register'!$F$4:$F$33,(IFERROR(MATCH(4,'02_Topic_Register'!$R$4:$R$33,0)+3,"")-3)))} | E12: {=IF($B12="","",IF(IFERROR(MAX(IF('04_Update_History'!$D$4:$D$153=INDEX('02_Topic_Register'!$B$4:$B$33,(IFERROR(MATCH(4,'02_Topic_Register'!$R$4:$R$33,0)+3,"")-3)),ROW('04_Update_History'!$D$4:$D$153))),0)=0,"",INDEX('04_Update_History'!$F$4:$F$153,(IFERROR(MAX(IF('04_Update_History'!$D$4:$D$153=INDEX('02_Topic_Register'!$B$4:$B$33,(IFERROR(MATCH(4,'02_Topic_Register'!$R$4:$R$33,0)+3,"")-3)),ROW('04_Update_History'!$D$4:$D$153))),0)-3))))} | F12: {=IF($B12="","",INDEX('02_Topic_Register'!$G$4:$G$33,(IFERROR(MATCH(4,'02_Topic_Register'!$R$4:$R$33,0)+3,"")-3)))} | G12: {=IF($B12="","",IF(IFERROR(MATCH(IFERROR(INDEX('02_Topic_Register'!$N$4:$N$33,(IFERROR(MATCH(4,'02_Topic_Register'!$R$4:$R$33,0)+3,"")-3)),""),'03_Action_Register'!$B$4:$B$33,0),"")="","",INDEX('03_Action_Register'!$D$4:$D$33,IFERROR(MATCH(IFERROR(INDEX('02_Topic_Register'!$N$4:$N$33,(IFERROR(MATCH(4,'02_Topic_Register'!$R$4:$R$33,0)+3,"")-3)),""),'03_Action_Register'!$B$4:$B$33,0),""))))} | H12: {=IF($B12="","",IF(IFERROR(MATCH(IFERROR(INDEX('02_Topic_Register'!$N$4:$N$33,(IFERROR(MATCH(4,'02_Topic_Register'!$R$4:$R$33,0)+3,"")-3)),""),'03_Action_Register'!$B$4:$B$33,0),"")="","",INDEX('03_Action_Register'!$E$4:$E$33,IFERROR(MATCH(IFERROR(INDEX('02_Topic_Register'!$N$4:$N$33,(IFERROR(MATCH(4,'02_Topic_Register'!$R$4:$R$33,0)+3,"")-3)),""),'03_Action_Register'!$B$4:$B$33,0),""))))} | I12: {=IF($B12="","",IF(IFERROR(MATCH(IFERROR(INDEX('02_Topic_Register'!$N$4:$N$33,(IFERROR(MATCH(4,'02_Topic_Register'!$R$4:$R$33,0)+3,"")-3)),""),'03_Action_Register'!$B$4:$B$33,0),"")="","",INDEX('03_Action_Register'!$H$4:$H$33,IFERROR(MATCH(IFERROR(INDEX('02_Topic_Register'!$N$4:$N$33,(IFERROR(MATCH(4,'02_Topic_Register'!$R$4:$R$33,0)+3,"")-3)),""),'03_Action_Register'!$B$4:$B$33,0),""))))} | J12: =IF($B12="","",IF($F12<>"","Yes - input needed","Update only"))
B13: {=IF(IFERROR(MATCH(5,'02_Topic_Register'!$R$4:$R$33,0)+3,"")="","",INDEX('02_Topic_Register'!$B$4:$B$33,(IFERROR(MATCH(5,'02_Topic_Register'!$R$4:$R$33,0)+3,"")-3)))} | C13: {=IF($B13="","",INDEX('02_Topic_Register'!$E$4:$E$33,(IFERROR(MATCH(5,'02_Topic_Register'!$R$4:$R$33,0)+3,"")-3)))} | D13: {=IF($B13="","",INDEX('02_Topic_Register'!$F$4:$F$33,(IFERROR(MATCH(5,'02_Topic_Register'!$R$4:$R$33,0)+3,"")-3)))} | E13: {=IF($B13="","",IF(IFERROR(MAX(IF('04_Update_History'!$D$4:$D$153=INDEX('02_Topic_Register'!$B$4:$B$33,(IFERROR(MATCH(5,'02_Topic_Register'!$R$4:$R$33,0)+3,"")-3)),ROW('04_Update_History'!$D$4:$D$153))),0)=0,"",INDEX('04_Update_History'!$F$4:$F$153,(IFERROR(MAX(IF('04_Update_History'!$D$4:$D$153=INDEX('02_Topic_Register'!$B$4:$B$33,(IFERROR(MATCH(5,'02_Topic_Register'!$R$4:$R$33,0)+3,"")-3)),ROW('04_Update_History'!$D$4:$D$153))),0)-3))))} | F13: {=IF($B13="","",INDEX('02_Topic_Register'!$G$4:$G$33,(IFERROR(MATCH(5,'02_Topic_Register'!$R$4:$R$33,0)+3,"")-3)))} | G13: {=IF($B13="","",IF(IFERROR(MATCH(IFERROR(INDEX('02_Topic_Register'!$N$4:$N$33,(IFERROR(MATCH(5,'02_Topic_Register'!$R$4:$R$33,0)+3,"")-3)),""),'03_Action_Register'!$B$4:$B$33,0),"")="","",INDEX('03_Action_Register'!$D$4:$D$33,IFERROR(MATCH(IFERROR(INDEX('02_Topic_Register'!$N$4:$N$33,(IFERROR(MATCH(5,'02_Topic_Register'!$R$4:$R$33,0)+3,"")-3)),""),'03_Action_Register'!$B$4:$B$33,0),""))))} | H13: {=IF($B13="","",IF(IFERROR(MATCH(IFERROR(INDEX('02_Topic_Register'!$N$4:$N$33,(IFERROR(MATCH(5,'02_Topic_Register'!$R$4:$R$33,0)+3,"")-3)),""),'03_Action_Register'!$B$4:$B$33,0),"")="","",INDEX('03_Action_Register'!$E$4:$E$33,IFERROR(MATCH(IFERROR(INDEX('02_Topic_Register'!$N$4:$N$33,(IFERROR(MATCH(5,'02_Topic_Register'!$R$4:$R$33,0)+3,"")-3)),""),'03_Action_Register'!$B$4:$B$33,0),""))))} | I13: {=IF($B13="","",IF(IFERROR(MATCH(IFERROR(INDEX('02_Topic_Register'!$N$4:$N$33,(IFERROR(MATCH(5,'02_Topic_Register'!$R$4:$R$33,0)+3,"")-3)),""),'03_Action_Register'!$B$4:$B$33,0),"")="","",INDEX('03_Action_Register'!$H$4:$H$33,IFERROR(MATCH(IFERROR(INDEX('02_Topic_Register'!$N$4:$N$33,(IFERROR(MATCH(5,'02_Topic_Register'!$R$4:$R$33,0)+3,"")-3)),""),'03_Action_Register'!$B$4:$B$33,0),""))))} | J13: =IF($B13="","",IF($F13<>"","Yes - input needed","Update only"))
B14: {=IF(IFERROR(MATCH(6,'02_Topic_Register'!$R$4:$R$33,0)+3,"")="","",INDEX('02_Topic_Register'!$B$4:$B$33,(IFERROR(MATCH(6,'02_Topic_Register'!$R$4:$R$33,0)+3,"")-3)))} | C14: {=IF($B14="","",INDEX('02_Topic_Register'!$E$4:$E$33,(IFERROR(MATCH(6,'02_Topic_Register'!$R$4:$R$33,0)+3,"")-3)))} | D14: {=IF($B14="","",INDEX('02_Topic_Register'!$F$4:$F$33,(IFERROR(MATCH(6,'02_Topic_Register'!$R$4:$R$33,0)+3,"")-3)))} | E14: {=IF($B14="","",IF(IFERROR(MAX(IF('04_Update_History'!$D$4:$D$153=INDEX('02_Topic_Register'!$B$4:$B$33,(IFERROR(MATCH(6,'02_Topic_Register'!$R$4:$R$33,0)+3,"")-3)),ROW('04_Update_History'!$D$4:$D$153))),0)=0,"",INDEX('04_Update_History'!$F$4:$F$153,(IFERROR(MAX(IF('04_Update_History'!$D$4:$D$153=INDEX('02_Topic_Register'!$B$4:$B$33,(IFERROR(MATCH(6,'02_Topic_Register'!$R$4:$R$33,0)+3,"")-3)),ROW('04_Update_History'!$D$4:$D$153))),0)-3))))} | F14: {=IF($B14="","",INDEX('02_Topic_Register'!$G$4:$G$33,(IFERROR(MATCH(6,'02_Topic_Register'!$R$4:$R$33,0)+3,"")-3)))} | G14: {=IF($B14="","",IF(IFERROR(MATCH(IFERROR(INDEX('02_Topic_Register'!$N$4:$N$33,(IFERROR(MATCH(6,'02_Topic_Register'!$R$4:$R$33,0)+3,"")-3)),""),'03_Action_Register'!$B$4:$B$33,0),"")="","",INDEX('03_Action_Register'!$D$4:$D$33,IFERROR(MATCH(IFERROR(INDEX('02_Topic_Register'!$N$4:$N$33,(IFERROR(MATCH(6,'02_Topic_Register'!$R$4:$R$33,0)+3,"")-3)),""),'03_Action_Register'!$B$4:$B$33,0),""))))} | H14: {=IF($B14="","",IF(IFERROR(MATCH(IFERROR(INDEX('02_Topic_Register'!$N$4:$N$33,(IFERROR(MATCH(6,'02_Topic_Register'!$R$4:$R$33,0)+3,"")-3)),""),'03_Action_Register'!$B$4:$B$33,0),"")="","",INDEX('03_Action_Register'!$E$4:$E$33,IFERROR(MATCH(IFERROR(INDEX('02_Topic_Register'!$N$4:$N$33,(IFERROR(MATCH(6,'02_Topic_Register'!$R$4:$R$33,0)+3,"")-3)),""),'03_Action_Register'!$B$4:$B$33,0),""))))} | I14: {=IF($B14="","",IF(IFERROR(MATCH(IFERROR(INDEX('02_Topic_Register'!$N$4:$N$33,(IFERROR(MATCH(6,'02_Topic_Register'!$R$4:$R$33,0)+3,"")-3)),""),'03_Action_Register'!$B$4:$B$33,0),"")="","",INDEX('03_Action_Register'!$H$4:$H$33,IFERROR(MATCH(IFERROR(INDEX('02_Topic_Register'!$N$4:$N$33,(IFERROR(MATCH(6,'02_Topic_Register'!$R$4:$R$33,0)+3,"")-3)),""),'03_Action_Register'!$B$4:$B$33,0),""))))} | J14: =IF($B14="","",IF($F14<>"","Yes - input needed","Update only"))
B15: {=IF(IFERROR(MATCH(7,'02_Topic_Register'!$R$4:$R$33,0)+3,"")="","",INDEX('02_Topic_Register'!$B$4:$B$33,(IFERROR(MATCH(7,'02_Topic_Register'!$R$4:$R$33,0)+3,"")-3)))} | C15: {=IF($B15="","",INDEX('02_Topic_Register'!$E$4:$E$33,(IFERROR(MATCH(7,'02_Topic_Register'!$R$4:$R$33,0)+3,"")-3)))} | D15: {=IF($B15="","",INDEX('02_Topic_Register'!$F$4:$F$33,(IFERROR(MATCH(7,'02_Topic_Register'!$R$4:$R$33,0)+3,"")-3)))} | E15: {=IF($B15="","",IF(IFERROR(MAX(IF('04_Update_History'!$D$4:$D$153=INDEX('02_Topic_Register'!$B$4:$B$33,(IFERROR(MATCH(7,'02_Topic_Register'!$R$4:$R$33,0)+3,"")-3)),ROW('04_Update_History'!$D$4:$D$153))),0)=0,"",INDEX('04_Update_History'!$F$4:$F$153,(IFERROR(MAX(IF('04_Update_History'!$D$4:$D$153=INDEX('02_Topic_Register'!$B$4:$B$33,(IFERROR(MATCH(7,'02_Topic_Register'!$R$4:$R$33,0)+3,"")-3)),ROW('04_Update_History'!$D$4:$D$153))),0)-3))))} | F15: {=IF($B15="","",INDEX('02_Topic_Register'!$G$4:$G$33,(IFERROR(MATCH(7,'02_Topic_Register'!$R$4:$R$33,0)+3,"")-3)))} | G15: {=IF($B15="","",IF(IFERROR(MATCH(IFERROR(INDEX('02_Topic_Register'!$N$4:$N$33,(IFERROR(MATCH(7,'02_Topic_Register'!$R$4:$R$33,0)+3,"")-3)),""),'03_Action_Register'!$B$4:$B$33,0),"")="","",INDEX('03_Action_Register'!$D$4:$D$33,IFERROR(MATCH(IFERROR(INDEX('02_Topic_Register'!$N$4:$N$33,(IFERROR(MATCH(7,'02_Topic_Register'!$R$4:$R$33,0)+3,"")-3)),""),'03_Action_Register'!$B$4:$B$33,0),""))))} | H15: {=IF($B15="","",IF(IFERROR(MATCH(IFERROR(INDEX('02_Topic_Register'!$N$4:$N$33,(IFERROR(MATCH(7,'02_Topic_Register'!$R$4:$R$33,0)+3,"")-3)),""),'03_Action_Register'!$B$4:$B$33,0),"")="","",INDEX('03_Action_Register'!$E$4:$E$33,IFERROR(MATCH(IFERROR(INDEX('02_Topic_Register'!$N$4:$N$33,(IFERROR(MATCH(7,'02_Topic_Register'!$R$4:$R$33,0)+3,"")-3)),""),'03_Action_Register'!$B$4:$B$33,0),""))))} | I15: {=IF($B15="","",IF(IFERROR(MATCH(IFERROR(INDEX('02_Topic_Register'!$N$4:$N$33,(IFERROR(MATCH(7,'02_Topic_Register'!$R$4:$R$33,0)+3,"")-3)),""),'03_Action_Register'!$B$4:$B$33,0),"")="","",INDEX('03_Action_Register'!$H$4:$H$33,IFERROR(MATCH(IFERROR(INDEX('02_Topic_Register'!$N$4:$N$33,(IFERROR(MATCH(7,'02_Topic_Register'!$R$4:$R$33,0)+3,"")-3)),""),'03_Action_Register'!$B$4:$B$33,0),""))))} | J15: =IF($B15="","",IF($F15<>"","Yes - input needed","Update only"))
B16: {=IF(IFERROR(MATCH(8,'02_Topic_Register'!$R$4:$R$33,0)+3,"")="","",INDEX('02_Topic_Register'!$B$4:$B$33,(IFERROR(MATCH(8,'02_Topic_Register'!$R$4:$R$33,0)+3,"")-3)))} | C16: {=IF($B16="","",INDEX('02_Topic_Register'!$E$4:$E$33,(IFERROR(MATCH(8,'02_Topic_Register'!$R$4:$R$33,0)+3,"")-3)))} | D16: {=IF($B16="","",INDEX('02_Topic_Register'!$F$4:$F$33,(IFERROR(MATCH(8,'02_Topic_Register'!$R$4:$R$33,0)+3,"")-3)))} | E16: {=IF($B16="","",IF(IFERROR(MAX(IF('04_Update_History'!$D$4:$D$153=INDEX('02_Topic_Register'!$B$4:$B$33,(IFERROR(MATCH(8,'02_Topic_Register'!$R$4:$R$33,0)+3,"")-3)),ROW('04_Update_History'!$D$4:$D$153))),0)=0,"",INDEX('04_Update_History'!$F$4:$F$153,(IFERROR(MAX(IF('04_Update_History'!$D$4:$D$153=INDEX('02_Topic_Register'!$B$4:$B$33,(IFERROR(MATCH(8,'02_Topic_Register'!$R$4:$R$33,0)+3,"")-3)),ROW('04_Update_History'!$D$4:$D$153))),0)-3))))} | F16: {=IF($B16="","",INDEX('02_Topic_Register'!$G$4:$G$33,(IFERROR(MATCH(8,'02_Topic_Register'!$R$4:$R$33,0)+3,"")-3)))} | G16: {=IF($B16="","",IF(IFERROR(MATCH(IFERROR(INDEX('02_Topic_Register'!$N$4:$N$33,(IFERROR(MATCH(8,'02_Topic_Register'!$R$4:$R$33,0)+3,"")-3)),""),'03_Action_Register'!$B$4:$B$33,0),"")="","",INDEX('03_Action_Register'!$D$4:$D$33,IFERROR(MATCH(IFERROR(INDEX('02_Topic_Register'!$N$4:$N$33,(IFERROR(MATCH(8,'02_Topic_Register'!$R$4:$R$33,0)+3,"")-3)),""),'03_Action_Register'!$B$4:$B$33,0),""))))} | H16: {=IF($B16="","",IF(IFERROR(MATCH(IFERROR(INDEX('02_Topic_Register'!$N$4:$N$33,(IFERROR(MATCH(8,'02_Topic_Register'!$R$4:$R$33,0)+3,"")-3)),""),'03_Action_Register'!$B$4:$B$33,0),"")="","",INDEX('03_Action_Register'!$E$4:$E$33,IFERROR(MATCH(IFERROR(INDEX('02_Topic_Register'!$N$4:$N$33,(IFERROR(MATCH(8,'02_Topic_Register'!$R$4:$R$33,0)+3,"")-3)),""),'03_Action_Register'!$B$4:$B$33,0),""))))} | I16: {=IF($B16="","",IF(IFERROR(MATCH(IFERROR(INDEX('02_Topic_Register'!$N$4:$N$33,(IFERROR(MATCH(8,'02_Topic_Register'!$R$4:$R$33,0)+3,"")-3)),""),'03_Action_Register'!$B$4:$B$33,0),"")="","",INDEX('03_Action_Register'!$H$4:$H$33,IFERROR(MATCH(IFERROR(INDEX('02_Topic_Register'!$N$4:$N$33,(IFERROR(MATCH(8,'02_Topic_Register'!$R$4:$R$33,0)+3,"")-3)),""),'03_Action_Register'!$B$4:$B$33,0),""))))} | J16: =IF($B16="","",IF($F16<>"","Yes - input needed","Update only"))
B17: {=IF(IFERROR(MATCH(9,'02_Topic_Register'!$R$4:$R$33,0)+3,"")="","",INDEX('02_Topic_Register'!$B$4:$B$33,(IFERROR(MATCH(9,'02_Topic_Register'!$R$4:$R$33,0)+3,"")-3)))} | C17: {=IF($B17="","",INDEX('02_Topic_Register'!$E$4:$E$33,(IFERROR(MATCH(9,'02_Topic_Register'!$R$4:$R$33,0)+3,"")-3)))} | D17: {=IF($B17="","",INDEX('02_Topic_Register'!$F$4:$F$33,(IFERROR(MATCH(9,'02_Topic_Register'!$R$4:$R$33,0)+3,"")-3)))} | E17: {=IF($B17="","",IF(IFERROR(MAX(IF('04_Update_History'!$D$4:$D$153=INDEX('02_Topic_Register'!$B$4:$B$33,(IFERROR(MATCH(9,'02_Topic_Register'!$R$4:$R$33,0)+3,"")-3)),ROW('04_Update_History'!$D$4:$D$153))),0)=0,"",INDEX('04_Update_History'!$F$4:$F$153,(IFERROR(MAX(IF('04_Update_History'!$D$4:$D$153=INDEX('02_Topic_Register'!$B$4:$B$33,(IFERROR(MATCH(9,'02_Topic_Register'!$R$4:$R$33,0)+3,"")-3)),ROW('04_Update_History'!$D$4:$D$153))),0)-3))))} | F17: {=IF($B17="","",INDEX('02_Topic_Register'!$G$4:$G$33,(IFERROR(MATCH(9,'02_Topic_Register'!$R$4:$R$33,0)+3,"")-3)))} | G17: {=IF($B17="","",IF(IFERROR(MATCH(IFERROR(INDEX('02_Topic_Register'!$N$4:$N$33,(IFERROR(MATCH(9,'02_Topic_Register'!$R$4:$R$33,0)+3,"")-3)),""),'03_Action_Register'!$B$4:$B$33,0),"")="","",INDEX('03_Action_Register'!$D$4:$D$33,IFERROR(MATCH(IFERROR(INDEX('02_Topic_Register'!$N$4:$N$33,(IFERROR(MATCH(9,'02_Topic_Register'!$R$4:$R$33,0)+3,"")-3)),""),'03_Action_Register'!$B$4:$B$33,0),""))))} | H17: {=IF($B17="","",IF(IFERROR(MATCH(IFERROR(INDEX('02_Topic_Register'!$N$4:$N$33,(IFERROR(MATCH(9,'02_Topic_Register'!$R$4:$R$33,0)+3,"")-3)),""),'03_Action_Register'!$B$4:$B$33,0),"")="","",INDEX('03_Action_Register'!$E$4:$E$33,IFERROR(MATCH(IFERROR(INDEX('02_Topic_Register'!$N$4:$N$33,(IFERROR(MATCH(9,'02_Topic_Register'!$R$4:$R$33,0)+3,"")-3)),""),'03_Action_Register'!$B$4:$B$33,0),""))))} | I17: {=IF($B17="","",IF(IFERROR(MATCH(IFERROR(INDEX('02_Topic_Register'!$N$4:$N$33,(IFERROR(MATCH(9,'02_Topic_Register'!$R$4:$R$33,0)+3,"")-3)),""),'03_Action_Register'!$B$4:$B$33,0),"")="","",INDEX('03_Action_Register'!$H$4:$H$33,IFERROR(MATCH(IFERROR(INDEX('02_Topic_Register'!$N$4:$N$33,(IFERROR(MATCH(9,'02_Topic_Register'!$R$4:$R$33,0)+3,"")-3)),""),'03_Action_Register'!$B$4:$B$33,0),""))))} | J17: =IF($B17="","",IF($F17<>"","Yes - input needed","Update only"))
B18: {=IF(IFERROR(MATCH(10,'02_Topic_Register'!$R$4:$R$33,0)+3,"")="","",INDEX('02_Topic_Register'!$B$4:$B$33,(IFERROR(MATCH(10,'02_Topic_Register'!$R$4:$R$33,0)+3,"")-3)))} | C18: {=IF($B18="","",INDEX('02_Topic_Register'!$E$4:$E$33,(IFERROR(MATCH(10,'02_Topic_Register'!$R$4:$R$33,0)+3,"")-3)))} | D18: {=IF($B18="","",INDEX('02_Topic_Register'!$F$4:$F$33,(IFERROR(MATCH(10,'02_Topic_Register'!$R$4:$R$33,0)+3,"")-3)))} | E18: {=IF($B18="","",IF(IFERROR(MAX(IF('04_Update_History'!$D$4:$D$153=INDEX('02_Topic_Register'!$B$4:$B$33,(IFERROR(MATCH(10,'02_Topic_Register'!$R$4:$R$33,0)+3,"")-3)),ROW('04_Update_History'!$D$4:$D$153))),0)=0,"",INDEX('04_Update_History'!$F$4:$F$153,(IFERROR(MAX(IF('04_Update_History'!$D$4:$D$153=INDEX('02_Topic_Register'!$B$4:$B$33,(IFERROR(MATCH(10,'02_Topic_Register'!$R$4:$R$33,0)+3,"")-3)),ROW('04_Update_History'!$D$4:$D$153))),0)-3))))} | F18: {=IF($B18="","",INDEX('02_Topic_Register'!$G$4:$G$33,(IFERROR(MATCH(10,'02_Topic_Register'!$R$4:$R$33,0)+3,"")-3)))} | G18: {=IF($B18="","",IF(IFERROR(MATCH(IFERROR(INDEX('02_Topic_Register'!$N$4:$N$33,(IFERROR(MATCH(10,'02_Topic_Register'!$R$4:$R$33,0)+3,"")-3)),""),'03_Action_Register'!$B$4:$B$33,0),"")="","",INDEX('03_Action_Register'!$D$4:$D$33,IFERROR(MATCH(IFERROR(INDEX('02_Topic_Register'!$N$4:$N$33,(IFERROR(MATCH(10,'02_Topic_Register'!$R$4:$R$33,0)+3,"")-3)),""),'03_Action_Register'!$B$4:$B$33,0),""))))} | H18: {=IF($B18="","",IF(IFERROR(MATCH(IFERROR(INDEX('02_Topic_Register'!$N$4:$N$33,(IFERROR(MATCH(10,'02_Topic_Register'!$R$4:$R$33,0)+3,"")-3)),""),'03_Action_Register'!$B$4:$B$33,0),"")="","",INDEX('03_Action_Register'!$E$4:$E$33,IFERROR(MATCH(IFERROR(INDEX('02_Topic_Register'!$N$4:$N$33,(IFERROR(MATCH(10,'02_Topic_Register'!$R$4:$R$33,0)+3,"")-3)),""),'03_Action_Register'!$B$4:$B$33,0),""))))} | I18: {=IF($B18="","",IF(IFERROR(MATCH(IFERROR(INDEX('02_Topic_Register'!$N$4:$N$33,(IFERROR(MATCH(10,'02_Topic_Register'!$R$4:$R$33,0)+3,"")-3)),""),'03_Action_Register'!$B$4:$B$33,0),"")="","",INDEX('03_Action_Register'!$H$4:$H$33,IFERROR(MATCH(IFERROR(INDEX('02_Topic_Register'!$N$4:$N$33,(IFERROR(MATCH(10,'02_Topic_Register'!$R$4:$R$33,0)+3,"")-3)),""),'03_Action_Register'!$B$4:$B$33,0),""))))} | J18: =IF($B18="","",IF($F18<>"","Yes - input needed","Update only"))
B19: {=IF(IFERROR(MATCH(11,'02_Topic_Register'!$R$4:$R$33,0)+3,"")="","",INDEX('02_Topic_Register'!$B$4:$B$33,(IFERROR(MATCH(11,'02_Topic_Register'!$R$4:$R$33,0)+3,"")-3)))} | C19: {=IF($B19="","",INDEX('02_Topic_Register'!$E$4:$E$33,(IFERROR(MATCH(11,'02_Topic_Register'!$R$4:$R$33,0)+3,"")-3)))} | D19: {=IF($B19="","",INDEX('02_Topic_Register'!$F$4:$F$33,(IFERROR(MATCH(11,'02_Topic_Register'!$R$4:$R$33,0)+3,"")-3)))} | E19: {=IF($B19="","",IF(IFERROR(MAX(IF('04_Update_History'!$D$4:$D$153=INDEX('02_Topic_Register'!$B$4:$B$33,(IFERROR(MATCH(11,'02_Topic_Register'!$R$4:$R$33,0)+3,"")-3)),ROW('04_Update_History'!$D$4:$D$153))),0)=0,"",INDEX('04_Update_History'!$F$4:$F$153,(IFERROR(MAX(IF('04_Update_History'!$D$4:$D$153=INDEX('02_Topic_Register'!$B$4:$B$33,(IFERROR(MATCH(11,'02_Topic_Register'!$R$4:$R$33,0)+3,"")-3)),ROW('04_Update_History'!$D$4:$D$153))),0)-3))))} | F19: {=IF($B19="","",INDEX('02_Topic_Register'!$G$4:$G$33,(IFERROR(MATCH(11,'02_Topic_Register'!$R$4:$R$33,0)+3,"")-3)))} | G19: {=IF($B19="","",IF(IFERROR(MATCH(IFERROR(INDEX('02_Topic_Register'!$N$4:$N$33,(IFERROR(MATCH(11,'02_Topic_Register'!$R$4:$R$33,0)+3,"")-3)),""),'03_Action_Register'!$B$4:$B$33,0),"")="","",INDEX('03_Action_Register'!$D$4:$D$33,IFERROR(MATCH(IFERROR(INDEX('02_Topic_Register'!$N$4:$N$33,(IFERROR(MATCH(11,'02_Topic_Register'!$R$4:$R$33,0)+3,"")-3)),""),'03_Action_Register'!$B$4:$B$33,0),""))))} | H19: {=IF($B19="","",IF(IFERROR(MATCH(IFERROR(INDEX('02_Topic_Register'!$N$4:$N$33,(IFERROR(MATCH(11,'02_Topic_Register'!$R$4:$R$33,0)+3,"")-3)),""),'03_Action_Register'!$B$4:$B$33,0),"")="","",INDEX('03_Action_Register'!$E$4:$E$33,IFERROR(MATCH(IFERROR(INDEX('02_Topic_Register'!$N$4:$N$33,(IFERROR(MATCH(11,'02_Topic_Register'!$R$4:$R$33,0)+3,"")-3)),""),'03_Action_Register'!$B$4:$B$33,0),""))))} | I19: {=IF($B19="","",IF(IFERROR(MATCH(IFERROR(INDEX('02_Topic_Register'!$N$4:$N$33,(IFERROR(MATCH(11,'02_Topic_Register'!$R$4:$R$33,0)+3,"")-3)),""),'03_Action_Register'!$B$4:$B$33,0),"")="","",INDEX('03_Action_Register'!$H$4:$H$33,IFERROR(MATCH(IFERROR(INDEX('02_Topic_Register'!$N$4:$N$33,(IFERROR(MATCH(11,'02_Topic_Register'!$R$4:$R$33,0)+3,"")-3)),""),'03_Action_Register'!$B$4:$B$33,0),""))))} | J19: =IF($B19="","",IF($F19<>"","Yes - input needed","Update only"))
B20: {=IF(IFERROR(MATCH(12,'02_Topic_Register'!$R$4:$R$33,0)+3,"")="","",INDEX('02_Topic_Register'!$B$4:$B$33,(IFERROR(MATCH(12,'02_Topic_Register'!$R$4:$R$33,0)+3,"")-3)))} | C20: {=IF($B20="","",INDEX('02_Topic_Register'!$E$4:$E$33,(IFERROR(MATCH(12,'02_Topic_Register'!$R$4:$R$33,0)+3,"")-3)))} | D20: {=IF($B20="","",INDEX('02_Topic_Register'!$F$4:$F$33,(IFERROR(MATCH(12,'02_Topic_Register'!$R$4:$R$33,0)+3,"")-3)))} | E20: {=IF($B20="","",IF(IFERROR(MAX(IF('04_Update_History'!$D$4:$D$153=INDEX('02_Topic_Register'!$B$4:$B$33,(IFERROR(MATCH(12,'02_Topic_Register'!$R$4:$R$33,0)+3,"")-3)),ROW('04_Update_History'!$D$4:$D$153))),0)=0,"",INDEX('04_Update_History'!$F$4:$F$153,(IFERROR(MAX(IF('04_Update_History'!$D$4:$D$153=INDEX('02_Topic_Register'!$B$4:$B$33,(IFERROR(MATCH(12,'02_Topic_Register'!$R$4:$R$33,0)+3,"")-3)),ROW('04_Update_History'!$D$4:$D$153))),0)-3))))} | F20: {=IF($B20="","",INDEX('02_Topic_Register'!$G$4:$G$33,(IFERROR(MATCH(12,'02_Topic_Register'!$R$4:$R$33,0)+3,"")-3)))} | G20: {=IF($B20="","",IF(IFERROR(MATCH(IFERROR(INDEX('02_Topic_Register'!$N$4:$N$33,(IFERROR(MATCH(12,'02_Topic_Register'!$R$4:$R$33,0)+3,"")-3)),""),'03_Action_Register'!$B$4:$B$33,0),"")="","",INDEX('03_Action_Register'!$D$4:$D$33,IFERROR(MATCH(IFERROR(INDEX('02_Topic_Register'!$N$4:$N$33,(IFERROR(MATCH(12,'02_Topic_Register'!$R$4:$R$33,0)+3,"")-3)),""),'03_Action_Register'!$B$4:$B$33,0),""))))} | H20: {=IF($B20="","",IF(IFERROR(MATCH(IFERROR(INDEX('02_Topic_Register'!$N$4:$N$33,(IFERROR(MATCH(12,'02_Topic_Register'!$R$4:$R$33,0)+3,"")-3)),""),'03_Action_Register'!$B$4:$B$33,0),"")="","",INDEX('03_Action_Register'!$E$4:$E$33,IFERROR(MATCH(IFERROR(INDEX('02_Topic_Register'!$N$4:$N$33,(IFERROR(MATCH(12,'02_Topic_Register'!$R$4:$R$33,0)+3,"")-3)),""),'03_Action_Register'!$B$4:$B$33,0),""))))} | I20: {=IF($B20="","",IF(IFERROR(MATCH(IFERROR(INDEX('02_Topic_Register'!$N$4:$N$33,(IFERROR(MATCH(12,'02_Topic_Register'!$R$4:$R$33,0)+3,"")-3)),""),'03_Action_Register'!$B$4:$B$33,0),"")="","",INDEX('03_Action_Register'!$H$4:$H$33,IFERROR(MATCH(IFERROR(INDEX('02_Topic_Register'!$N$4:$N$33,(IFERROR(MATCH(12,'02_Topic_Register'!$R$4:$R$33,0)+3,"")-3)),""),'03_Action_Register'!$B$4:$B$33,0),""))))} | J20: =IF($B20="","",IF($F20<>"","Yes - input needed","Update only"))
B21: {=IF(IFERROR(MATCH(13,'02_Topic_Register'!$R$4:$R$33,0)+3,"")="","",INDEX('02_Topic_Register'!$B$4:$B$33,(IFERROR(MATCH(13,'02_Topic_Register'!$R$4:$R$33,0)+3,"")-3)))} | C21: {=IF($B21="","",INDEX('02_Topic_Register'!$E$4:$E$33,(IFERROR(MATCH(13,'02_Topic_Register'!$R$4:$R$33,0)+3,"")-3)))} | D21: {=IF($B21="","",INDEX('02_Topic_Register'!$F$4:$F$33,(IFERROR(MATCH(13,'02_Topic_Register'!$R$4:$R$33,0)+3,"")-3)))} | E21: {=IF($B21="","",IF(IFERROR(MAX(IF('04_Update_History'!$D$4:$D$153=INDEX('02_Topic_Register'!$B$4:$B$33,(IFERROR(MATCH(13,'02_Topic_Register'!$R$4:$R$33,0)+3,"")-3)),ROW('04_Update_History'!$D$4:$D$153))),0)=0,"",INDEX('04_Update_History'!$F$4:$F$153,(IFERROR(MAX(IF('04_Update_History'!$D$4:$D$153=INDEX('02_Topic_Register'!$B$4:$B$33,(IFERROR(MATCH(13,'02_Topic_Register'!$R$4:$R$33,0)+3,"")-3)),ROW('04_Update_History'!$D$4:$D$153))),0)-3))))} | F21: {=IF($B21="","",INDEX('02_Topic_Register'!$G$4:$G$33,(IFERROR(MATCH(13,'02_Topic_Register'!$R$4:$R$33,0)+3,"")-3)))} | G21: {=IF($B21="","",IF(IFERROR(MATCH(IFERROR(INDEX('02_Topic_Register'!$N$4:$N$33,(IFERROR(MATCH(13,'02_Topic_Register'!$R$4:$R$33,0)+3,"")-3)),""),'03_Action_Register'!$B$4:$B$33,0),"")="","",INDEX('03_Action_Register'!$D$4:$D$33,IFERROR(MATCH(IFERROR(INDEX('02_Topic_Register'!$N$4:$N$33,(IFERROR(MATCH(13,'02_Topic_Register'!$R$4:$R$33,0)+3,"")-3)),""),'03_Action_Register'!$B$4:$B$33,0),""))))} | H21: {=IF($B21="","",IF(IFERROR(MATCH(IFERROR(INDEX('02_Topic_Register'!$N$4:$N$33,(IFERROR(MATCH(13,'02_Topic_Register'!$R$4:$R$33,0)+3,"")-3)),""),'03_Action_Register'!$B$4:$B$33,0),"")="","",INDEX('03_Action_Register'!$E$4:$E$33,IFERROR(MATCH(IFERROR(INDEX('02_Topic_Register'!$N$4:$N$33,(IFERROR(MATCH(13,'02_Topic_Register'!$R$4:$R$33,0)+3,"")-3)),""),'03_Action_Register'!$B$4:$B$33,0),""))))} | I21: {=IF($B21="","",IF(IFERROR(MATCH(IFERROR(INDEX('02_Topic_Register'!$N$4:$N$33,(IFERROR(MATCH(13,'02_Topic_Register'!$R$4:$R$33,0)+3,"")-3)),""),'03_Action_Register'!$B$4:$B$33,0),"")="","",INDEX('03_Action_Register'!$H$4:$H$33,IFERROR(MATCH(IFERROR(INDEX('02_Topic_Register'!$N$4:$N$33,(IFERROR(MATCH(13,'02_Topic_Register'!$R$4:$R$33,0)+3,"")-3)),""),'03_Action_Register'!$B$4:$B$33,0),""))))} | J21: =IF($B21="","",IF($F21<>"","Yes - input needed","Update only"))
B22: {=IF(IFERROR(MATCH(14,'02_Topic_Register'!$R$4:$R$33,0)+3,"")="","",INDEX('02_Topic_Register'!$B$4:$B$33,(IFERROR(MATCH(14,'02_Topic_Register'!$R$4:$R$33,0)+3,"")-3)))} | C22: {=IF($B22="","",INDEX('02_Topic_Register'!$E$4:$E$33,(IFERROR(MATCH(14,'02_Topic_Register'!$R$4:$R$33,0)+3,"")-3)))} | D22: {=IF($B22="","",INDEX('02_Topic_Register'!$F$4:$F$33,(IFERROR(MATCH(14,'02_Topic_Register'!$R$4:$R$33,0)+3,"")-3)))} | E22: {=IF($B22="","",IF(IFERROR(MAX(IF('04_Update_History'!$D$4:$D$153=INDEX('02_Topic_Register'!$B$4:$B$33,(IFERROR(MATCH(14,'02_Topic_Register'!$R$4:$R$33,0)+3,"")-3)),ROW('04_Update_History'!$D$4:$D$153))),0)=0,"",INDEX('04_Update_History'!$F$4:$F$153,(IFERROR(MAX(IF('04_Update_History'!$D$4:$D$153=INDEX('02_Topic_Register'!$B$4:$B$33,(IFERROR(MATCH(14,'02_Topic_Register'!$R$4:$R$33,0)+3,"")-3)),ROW('04_Update_History'!$D$4:$D$153))),0)-3))))} | F22: {=IF($B22="","",INDEX('02_Topic_Register'!$G$4:$G$33,(IFERROR(MATCH(14,'02_Topic_Register'!$R$4:$R$33,0)+3,"")-3)))} | G22: {=IF($B22="","",IF(IFERROR(MATCH(IFERROR(INDEX('02_Topic_Register'!$N$4:$N$33,(IFERROR(MATCH(14,'02_Topic_Register'!$R$4:$R$33,0)+3,"")-3)),""),'03_Action_Register'!$B$4:$B$33,0),"")="","",INDEX('03_Action_Register'!$D$4:$D$33,IFERROR(MATCH(IFERROR(INDEX('02_Topic_Register'!$N$4:$N$33,(IFERROR(MATCH(14,'02_Topic_Register'!$R$4:$R$33,0)+3,"")-3)),""),'03_Action_Register'!$B$4:$B$33,0),""))))} | H22: {=IF($B22="","",IF(IFERROR(MATCH(IFERROR(INDEX('02_Topic_Register'!$N$4:$N$33,(IFERROR(MATCH(14,'02_Topic_Register'!$R$4:$R$33,0)+3,"")-3)),""),'03_Action_Register'!$B$4:$B$33,0),"")="","",INDEX('03_Action_Register'!$E$4:$E$33,IFERROR(MATCH(IFERROR(INDEX('02_Topic_Register'!$N$4:$N$33,(IFERROR(MATCH(14,'02_Topic_Register'!$R$4:$R$33,0)+3,"")-3)),""),'03_Action_Register'!$B$4:$B$33,0),""))))} | I22: {=IF($B22="","",IF(IFERROR(MATCH(IFERROR(INDEX('02_Topic_Register'!$N$4:$N$33,(IFERROR(MATCH(14,'02_Topic_Register'!$R$4:$R$33,0)+3,"")-3)),""),'03_Action_Register'!$B$4:$B$33,0),"")="","",INDEX('03_Action_Register'!$H$4:$H$33,IFERROR(MATCH(IFERROR(INDEX('02_Topic_Register'!$N$4:$N$33,(IFERROR(MATCH(14,'02_Topic_Register'!$R$4:$R$33,0)+3,"")-3)),""),'03_Action_Register'!$B$4:$B$33,0),""))))} | J22: =IF($B22="","",IF($F22<>"","Yes - input needed","Update only"))
B23: {=IF(IFERROR(MATCH(15,'02_Topic_Register'!$R$4:$R$33,0)+3,"")="","",INDEX('02_Topic_Register'!$B$4:$B$33,(IFERROR(MATCH(15,'02_Topic_Register'!$R$4:$R$33,0)+3,"")-3)))} | C23: {=IF($B23="","",INDEX('02_Topic_Register'!$E$4:$E$33,(IFERROR(MATCH(15,'02_Topic_Register'!$R$4:$R$33,0)+3,"")-3)))} | D23: {=IF($B23="","",INDEX('02_Topic_Register'!$F$4:$F$33,(IFERROR(MATCH(15,'02_Topic_Register'!$R$4:$R$33,0)+3,"")-3)))} | E23: {=IF($B23="","",IF(IFERROR(MAX(IF('04_Update_History'!$D$4:$D$153=INDEX('02_Topic_Register'!$B$4:$B$33,(IFERROR(MATCH(15,'02_Topic_Register'!$R$4:$R$33,0)+3,"")-3)),ROW('04_Update_History'!$D$4:$D$153))),0)=0,"",INDEX('04_Update_History'!$F$4:$F$153,(IFERROR(MAX(IF('04_Update_History'!$D$4:$D$153=INDEX('02_Topic_Register'!$B$4:$B$33,(IFERROR(MATCH(15,'02_Topic_Register'!$R$4:$R$33,0)+3,"")-3)),ROW('04_Update_History'!$D$4:$D$153))),0)-3))))} | F23: {=IF($B23="","",INDEX('02_Topic_Register'!$G$4:$G$33,(IFERROR(MATCH(15,'02_Topic_Register'!$R$4:$R$33,0)+3,"")-3)))} | G23: {=IF($B23="","",IF(IFERROR(MATCH(IFERROR(INDEX('02_Topic_Register'!$N$4:$N$33,(IFERROR(MATCH(15,'02_Topic_Register'!$R$4:$R$33,0)+3,"")-3)),""),'03_Action_Register'!$B$4:$B$33,0),"")="","",INDEX('03_Action_Register'!$D$4:$D$33,IFERROR(MATCH(IFERROR(INDEX('02_Topic_Register'!$N$4:$N$33,(IFERROR(MATCH(15,'02_Topic_Register'!$R$4:$R$33,0)+3,"")-3)),""),'03_Action_Register'!$B$4:$B$33,0),""))))} | H23: {=IF($B23="","",IF(IFERROR(MATCH(IFERROR(INDEX('02_Topic_Register'!$N$4:$N$33,(IFERROR(MATCH(15,'02_Topic_Register'!$R$4:$R$33,0)+3,"")-3)),""),'03_Action_Register'!$B$4:$B$33,0),"")="","",INDEX('03_Action_Register'!$E$4:$E$33,IFERROR(MATCH(IFERROR(INDEX('02_Topic_Register'!$N$4:$N$33,(IFERROR(MATCH(15,'02_Topic_Register'!$R$4:$R$33,0)+3,"")-3)),""),'03_Action_Register'!$B$4:$B$33,0),""))))} | I23: {=IF($B23="","",IF(IFERROR(MATCH(IFERROR(INDEX('02_Topic_Register'!$N$4:$N$33,(IFERROR(MATCH(15,'02_Topic_Register'!$R$4:$R$33,0)+3,"")-3)),""),'03_Action_Register'!$B$4:$B$33,0),"")="","",INDEX('03_Action_Register'!$H$4:$H$33,IFERROR(MATCH(IFERROR(INDEX('02_Topic_Register'!$N$4:$N$33,(IFERROR(MATCH(15,'02_Topic_Register'!$R$4:$R$33,0)+3,"")-3)),""),'03_Action_Register'!$B$4:$B$33,0),""))))} | J23: =IF($B23="","",IF($F23<>"","Yes - input needed","Update only"))
B24: {=IF(IFERROR(MATCH(16,'02_Topic_Register'!$R$4:$R$33,0)+3,"")="","",INDEX('02_Topic_Register'!$B$4:$B$33,(IFERROR(MATCH(16,'02_Topic_Register'!$R$4:$R$33,0)+3,"")-3)))} | C24: {=IF($B24="","",INDEX('02_Topic_Register'!$E$4:$E$33,(IFERROR(MATCH(16,'02_Topic_Register'!$R$4:$R$33,0)+3,"")-3)))} | D24: {=IF($B24="","",INDEX('02_Topic_Register'!$F$4:$F$33,(IFERROR(MATCH(16,'02_Topic_Register'!$R$4:$R$33,0)+3,"")-3)))} | E24: {=IF($B24="","",IF(IFERROR(MAX(IF('04_Update_History'!$D$4:$D$153=INDEX('02_Topic_Register'!$B$4:$B$33,(IFERROR(MATCH(16,'02_Topic_Register'!$R$4:$R$33,0)+3,"")-3)),ROW('04_Update_History'!$D$4:$D$153))),0)=0,"",INDEX('04_Update_History'!$F$4:$F$153,(IFERROR(MAX(IF('04_Update_History'!$D$4:$D$153=INDEX('02_Topic_Register'!$B$4:$B$33,(IFERROR(MATCH(16,'02_Topic_Register'!$R$4:$R$33,0)+3,"")-3)),ROW('04_Update_History'!$D$4:$D$153))),0)-3))))} | F24: {=IF($B24="","",INDEX('02_Topic_Register'!$G$4:$G$33,(IFERROR(MATCH(16,'02_Topic_Register'!$R$4:$R$33,0)+3,"")-3)))} | G24: {=IF($B24="","",IF(IFERROR(MATCH(IFERROR(INDEX('02_Topic_Register'!$N$4:$N$33,(IFERROR(MATCH(16,'02_Topic_Register'!$R$4:$R$33,0)+3,"")-3)),""),'03_Action_Register'!$B$4:$B$33,0),"")="","",INDEX('03_Action_Register'!$D$4:$D$33,IFERROR(MATCH(IFERROR(INDEX('02_Topic_Register'!$N$4:$N$33,(IFERROR(MATCH(16,'02_Topic_Register'!$R$4:$R$33,0)+3,"")-3)),""),'03_Action_Register'!$B$4:$B$33,0),""))))} | H24: {=IF($B24="","",IF(IFERROR(MATCH(IFERROR(INDEX('02_Topic_Register'!$N$4:$N$33,(IFERROR(MATCH(16,'02_Topic_Register'!$R$4:$R$33,0)+3,"")-3)),""),'03_Action_Register'!$B$4:$B$33,0),"")="","",INDEX('03_Action_Register'!$E$4:$E$33,IFERROR(MATCH(IFERROR(INDEX('02_Topic_Register'!$N$4:$N$33,(IFERROR(MATCH(16,'02_Topic_Register'!$R$4:$R$33,0)+3,"")-3)),""),'03_Action_Register'!$B$4:$B$33,0),""))))} | I24: {=IF($B24="","",IF(IFERROR(MATCH(IFERROR(INDEX('02_Topic_Register'!$N$4:$N$33,(IFERROR(MATCH(16,'02_Topic_Register'!$R$4:$R$33,0)+3,"")-3)),""),'03_Action_Register'!$B$4:$B$33,0),"")="","",INDEX('03_Action_Register'!$H$4:$H$33,IFERROR(MATCH(IFERROR(INDEX('02_Topic_Register'!$N$4:$N$33,(IFERROR(MATCH(16,'02_Topic_Register'!$R$4:$R$33,0)+3,"")-3)),""),'03_Action_Register'!$B$4:$B$33,0),""))))} | J24: =IF($B24="","",IF($F24<>"","Yes - input needed","Update only"))
B25: {=IF(IFERROR(MATCH(17,'02_Topic_Register'!$R$4:$R$33,0)+3,"")="","",INDEX('02_Topic_Register'!$B$4:$B$33,(IFERROR(MATCH(17,'02_Topic_Register'!$R$4:$R$33,0)+3,"")-3)))} | C25: {=IF($B25="","",INDEX('02_Topic_Register'!$E$4:$E$33,(IFERROR(MATCH(17,'02_Topic_Register'!$R$4:$R$33,0)+3,"")-3)))} | D25: {=IF($B25="","",INDEX('02_Topic_Register'!$F$4:$F$33,(IFERROR(MATCH(17,'02_Topic_Register'!$R$4:$R$33,0)+3,"")-3)))} | E25: {=IF($B25="","",IF(IFERROR(MAX(IF('04_Update_History'!$D$4:$D$153=INDEX('02_Topic_Register'!$B$4:$B$33,(IFERROR(MATCH(17,'02_Topic_Register'!$R$4:$R$33,0)+3,"")-3)),ROW('04_Update_History'!$D$4:$D$153))),0)=0,"",INDEX('04_Update_History'!$F$4:$F$153,(IFERROR(MAX(IF('04_Update_History'!$D$4:$D$153=INDEX('02_Topic_Register'!$B$4:$B$33,(IFERROR(MATCH(17,'02_Topic_Register'!$R$4:$R$33,0)+3,"")-3)),ROW('04_Update_History'!$D$4:$D$153))),0)-3))))} | F25: {=IF($B25="","",INDEX('02_Topic_Register'!$G$4:$G$33,(IFERROR(MATCH(17,'02_Topic_Register'!$R$4:$R$33,0)+3,"")-3)))} | G25: {=IF($B25="","",IF(IFERROR(MATCH(IFERROR(INDEX('02_Topic_Register'!$N$4:$N$33,(IFERROR(MATCH(17,'02_Topic_Register'!$R$4:$R$33,0)+3,"")-3)),""),'03_Action_Register'!$B$4:$B$33,0),"")="","",INDEX('03_Action_Register'!$D$4:$D$33,IFERROR(MATCH(IFERROR(INDEX('02_Topic_Register'!$N$4:$N$33,(IFERROR(MATCH(17,'02_Topic_Register'!$R$4:$R$33,0)+3,"")-3)),""),'03_Action_Register'!$B$4:$B$33,0),""))))} | H25: {=IF($B25="","",IF(IFERROR(MATCH(IFERROR(INDEX('02_Topic_Register'!$N$4:$N$33,(IFERROR(MATCH(17,'02_Topic_Register'!$R$4:$R$33,0)+3,"")-3)),""),'03_Action_Register'!$B$4:$B$33,0),"")="","",INDEX('03_Action_Register'!$E$4:$E$33,IFERROR(MATCH(IFERROR(INDEX('02_Topic_Register'!$N$4:$N$33,(IFERROR(MATCH(17,'02_Topic_Register'!$R$4:$R$33,0)+3,"")-3)),""),'03_Action_Register'!$B$4:$B$33,0),""))))} | I25: {=IF($B25="","",IF(IFERROR(MATCH(IFERROR(INDEX('02_Topic_Register'!$N$4:$N$33,(IFERROR(MATCH(17,'02_Topic_Register'!$R$4:$R$33,0)+3,"")-3)),""),'03_Action_Register'!$B$4:$B$33,0),"")="","",INDEX('03_Action_Register'!$H$4:$H$33,IFERROR(MATCH(IFERROR(INDEX('02_Topic_Register'!$N$4:$N$33,(IFERROR(MATCH(17,'02_Topic_Register'!$R$4:$R$33,0)+3,"")-3)),""),'03_Action_Register'!$B$4:$B$33,0),""))))} | J25: =IF($B25="","",IF($F25<>"","Yes - input needed","Update only"))
B26: {=IF(IFERROR(MATCH(18,'02_Topic_Register'!$R$4:$R$33,0)+3,"")="","",INDEX('02_Topic_Register'!$B$4:$B$33,(IFERROR(MATCH(18,'02_Topic_Register'!$R$4:$R$33,0)+3,"")-3)))} | C26: {=IF($B26="","",INDEX('02_Topic_Register'!$E$4:$E$33,(IFERROR(MATCH(18,'02_Topic_Register'!$R$4:$R$33,0)+3,"")-3)))} | D26: {=IF($B26="","",INDEX('02_Topic_Register'!$F$4:$F$33,(IFERROR(MATCH(18,'02_Topic_Register'!$R$4:$R$33,0)+3,"")-3)))} | E26: {=IF($B26="","",IF(IFERROR(MAX(IF('04_Update_History'!$D$4:$D$153=INDEX('02_Topic_Register'!$B$4:$B$33,(IFERROR(MATCH(18,'02_Topic_Register'!$R$4:$R$33,0)+3,"")-3)),ROW('04_Update_History'!$D$4:$D$153))),0)=0,"",INDEX('04_Update_History'!$F$4:$F$153,(IFERROR(MAX(IF('04_Update_History'!$D$4:$D$153=INDEX('02_Topic_Register'!$B$4:$B$33,(IFERROR(MATCH(18,'02_Topic_Register'!$R$4:$R$33,0)+3,"")-3)),ROW('04_Update_History'!$D$4:$D$153))),0)-3))))} | F26: {=IF($B26="","",INDEX('02_Topic_Register'!$G$4:$G$33,(IFERROR(MATCH(18,'02_Topic_Register'!$R$4:$R$33,0)+3,"")-3)))} | G26: {=IF($B26="","",IF(IFERROR(MATCH(IFERROR(INDEX('02_Topic_Register'!$N$4:$N$33,(IFERROR(MATCH(18,'02_Topic_Register'!$R$4:$R$33,0)+3,"")-3)),""),'03_Action_Register'!$B$4:$B$33,0),"")="","",INDEX('03_Action_Register'!$D$4:$D$33,IFERROR(MATCH(IFERROR(INDEX('02_Topic_Register'!$N$4:$N$33,(IFERROR(MATCH(18,'02_Topic_Register'!$R$4:$R$33,0)+3,"")-3)),""),'03_Action_Register'!$B$4:$B$33,0),""))))} | H26: {=IF($B26="","",IF(IFERROR(MATCH(IFERROR(INDEX('02_Topic_Register'!$N$4:$N$33,(IFERROR(MATCH(18,'02_Topic_Register'!$R$4:$R$33,0)+3,"")-3)),""),'03_Action_Register'!$B$4:$B$33,0),"")="","",INDEX('03_Action_Register'!$E$4:$E$33,IFERROR(MATCH(IFERROR(INDEX('02_Topic_Register'!$N$4:$N$33,(IFERROR(MATCH(18,'02_Topic_Register'!$R$4:$R$33,0)+3,"")-3)),""),'03_Action_Register'!$B$4:$B$33,0),""))))} | I26: {=IF($B26="","",IF(IFERROR(MATCH(IFERROR(INDEX('02_Topic_Register'!$N$4:$N$33,(IFERROR(MATCH(18,'02_Topic_Register'!$R$4:$R$33,0)+3,"")-3)),""),'03_Action_Register'!$B$4:$B$33,0),"")="","",INDEX('03_Action_Register'!$H$4:$H$33,IFERROR(MATCH(IFERROR(INDEX('02_Topic_Register'!$N$4:$N$33,(IFERROR(MATCH(18,'02_Topic_Register'!$R$4:$R$33,0)+3,"")-3)),""),'03_Action_Register'!$B$4:$B$33,0),""))))} | J26: =IF($B26="","",IF($F26<>"","Yes - input needed","Update only"))
B27: {=IF(IFERROR(MATCH(19,'02_Topic_Register'!$R$4:$R$33,0)+3,"")="","",INDEX('02_Topic_Register'!$B$4:$B$33,(IFERROR(MATCH(19,'02_Topic_Register'!$R$4:$R$33,0)+3,"")-3)))} | C27: {=IF($B27="","",INDEX('02_Topic_Register'!$E$4:$E$33,(IFERROR(MATCH(19,'02_Topic_Register'!$R$4:$R$33,0)+3,"")-3)))} | D27: {=IF($B27="","",INDEX('02_Topic_Register'!$F$4:$F$33,(IFERROR(MATCH(19,'02_Topic_Register'!$R$4:$R$33,0)+3,"")-3)))} | E27: {=IF($B27="","",IF(IFERROR(MAX(IF('04_Update_History'!$D$4:$D$153=INDEX('02_Topic_Register'!$B$4:$B$33,(IFERROR(MATCH(19,'02_Topic_Register'!$R$4:$R$33,0)+3,"")-3)),ROW('04_Update_History'!$D$4:$D$153))),0)=0,"",INDEX('04_Update_History'!$F$4:$F$153,(IFERROR(MAX(IF('04_Update_History'!$D$4:$D$153=INDEX('02_Topic_Register'!$B$4:$B$33,(IFERROR(MATCH(19,'02_Topic_Register'!$R$4:$R$33,0)+3,"")-3)),ROW('04_Update_History'!$D$4:$D$153))),0)-3))))} | F27: {=IF($B27="","",INDEX('02_Topic_Register'!$G$4:$G$33,(IFERROR(MATCH(19,'02_Topic_Register'!$R$4:$R$33,0)+3,"")-3)))} | G27: {=IF($B27="","",IF(IFERROR(MATCH(IFERROR(INDEX('02_Topic_Register'!$N$4:$N$33,(IFERROR(MATCH(19,'02_Topic_Register'!$R$4:$R$33,0)+3,"")-3)),""),'03_Action_Register'!$B$4:$B$33,0),"")="","",INDEX('03_Action_Register'!$D$4:$D$33,IFERROR(MATCH(IFERROR(INDEX('02_Topic_Register'!$N$4:$N$33,(IFERROR(MATCH(19,'02_Topic_Register'!$R$4:$R$33,0)+3,"")-3)),""),'03_Action_Register'!$B$4:$B$33,0),""))))} | H27: {=IF($B27="","",IF(IFERROR(MATCH(IFERROR(INDEX('02_Topic_Register'!$N$4:$N$33,(IFERROR(MATCH(19,'02_Topic_Register'!$R$4:$R$33,0)+3,"")-3)),""),'03_Action_Register'!$B$4:$B$33,0),"")="","",INDEX('03_Action_Register'!$E$4:$E$33,IFERROR(MATCH(IFERROR(INDEX('02_Topic_Register'!$N$4:$N$33,(IFERROR(MATCH(19,'02_Topic_Register'!$R$4:$R$33,0)+3,"")-3)),""),'03_Action_Register'!$B$4:$B$33,0),""))))} | I27: {=IF($B27="","",IF(IFERROR(MATCH(IFERROR(INDEX('02_Topic_Register'!$N$4:$N$33,(IFERROR(MATCH(19,'02_Topic_Register'!$R$4:$R$33,0)+3,"")-3)),""),'03_Action_Register'!$B$4:$B$33,0),"")="","",INDEX('03_Action_Register'!$H$4:$H$33,IFERROR(MATCH(IFERROR(INDEX('02_Topic_Register'!$N$4:$N$33,(IFERROR(MATCH(19,'02_Topic_Register'!$R$4:$R$33,0)+3,"")-3)),""),'03_Action_Register'!$B$4:$B$33,0),""))))} | J27: =IF($B27="","",IF($F27<>"","Yes - input needed","Update only"))
B28: {=IF(IFERROR(MATCH(20,'02_Topic_Register'!$R$4:$R$33,0)+3,"")="","",INDEX('02_Topic_Register'!$B$4:$B$33,(IFERROR(MATCH(20,'02_Topic_Register'!$R$4:$R$33,0)+3,"")-3)))} | C28: {=IF($B28="","",INDEX('02_Topic_Register'!$E$4:$E$33,(IFERROR(MATCH(20,'02_Topic_Register'!$R$4:$R$33,0)+3,"")-3)))} | D28: {=IF($B28="","",INDEX('02_Topic_Register'!$F$4:$F$33,(IFERROR(MATCH(20,'02_Topic_Register'!$R$4:$R$33,0)+3,"")-3)))} | E28: {=IF($B28="","",IF(IFERROR(MAX(IF('04_Update_History'!$D$4:$D$153=INDEX('02_Topic_Register'!$B$4:$B$33,(IFERROR(MATCH(20,'02_Topic_Register'!$R$4:$R$33,0)+3,"")-3)),ROW('04_Update_History'!$D$4:$D$153))),0)=0,"",INDEX('04_Update_History'!$F$4:$F$153,(IFERROR(MAX(IF('04_Update_History'!$D$4:$D$153=INDEX('02_Topic_Register'!$B$4:$B$33,(IFERROR(MATCH(20,'02_Topic_Register'!$R$4:$R$33,0)+3,"")-3)),ROW('04_Update_History'!$D$4:$D$153))),0)-3))))} | F28: {=IF($B28="","",INDEX('02_Topic_Register'!$G$4:$G$33,(IFERROR(MATCH(20,'02_Topic_Register'!$R$4:$R$33,0)+3,"")-3)))} | G28: {=IF($B28="","",IF(IFERROR(MATCH(IFERROR(INDEX('02_Topic_Register'!$N$4:$N$33,(IFERROR(MATCH(20,'02_Topic_Register'!$R$4:$R$33,0)+3,"")-3)),""),'03_Action_Register'!$B$4:$B$33,0),"")="","",INDEX('03_Action_Register'!$D$4:$D$33,IFERROR(MATCH(IFERROR(INDEX('02_Topic_Register'!$N$4:$N$33,(IFERROR(MATCH(20,'02_Topic_Register'!$R$4:$R$33,0)+3,"")-3)),""),'03_Action_Register'!$B$4:$B$33,0),""))))} | H28: {=IF($B28="","",IF(IFERROR(MATCH(IFERROR(INDEX('02_Topic_Register'!$N$4:$N$33,(IFERROR(MATCH(20,'02_Topic_Register'!$R$4:$R$33,0)+3,"")-3)),""),'03_Action_Register'!$B$4:$B$33,0),"")="","",INDEX('03_Action_Register'!$E$4:$E$33,IFERROR(MATCH(IFERROR(INDEX('02_Topic_Register'!$N$4:$N$33,(IFERROR(MATCH(20,'02_Topic_Register'!$R$4:$R$33,0)+3,"")-3)),""),'03_Action_Register'!$B$4:$B$33,0),""))))} | I28: {=IF($B28="","",IF(IFERROR(MATCH(IFERROR(INDEX('02_Topic_Register'!$N$4:$N$33,(IFERROR(MATCH(20,'02_Topic_Register'!$R$4:$R$33,0)+3,"")-3)),""),'03_Action_Register'!$B$4:$B$33,0),"")="","",INDEX('03_Action_Register'!$H$4:$H$33,IFERROR(MATCH(IFERROR(INDEX('02_Topic_Register'!$N$4:$N$33,(IFERROR(MATCH(20,'02_Topic_Register'!$R$4:$R$33,0)+3,"")-3)),""),'03_Action_Register'!$B$4:$B$33,0),""))))} | J28: =IF($B28="","",IF($F28<>"","Yes - input needed","Update only"))

Sheet 02_Topic_Register
B2: Topic Register | G2: Legend: Blue text = fill in yourself | Black text = automatic formula, do not overtype | Grey columns = automation helpers, do not edit
B3: Topic ID | C3: Category | D3: Sub-category | E3: Topic | F3: Current Position | G3: Outstanding Point / Question | H3: Status | I3: Priority | J3: Owner | K3: Last Update | L3: Next Step | M3: Discuss at Next Meeting? | N3: Related Action ID | O3: Related PQCP Requirement | P3: Related Document / Evidence | Q3: Flag | R3: Rank
B4: =IF(COUNTA($E4)=0,"","T"&TEXT(ROW()-3,"000")) | C4: Systems & Equipment | D4: Pump Skid A | E4: Pump skid A commissioning sequence | F4: Functional test completed; awaiting punch list closure. | G4: Punch list item #4 (instrumentation calibration) still open. | H4: Open | I4: High | J4: J. Smith | K4: {=IF($B4="","",IF(IFERROR(MAX(IF('04_Update_History'!$D$4:$D$153=$B4,ROW('04_Update_History'!$D$4:$D$153))),0)=0,"",INDEX('04_Update_History'!$C$4:$C$153,IFERROR(MAX(IF('04_Update_History'!$D$4:$D$153=$B4,ROW('04_Update_History'!$D$4:$D$153))),0)-3)))} | L4: Confirm calibration certificate received. | M4: Yes | N4: A001 | O4: P001 | P4: E001 | Q4: =IF($B4="",0,IF(OR($M4="Yes",COUNTIFS('03_Action_Register'!$C$4:$C$33,$B4,'03_Action_Register'!$M$4:$M$33,"Yes")>0,$G4<>""),1,0)) | R4: =IF($Q4=1,SUM($Q$4:$Q4),"")
B5: =IF(COUNTA($E5)=0,"","T"&TEXT(ROW()-3,"000")) | C5: Documentation | D5: ITP Register | E5: Inspection & Test Plan sign-off backlog | F5: 6 of 10 ITPs signed off by the contractor. | G5: 4 ITPs pending contractor signature. | H5: Monitoring | I5: Medium | J5: A. Diallo | K5: {=IF($B5="","",IF(IFERROR(MAX(IF('04_Update_History'!$D$4:$D$153=$B5,ROW('04_Update_History'!$D$4:$D$153))),0)=0,"",INDEX('04_Update_History'!$C$4:$C$153,IFERROR(MAX(IF('04_Update_History'!$D$4:$D$153=$B5,ROW('04_Update_History'!$D$4:$D$153))),0)-3)))} | L5: Escalate to contractor PM if no response. | M5: No | N5: A002 | O5: P002 | P5: E002 | Q5: =IF($B5="",0,IF(OR($M5="Yes",COUNTIFS('03_Action_Register'!$C$4:$C$33,$B5,'03_Action_Register'!$M$4:$M$33,"Yes")>0,$G5<>""),1,0)) | R5: =IF($Q5=1,SUM($Q$4:$Q5),"")
B6: =IF(COUNTA($E6)=0,"","T"&TEXT(ROW()-3,"000")) | C6: Interfaces | D6: Electrical / Mechanical | E6: Interface clearance for Skid B power feed | F6: Interface closed - confirmed by both parties. | H6: Closed | I6: Low | J6: M. Chen | K6: {=IF($B6="","",IF(IFERROR(MAX(IF('04_Update_History'!$D$4:$D$153=$B6,ROW('04_Update_History'!$D$4:$D$153))),0)=0,"",INDEX('04_Update_History'!$C$4:$C$153,IFERROR(MAX(IF('04_Update_History'!$D$4:$D$153=$B6,ROW('04_Update_History'!$D$4:$D$153))),0)-3)))} | L6: None - closed. | M6: No | N6: A003 | P6: E002 | Q6: =IF($B6="",0,IF(OR($M6="Yes",COUNTIFS('03_Action_Register'!$C$4:$C$33,$B6,'03_Action_Register'!$M$4:$M$33,"Yes")>0,$G6<>""),1,0)) | R6: =IF($Q6=1,SUM($Q$4:$Q6),"")
B7: =IF(COUNTA($E7)=0,"","T"&TEXT(ROW()-3,"000")) | K7: {=IF($B7="","",IF(IFERROR(MAX(IF('04_Update_History'!$D$4:$D$153=$B7,ROW('04_Update_History'!$D$4:$D$153))),0)=0,"",INDEX('04_Update_History'!$C$4:$C$153,IFERROR(MAX(IF('04_Update_History'!$D$4:$D$153=$B7,ROW('04_Update_History'!$D$4:$D$153))),0)-3)))} | Q7: =IF($B7="",0,IF(OR($M7="Yes",COUNTIFS('03_Action_Register'!$C$4:$C$33,$B7,'03_Action_Register'!$M$4:$M$33,"Yes")>0,$G7<>""),1,0)) | R7: =IF($Q7=1,SUM($Q$4:$Q7),"")
B8: =IF(COUNTA($E8)=0,"","T"&TEXT(ROW()-3,"000")) | K8: {=IF($B8="","",IF(IFERROR(MAX(IF('04_Update_History'!$D$4:$D$153=$B8,ROW('04_Update_History'!$D$4:$D$153))),0)=0,"",INDEX('04_Update_History'!$C$4:$C$153,IFERROR(MAX(IF('04_Update_History'!$D$4:$D$153=$B8,ROW('04_Update_History'!$D$4:$D$153))),0)-3)))} | Q8: =IF($B8="",0,IF(OR($M8="Yes",COUNTIFS('03_Action_Register'!$C$4:$C$33,$B8,'03_Action_Register'!$M$4:$M$33,"Yes")>0,$G8<>""),1,0)) | R8: =IF($Q8=1,SUM($Q$4:$Q8),"")
B9: =IF(COUNTA($E9)=0,"","T"&TEXT(ROW()-3,"000")) | K9: {=IF($B9="","",IF(IFERROR(MAX(IF('04_Update_History'!$D$4:$D$153=$B9,ROW('04_Update_History'!$D$4:$D$153))),0)=0,"",INDEX('04_Update_History'!$C$4:$C$153,IFERROR(MAX(IF('04_Update_History'!$D$4:$D$153=$B9,ROW('04_Update_History'!$D$4:$D$153))),0)-3)))} | Q9: =IF($B9="",0,IF(OR($M9="Yes",COUNTIFS('03_Action_Register'!$C$4:$C$33,$B9,'03_Action_Register'!$M$4:$M$33,"Yes")>0,$G9<>""),1,0)) | R9: =IF($Q9=1,SUM($Q$4:$Q9),"")
B10: =IF(COUNTA($E10)=0,"","T"&TEXT(ROW()-3,"000")) | K10: {=IF($B10="","",IF(IFERROR(MAX(IF('04_Update_History'!$D$4:$D$153=$B10,ROW('04_Update_History'!$D$4:$D$153))),0)=0,"",INDEX('04_Update_History'!$C$4:$C$153,IFERROR(MAX(IF('04_Update_History'!$D$4:$D$153=$B10,ROW('04_Update_History'!$D$4:$D$153))),0)-3)))} | Q10: =IF($B10="",0,IF(OR($M10="Yes",COUNTIFS('03_Action_Register'!$C$4:$C$33,$B10,'03_Action_Register'!$M$4:$M$33,"Yes")>0,$G10<>""),1,0)) | R10: =IF($Q10=1,SUM($Q$4:$Q10),"")
B11: =IF(COUNTA($E11)=0,"","T"&TEXT(ROW()-3,"000")) | K11: {=IF($B11="","",IF(IFERROR(MAX(IF('04_Update_History'!$D$4:$D$153=$B11,ROW('04_Update_History'!$D$4:$D$153))),0)=0,"",INDEX('04_Update_History'!$C$4:$C$153,IFERROR(MAX(IF('04_Update_History'!$D$4:$D$153=$B11,ROW('04_Update_History'!$D$4:$D$153))),0)-3)))} | Q11: =IF($B11="",0,IF(OR($M11="Yes",COUNTIFS('03_Action_Register'!$C$4:$C$33,$B11,'03_Action_Register'!$M$4:$M$33,"Yes")>0,$G11<>""),1,0)) | R11: =IF($Q11=1,SUM($Q$4:$Q11),"")
B12: =IF(COUNTA($E12)=0,"","T"&TEXT(ROW()-3,"000")) | K12: {=IF($B12="","",IF(IFERROR(MAX(IF('04_Update_History'!$D$4:$D$153=$B12,ROW('04_Update_History'!$D$4:$D$153))),0)=0,"",INDEX('04_Update_History'!$C$4:$C$153,IFERROR(MAX(IF('04_Update_History'!$D$4:$D$153=$B12,ROW('04_Update_History'!$D$4:$D$153))),0)-3)))} | Q12: =IF($B12="",0,IF(OR($M12="Yes",COUNTIFS('03_Action_Register'!$C$4:$C$33,$B12,'03_Action_Register'!$M$4:$M$33,"Yes")>0,$G12<>""),1,0)) | R12: =IF($Q12=1,SUM($Q$4:$Q12),"")
