Workbook

Sheet Read Me
B1: DMIC COMMISSIONING CONTRACT MANAGEMENT WORKBOOK
B2: Built to the specification 'DMIC Commissioning Contract Management Workbook v3'. BLANK TEMPLATE — row 4 of each tracker holds an example; overwrite it with your first real record.
B4: START HERE
B5: 1. Set the driver date | C5: Control Panel → 'Planned Commissioning Start' (amber cell). Every target date in the workbook is generated from it.
B6: 2. Tune the lead times | C6: Control Panel → 'Lead Time Configuration'. Edit the blue Lead Days column; all target dates update.
B7: 3. Enter your scopes | C7: Scope Tracker → one row per commissioning scope. The Scope ID is the key everything else links to.
B8: 4. Enter your equipment | C8: Equipment Tracker → one row per item, each with a Parent Scope and a Commissioning Phase.
B9: 5. Enter your deliverables | C9: Document Tracker → one row per deliverable. Pick a Document Type and the target dates appear.
B10: 6. Work the actions | C10: Action Tracker → rows colour themselves by priority and lateness.
B11: 7. Read the Dashboard | C11: Dashboard → Contract Health Index, the nine executive questions, milestones and nine charts.
B12: CELL COLOUR LEGEND
B13: Amber cell | C13: The single key driver — Planned Commissioning Start.
B14: Blue text, white cell | C14: Your input. Type here.
B15: Grey cell | C15: Calculated. Do not type over it — you would break the roll-up.
B16: DOCUMENT COLOUR CODING (spec)
B17: Grey | C17: Not Started
B18: Blue | C18: Draft
B19: Yellow | C19: Internal Review / Submitted / Under Review / Resubmitted
B20: Orange | C20: Comments Received
B21: Red | C21: Rework (rejected) — and any overdue row
B22: Green | C22: Approved / Released / Implemented
B23: Dark Green | C23: Closed
B24: ACTION COLOUR RULES (spec)
B25: Dark Red | C25: Critical and overdue
B26: Red | C26: Overdue
B27: Amber | C27: Due within 14 days
B28: Blue | C28: In Progress
B29: Green | C29: Closed
B30: Grey | C30: Waiting
B31: HOW READINESS IS CALCULATED
B32: Equipment Readiness | C32: 50% x phase progress + 50% x share of that item's linked documents approved. Equipment with no linked documents uses phase progress alone. Weights: Configuration sheet.
B33: Scope Readiness | C33: Average equipment readiness across the scope's equipment.
B34: Contract Readiness | C34: Average equipment readiness across all equipment.
B35: Contract Health Index | C35: 40% Documents + 20% Readiness + 15% Actions + 10% Milestones + 10% Equipment Progress + 5% Handovers. Weights: Configuration sheet.
B36: ATS Readiness | C36: Share of the 10 spec-mandated deliverables that are fully satisfied — the type exists in the tracker AND none of that type is still outstanding. 100% = Ready, 80%+ = At Risk, below = Not Ready.
B37: ASSUMPTIONS WE HAD TO MAKE
B38: Phase progress ramp | C38: The spec names 11 commissioning phases but gives no % for each. Seeded 0% → 100%; retune on the Configuration sheet.
B39: Months → days | C39: Converted at 30 days per month (T-3 Months = 90), which reproduces the spec's own worked example exactly.
B40: Post-commissioning lead times | C40: 'During Commissioning', 'Before FTC/TFM/TFTO' and 'Before Final Takeover' have no stated duration. Seeded as T+30 to T+120 days.
B41: 'Missing Documents' | C41: Counted as deliverables that exist as a row but are still 'Not Started'. The workbook cannot count a row you never created.
...

Sheet Control Panel
B1: DMIC COMMISSIONING CONTRACT — CONTROL PANEL
B2: Master page. Blue cells are for you to type in; grey cells calculate themselves. The amber cell (Planned Commissioning Start) drives every target date in the workbook.
B4: CONTRACT INFORMATION | F4: CONTRACT READINESS SUMMARY
B5: Contract Name | F5: Overall Contract Readiness % | G5: =IFERROR(AVERAGE(Eq_Readiness),0) -> 0.225
B6: Contract Manager | F6: Number of Scopes | G6: =COUNTA(Sc_ID) -> 1
B7: Project Manager | F7: Number of Equipment Items | G7: =COUNTA(Eq_Name) -> 1
B8: Commissioning Manager | F8: Open Actions | G8: =COUNTA(Act_ID)-COUNTIF(Act_Status,"Closed") -> 1
B9: Lead Commissioning Engineer | F9: Overdue Actions | G9: =SUM(Act_Overdue) -> 0
B10: Quality Lead | F10: Missing Documents | G10: =COUNTIF(Doc_Workflow,"Not Started") -> 0
B11: Contract Status | F11: Open Risks | G11: =COUNTIFS(Act_Blocker,"Yes",Act_Status,"<>Closed") -> 1
F12: Upcoming Milestones | G12: =COUNTIFS(Ms_Days,">=0",Ms_Days,"<="&Cfg_MsWindow) -> 0
B13: COMMISSIONING DATES
B14: Planned Commissioning Start | C14: 46539 | D14: ◀ drives all target dates | F14: RAG STATUS
B15: Planned Commissioning Finish | F15: Contract Health Index | G15: =Dashboard!$L$12 -> 0.56
B16: Forecast Commissioning Start | F16: Health Category | G16: =IF($G$15>=Cfg_ThrExcellent,"Excellent",IF($G$15>=Cfg_ThrGood,"Good",IF($G$15>=Cfg_ThrAttention,"Attention Required","Critical"))) -> Attention Required
B17: Forecast Commissioning Finish | F17: RAG | G17: =IF($G$15>=Cfg_RagGreen,"GREEN",IF($G$15>=Cfg_RagAmber,"AMBER","RED")) -> AMBER
B18: Actual Commissioning Start
B19: Actual Commissioning Finish | F19: AUTHORITY TO START (ATS) READINESS GATE
F20: ATS Readiness Score | G20: =Configuration!$B$57 -> 0
B21: SCHEDULE PERFORMANCE | F21: ATS Status | G21: =Configuration!$B$58 -> Not Ready
B22: Delay vs Baseline (days) | C22: =IF(OR($C$14="",$C$16=""),"",$C$16-$C$14) | F22: Required Types Met | G22: =Configuration!$B$60 -> 0 of 10
B23: Days To Commissioning Start | C23: =IF($C$14="","",$C$14-TODAY()) -> 285 | F23: 'Ready' requires all 10 minimum deliverable types fully approved.
B24: LEGEND
B25: Amber cell | C25: The single key driver — Planned Commissioning Start.
B26: Blue text on white | C26: Type here. These are your inputs.
B27: Grey cell | C27: Calculated automatically — do not type over it.
B29: LEAD TIME CONFIGURATION — DOCUMENTS
B30: Target dates are generated as: Planned Commissioning Start − Lead Days. Edit the blue Lead Days column and every target date in the Document Tracker updates. A negative Lead Day value places the target AFTER commissioning start.
B31: Document Type | C31: Spec Lead Time | D31: Lead Days (T minus) | E31: Target Submission | F31: Target Approval
B32: Basis of Commissioning | C32: T-12 Months | D32: 360 | E32: =IF($F32="","",$F32-Cfg_ReviewDays) -> 46158 | F32: =IF(OR($C$14="",$D32=""),"",$C$14-$D32) -> 46179
B33: Surveillance Strategy | C33: T-12 Months | D33: 360 | E33: =IF($F33="","",$F33-Cfg_ReviewDays) -> 46158 | F33: =IF(OR($C$14="",$D33=""),"",$C$14-$D33) -> 46179
B34: Surveillance Programme | C34: T-9 Months | D34: 270 | E34: =IF($F34="","",$F34-Cfg_ReviewDays) -> 46248 | F34: =IF(OR($C$14="",$D34=""),"",$C$14-$D34) -> 46269
B35: Competency Evidence | C35: T-9 Months | D35: 270 | E35: =IF($F35="","",$F35-Cfg_ReviewDays) -> 46248 | F35: =IF(OR($C$14="",$D35=""),"",$C$14-$D35) -> 46269
B36: Safe System Of Work | C36: T-6 Months | D36: 180 | E36: =IF($F36="","",$F36-Cfg_ReviewDays) -> 46338 | F36: =IF(OR($C$14="",$D36=""),"",$C$14-$D36) -> 46359
B37: Risk Assessment And Method Statement | C37: T-6 Months | D37: 180 | E37: =IF($F37="","",$F37-Cfg_ReviewDays) -> 46338 | F37: =IF(OR($C$14="",$D37=""),"",$C$14-$D37) -> 46359
B38: System Commissioning Programme | C38: T-6 Months | D38: 180 | E38: =IF($F38="","",$F38-Cfg_ReviewDays) -> 46338 | F38: =IF(OR($C$14="",$D38=""),"",$C$14-$D38) -> 46359
B39: Commissioning Procedure | C39: T-3 Months | D39: 90 | E39: =IF($F39="","",$F39-Cfg_ReviewDays) -> 46428 | F39: =IF(OR($C$14="",$D39=""),"",$C$14-$D39) -> 46449
B40: Inspection and Test Plan | C40: T-3 Months | D40: 90 | E40: =IF($F40="","",$F40-Cfg_ReviewDays) -> 46428 | F40: =IF(OR($C$14="",$D40=""),"",$C$14-$D40) -> 46449
B41: Initial End Of Erection Status Report | C41: T-3 Months | D41: 90 | E41: =IF($F41="","",$F41-Cfg_ReviewDays) -> 46428 | F41: =IF(OR($C$14="",$D41=""),"",$C$14-$D41) -> 46449
B42: Planned End Of Erection Status Report | C42: T-1 Month | D42: 30 | E42: =IF($F42="","",$F42-Cfg_ReviewDays) -> 46488 | F42: =IF(OR($C$14="",$D42=""),"",$C$14-$D42) -> 46509
...

Sheet Scope Tracker
A1: SCOPE TRACKER
A2: One row per Commissioning Scope. White columns are inputs; grey columns roll up automatically from the Equipment, Document and Action trackers.
A3: Scope ID | B3: Scope Name | C3: Scope Owner | D3: Planned Start | E3: Planned Finish | F3: Forecast Start | G3: Forecast Finish | H3: Actual Start | I3: Actual Finish | J3: Readiness % | K3: Status | L3: Number of Equipment | M3: Equipment Complete | N3: Equipment In Progress | O3: Equipment Not Started | P3: Open Actions | Q3: Outstanding Documents | R3: Comments
A4: SC-01 | B4: Traction Power & 33kV Distribution | C4: A. Mercer | D4: 46329 | E4: 46659 | F4: 46336 | G4: 46666 | J4: =IF($A4="","",IFERROR(AVERAGEIF(Eq_Scope,$A4,Eq_Readiness),0)) -> 0.225 | K4: In Progress | L4: =IF($A4="","",COUNTIF(Eq_Scope,$A4)) -> 1 | M4: =IF($A4="","",COUNTIFS(Eq_Scope,$A4,Eq_Phase,"Complete")) -> 0 | N4: =IF($A4="","",$L4-$M4-$O4) -> 1 | O4: =IF($A4="","",COUNTIFS(Eq_Scope,$A4,Eq_Phase,"Pre-Commissioning")) -> 0 | P4: =IF($A4="","",COUNTIFS(Act_Scope,$A4,Act_Status,"<>Closed")) -> 1 | Q4: =IF($A4="","",COUNTIFS(Doc_Scope,$A4,Doc_Approved,0)) -> 1 | R4: ◀ EXAMPLE ROW — overwrite with your own data
J5: =IF($A5="","",IFERROR(AVERAGEIF(Eq_Scope,$A5,Eq_Readiness),0)) | L5: =IF($A5="","",COUNTIF(Eq_Scope,$A5)) | M5: =IF($A5="","",COUNTIFS(Eq_Scope,$A5,Eq_Phase,"Complete")) | N5: =IF($A5="","",$L5-$M5-$O5) | O5: =IF($A5="","",COUNTIFS(Eq_Scope,$A5,Eq_Phase,"Pre-Commissioning")) | P5: =IF($A5="","",COUNTIFS(Act_Scope,$A5,Act_Status,"<>Closed")) | Q5: =IF($A5="","",COUNTIFS(Doc_Scope,$A5,Doc_Approved,0))
J6: =IF($A6="","",IFERROR(AVERAGEIF(Eq_Scope,$A6,Eq_Readiness),0)) | L6: =IF($A6="","",COUNTIF(Eq_Scope,$A6)) | M6: =IF($A6="","",COUNTIFS(Eq_Scope,$A6,Eq_Phase,"Complete")) | N6: =IF($A6="","",$L6-$M6-$O6) | O6: =IF($A6="","",COUNTIFS(Eq_Scope,$A6,Eq_Phase,"Pre-Commissioning")) | P6: =IF($A6="","",COUNTIFS(Act_Scope,$A6,Act_Status,"<>Closed")) | Q6: =IF($A6="","",COUNTIFS(Doc_Scope,$A6,Doc_Approved,0))
J7: =IF($A7="","",IFERROR(AVERAGEIF(Eq_Scope,$A7,Eq_Readiness),0)) | L7: =IF($A7="","",COUNTIF(Eq_Scope,$A7)) | M7: =IF($A7="","",COUNTIFS(Eq_Scope,$A7,Eq_Phase,"Complete")) | N7: =IF($A7="","",$L7-$M7-$O7) | O7: =IF($A7="","",COUNTIFS(Eq_Scope,$A7,Eq_Phase,"Pre-Commissioning")) | P7: =IF($A7="","",COUNTIFS(Act_Scope,$A7,Act_Status,"<>Closed")) | Q7: =IF($A7="","",COUNTIFS(Doc_Scope,$A7,Doc_Approved,0))
J8: =IF($A8="","",IFERROR(AVERAGEIF(Eq_Scope,$A8,Eq_Readiness),0)) | L8: =IF($A8="","",COUNTIF(Eq_Scope,$A8)) | M8: =IF($A8="","",COUNTIFS(Eq_Scope,$A8,Eq_Phase,"Complete")) | N8: =IF($A8="","",$L8-$M8-$O8) | O8: =IF($A8="","",COUNTIFS(Eq_Scope,$A8,Eq_Phase,"Pre-Commissioning")) | P8: =IF($A8="","",COUNTIFS(Act_Scope,$A8,Act_Status,"<>Closed")) | Q8: =IF($A8="","",COUNTIFS(Doc_Scope,$A8,Doc_Approved,0))
J9: =IF($A9="","",IFERROR(AVERAGEIF(Eq_Scope,$A9,Eq_Readiness),0)) | L9: =IF($A9="","",COUNTIF(Eq_Scope,$A9)) | M9: =IF($A9="","",COUNTIFS(Eq_Scope,$A9,Eq_Phase,"Complete")) | N9: =IF($A9="","",$L9-$M9-$O9) | O9: =IF($A9="","",COUNTIFS(Eq_Scope,$A9,Eq_Phase,"Pre-Commissioning")) | P9: =IF($A9="","",COUNTIFS(Act_Scope,$A9,Act_Status,"<>Closed")) | Q9: =IF($A9="","",COUNTIFS(Doc_Scope,$A9,Doc_Approved,0))
J10: =IF($A10="","",IFERROR(AVERAGEIF(Eq_Scope,$A10,Eq_Readiness),0)) | L10: =IF($A10="","",COUNTIF(Eq_Scope,$A10)) | M10: =IF($A10="","",COUNTIFS(Eq_Scope,$A10,Eq_Phase,"Complete")) | N10: =IF($A10="","",$L10-$M10-$O10) | O10: =IF($A10="","",COUNTIFS(Eq_Scope,$A10,Eq_Phase,"Pre-Commissioning")) | P10: =IF($A10="","",COUNTIFS(Act_Scope,$A10,Act_Status,"<>Closed")) | Q10: =IF($A10="","",COUNTIFS(Doc_Scope,$A10,Doc_Approved,0))
J11: =IF($A11="","",IFERROR(AVERAGEIF(Eq_Scope,$A11,Eq_Readiness),0)) | L11: =IF($A11="","",COUNTIF(Eq_Scope,$A11)) | M11: =IF($A11="","",COUNTIFS(Eq_Scope,$A11,Eq_Phase,"Complete")) | N11: =IF($A11="","",$L11-$M11-$O11) | O11: =IF($A11="","",COUNTIFS(Eq_Scope,$A11,Eq_Phase,"Pre-Commissioning")) | P11: =IF($A11="","",COUNTIFS(Act_Scope,$A11,Act_Status,"<>Closed")) | Q11: =IF($A11="","",COUNTIFS(Doc_Scope,$A11,Doc_Approved,0))
J12: =IF($A12="","",IFERROR(AVERAGEIF(Eq_Scope,$A12,Eq_Readiness),0)) | L12: =IF($A12="","",COUNTIF(Eq_Scope,$A12)) | M12: =IF($A12="","",COUNTIFS(Eq_Scope,$A12,Eq_Phase,"Complete")) | N12: =IF($A12="","",$L12-$M12-$O12) | O12: =IF($A12="","",COUNTIFS(Eq_Scope,$A12,Eq_Phase,"Pre-Commissioning")) | P12: =IF($A12="","",COUNTIFS(Act_Scope,$A12,Act_Status,"<>Closed")) | Q12: =IF($A12="","",COUNTIFS(Doc_Scope,$A12,Doc_Approved,0))
J13: =IF($A13="","",IFERROR(AVERAGEIF(Eq_Scope,$A13,Eq_Readiness),0)) | L13: =IF($A13="","",COUNTIF(Eq_Scope,$A13)) | M13: =IF($A13="","",COUNTIFS(Eq_Scope,$A13,Eq_Phase,"Complete")) | N13: =IF($A13="","",$L13-$M13-$O13) | O13: =IF($A13="","",COUNTIFS(Eq_Scope,$A13,Eq_Phase,"Pre-Commissioning")) | P13: =IF($A13="","",COUNTIFS(Act_Scope,$A13,Act_Status,"<>Closed")) | Q13: =IF($A13="","",COUNTIFS(Doc_Scope,$A13,Doc_Approved,0))
J14: =IF($A14="","",IFERROR(AVERAGEIF(Eq_Scope,$A14,Eq_Readiness),0)) | L14: =IF($A14="","",COUNTIF(Eq_Scope,$A14)) | M14: =IF($A14="","",COUNTIFS(Eq_Scope,$A14,Eq_Phase,"Complete")) | N14: =IF($A14="","",$L14-$M14-$O14) | O14: =IF($A14="","",COUNTIFS(Eq_Scope,$A14,Eq_Phase,"Pre-Commissioning")) | P14: =IF($A14="","",COUNTIFS(Act_Scope,$A14,Act_Status,"<>Closed")) | Q14: =IF($A14="","",COUNTIFS(Doc_Scope,$A14,Doc_Approved,0))
J15: =IF($A15="","",IFERROR(AVERAGEIF(Eq_Scope,$A15,Eq_Readiness),0)) | L15: =IF($A15="","",COUNTIF(Eq_Scope,$A15)) | M15: =IF($A15="","",COUNTIFS(Eq_Scope,$A15,Eq_Phase,"Complete")) | N15: =IF($A15="","",$L15-$M15-$O15) | O15: =IF($A15="","",COUNTIFS(Eq_Scope,$A15,Eq_Phase,"Pre-Commissioning")) | P15: =IF($A15="","",COUNTIFS(Act_Scope,$A15,Act_Status,"<>Closed")) | Q15: =IF($A15="","",COUNTIFS(Doc_Scope,$A15,Doc_Approved,0))
J16: =IF($A16="","",IFERROR(AVERAGEIF(Eq_Scope,$A16,Eq_Readiness),0)) | L16: =IF($A16="","",COUNTIF(Eq_Scope,$A16)) | M16: =IF($A16="","",COUNTIFS(Eq_Scope,$A16,Eq_Phase,"Complete")) | N16: =IF($A16="","",$L16-$M16-$O16) | O16: =IF($A16="","",COUNTIFS(Eq_Scope,$A16,Eq_Phase,"Pre-Commissioning")) | P16: =IF($A16="","",COUNTIFS(Act_Scope,$A16,Act_Status,"<>Closed")) | Q16: =IF($A16="","",COUNTIFS(Doc_Scope,$A16,Doc_Approved,0))
... J103: =IF($A103="","",IFERROR(AVERAGEIF(Eq_Scope,$A103,Eq_Readiness),0)) | L103: =IF($A103="","",COUNTIF(Eq_Scope,$A103)) | M103: =IF($A103="","",COUNTIFS(Eq_Scope,$A103,Eq_Phase,"Complete")) | N103: =IF($A103="","",$L103-$M103-$O103) | O103: =IF($A103="","",COUNTIFS(Eq_Scope,$A103,Eq_Phase,"Pre-Commissioning")) | P103: =IF($A103="","",COUNTIFS(Act_Scope,$A103,Act_Status,"<>Closed")) | Q103: =IF($A103="","",COUNTIFS(Doc_Scope,$A103,Doc_Approved,0))

Sheet Equipment Tracker
A1: EQUIPMENT TRACKER
A2: One row per Equipment Item. Each item progresses independently; Scope and Contract readiness roll up from here.
A3: Equipment Name | B3: Parent Scope | C3: Responsible Engineer | D3: Commissioning Phase | E3: Planned Start | F3: Forecast Start | G3: Actual Start | H3: Planned Finish | I3: Forecast Finish | J3: Actual Finish | K3: Readiness % | L3: Status | M3: Comments | N3: Linked Docs | O3: Phase % | P3: Doc %
A4: TR-TSS-02 Traction Substation Alpha | B4: SC-01 | C4: D. Petrov | D4: Testing In Progress | E4: 46359 | F4: 46364 | H4: 46434 | I4: 46441 | K4: =IF($A4="","",IF($N4=0,$O4,Cfg_WPhase*$O4+Cfg_WDoc*$P4)) -> 0.225 | L4: =IF($A4="","",IF($K4>=1,"Complete",IF($K4<=0,"Not Started",IF(AND($H4<>"",$H4<TODAY(),$J4=""),"Behind Schedule","In Progress")))) -> In Progress | M4: ◀ EXAMPLE ROW — overwrite with your own data | N4: =IF($A4="","",COUNTIF(Doc_Equipment,$A4)) -> 1 | O4: =IF($A4="","",IFERROR(INDEX(Cfg_PhasePct,MATCH($D4,Cfg_PhaseList,0)),0)) -> 0.45 | P4: =IF($A4="","",IF($N4=0,"",COUNTIFS(Doc_Equipment,$A4,Doc_Approved,1)/$N4)) -> 0
K5: =IF($A5="","",IF($N5=0,$O5,Cfg_WPhase*$O5+Cfg_WDoc*$P5)) | L5: =IF($A5="","",IF($K5>=1,"Complete",IF($K5<=0,"Not Started",IF(AND($H5<>"",$H5<TODAY(),$J5=""),"Behind Schedule","In Progress")))) | N5: =IF($A5="","",COUNTIF(Doc_Equipment,$A5)) | O5: =IF($A5="","",IFERROR(INDEX(Cfg_PhasePct,MATCH($D5,Cfg_PhaseList,0)),0)) | P5: =IF($A5="","",IF($N5=0,"",COUNTIFS(Doc_Equipment,$A5,Doc_Approved,1)/$N5))
K6: =IF($A6="","",IF($N6=0,$O6,Cfg_WPhase*$O6+Cfg_WDoc*$P6)) | L6: =IF($A6="","",IF($K6>=1,"Complete",IF($K6<=0,"Not Started",IF(AND($H6<>"",$H6<TODAY(),$J6=""),"Behind Schedule","In Progress")))) | N6: =IF($A6="","",COUNTIF(Doc_Equipment,$A6)) | O6: =IF($A6="","",IFERROR(INDEX(Cfg_PhasePct,MATCH($D6,Cfg_PhaseList,0)),0)) | P6: =IF($A6="","",IF($N6=0,"",COUNTIFS(Doc_Equipment,$A6,Doc_Approved,1)/$N6))
K7: =IF($A7="","",IF($N7=0,$O7,Cfg_WPhase*$O7+Cfg_WDoc*$P7)) | L7: =IF($A7="","",IF($K7>=1,"Complete",IF($K7<=0,"Not Started",IF(AND($H7<>"",$H7<TODAY(),$J7=""),"Behind Schedule","In Progress")))) | N7: =IF($A7="","",COUNTIF(Doc_Equipment,$A7)) | O7: =IF($A7="","",IFERROR(INDEX(Cfg_PhasePct,MATCH($D7,Cfg_PhaseList,0)),0)) | P7: =IF($A7="","",IF($N7=0,"",COUNTIFS(Doc_Equipment,$A7,Doc_Approved,1)/$N7))
K8: =IF($A8="","",IF($N8=0,$O8,Cfg_WPhase*$O8+Cfg_WDoc*$P8)) | L8: =IF($A8="","",IF($K8>=1,"Complete",IF($K8<=0,"Not Started",IF(AND($H8<>"",$H8<TODAY(),$J8=""),"Behind Schedule","In Progress")))) | N8: =IF($A8="","",COUNTIF(Doc_Equipment,$A8)) | O8: =IF($A8="","",IFERROR(INDEX(Cfg_PhasePct,MATCH($D8,Cfg_PhaseList,0)),0)) | P8: =IF($A8="","",IF($N8=0,"",COUNTIFS(Doc_Equipment,$A8,Doc_Approved,1)/$N8))
K9: =IF($A9="","",IF($N9=0,$O9,Cfg_WPhase*$O9+Cfg_WDoc*$P9)) | L9: =IF($A9="","",IF($K9>=1,"Complete",IF($K9<=0,"Not Started",IF(AND($H9<>"",$H9<TODAY(),$J9=""),"Behind Schedule","In Progress")))) | N9: =IF($A9="","",COUNTIF(Doc_Equipment,$A9)) | O9: =IF($A9="","",IFERROR(INDEX(Cfg_PhasePct,MATCH($D9,Cfg_PhaseList,0)),0)) | P9: =IF($A9="","",IF($N9=0,"",COUNTIFS(Doc_Equipment,$A9,Doc_Approved,1)/$N9))
K10: =IF($A10="","",IF($N10=0,$O10,Cfg_WPhase*$O10+Cfg_WDoc*$P10)) | L10: =IF($A10="","",IF($K10>=1,"Complete",IF($K10<=0,"Not Started",IF(AND($H10<>"",$H10<TODAY(),$J10=""),"Behind Schedule","In Progress")))) | N10: =IF($A10="","",COUNTIF(Doc_Equipment,$A10)) | O10: =IF($A10="","",IFERROR(INDEX(Cfg_PhasePct,MATCH($D10,Cfg_PhaseList,0)),0)) | P10: =IF($A10="","",IF($N10=0,"",COUNTIFS(Doc_Equipment,$A10,Doc_Approved,1)/$N10))
K11: =IF($A11="","",IF($N11=0,$O11,Cfg_WPhase*$O11+Cfg_WDoc*$P11)) | L11: =IF($A11="","",IF($K11>=1,"Complete",IF($K11<=0,"Not Started",IF(AND($H11<>"",$H11<TODAY(),$J11=""),"Behind Schedule","In Progress")))) | N11: =IF($A11="","",COUNTIF(Doc_Equipment,$A11)) | O11: =IF($A11="","",IFERROR(INDEX(Cfg_PhasePct,MATCH($D11,Cfg_PhaseList,0)),0)) | P11: =IF($A11="","",IF($N11=0,"",COUNTIFS(Doc_Equipment,$A11,Doc_Approved,1)/$N11))
K12: =IF($A12="","",IF($N12=0,$O12,Cfg_WPhase*$O12+Cfg_WDoc*$P12)) | L12: =IF($A12="","",IF($K12>=1,"Complete",IF($K12<=0,"Not Started",IF(AND($H12<>"",$H12<TODAY(),$J12=""),"Behind Schedule","In Progress")))) | N12: =IF($A12="","",COUNTIF(Doc_Equipment,$A12)) | O12: =IF($A12="","",IFERROR(INDEX(Cfg_PhasePct,MATCH($D12,Cfg_PhaseList,0)),0)) | P12: =IF($A12="","",IF($N12=0,"",COUNTIFS(Doc_Equipment,$A12,Doc_Approved,1)/$N12))
K13: =IF($A13="","",IF($N13=0,$O13,Cfg_WPhase*$O13+Cfg_WDoc*$P13)) | L13: =IF($A13="","",IF($K13>=1,"Complete",IF($K13<=0,"Not Started",IF(AND($H13<>"",$H13<TODAY(),$J13=""),"Behind Schedule","In Progress")))) | N13: =IF($A13="","",COUNTIF(Doc_Equipment,$A13)) | O13: =IF($A13="","",IFERROR(INDEX(Cfg_PhasePct,MATCH($D13,Cfg_PhaseList,0)),0)) | P13: =IF($A13="","",IF($N13=0,"",COUNTIFS(Doc_Equipment,$A13,Doc_Approved,1)/$N13))
K14: =IF($A14="","",IF($N14=0,$O14,Cfg_WPhase*$O14+Cfg_WDoc*$P14)) | L14: =IF($A14="","",IF($K14>=1,"Complete",IF($K14<=0,"Not Started",IF(AND($H14<>"",$H14<TODAY(),$J14=""),"Behind Schedule","In Progress")))) | N14: =IF($A14="","",COUNTIF(Doc_Equipment,$A14)) | O14: =IF($A14="","",IFERROR(INDEX(Cfg_PhasePct,MATCH($D14,Cfg_PhaseList,0)),0)) | P14: =IF($A14="","",IF($N14=0,"",COUNTIFS(Doc_Equipment,$A14,Doc_Approved,1)/$N14))
K15: =IF($A15="","",IF($N15=0,$O15,Cfg_WPhase*$O15+Cfg_WDoc*$P15)) | L15: =IF($A15="","",IF($K15>=1,"Complete",IF($K15<=0,"Not Started",IF(AND($H15<>"",$H15<TODAY(),$J15=""),"Behind Schedule","In Progress")))) | N15: =IF($A15="","",COUNTIF(Doc_Equipment,$A15)) | O15: =IF($A15="","",IFERROR(INDEX(Cfg_PhasePct,MATCH($D15,Cfg_PhaseList,0)),0)) | P15: =IF($A15="","",IF($N15=0,"",COUNTIFS(Doc_Equipment,$A15,Doc_Approved,1)/$N15))
K16: =IF($A16="","",IF($N16=0,$O16,Cfg_WPhase*$O16+Cfg_WDoc*$P16)) | L16: =IF($A16="","",IF($K16>=1,"Complete",IF($K16<=0,"Not Started",IF(AND($H16<>"",$H16<TODAY(),$J16=""),"Behind Schedule","In Progress")))) | N16: =IF($A16="","",COUNTIF(Doc_Equipment,$A16)) | O16: =IF($A16="","",IFERROR(INDEX(Cfg_PhasePct,MATCH($D16,Cfg_PhaseList,0)),0)) | P16: =IF($A16="","",IF($N16=0,"",COUNTIFS(Doc_Equipment,$A16,Doc_Approved,1)/$N16))
... K103: =IF($A103="","",IF($N103=0,$O103,Cfg_WPhase*$O103+Cfg_WDoc*$P103)) | L103: =IF($A103="","",IF($K103>=1,"Complete",IF($K103<=0,"Not Started",IF(AND($H103<>"",$H103<TODAY(),$J103=""),"Behind Schedule","In Progress")))) | N103: =IF($A103="","",COUNTIF(Doc_Equipment,$A103)) | O103: =IF($A103="","",IFERROR(INDEX(Cfg_PhasePct,MATCH($D103,Cfg_PhaseList,0)),0)) | P103: =IF($A103="","",IF($N103=0,"",COUNTIFS(Doc_Equipment,$A103,Doc_Approved,1)/$N103))

Sheet Document Tracker
A1: DOCUMENT TRACKER
A2: Primary operational sheet — one row per commissioning deliverable. Target dates are generated from the Planned Commissioning Start Date and the lead times on the Control Panel.
A3: Document Type | B3: Scope | C3: Equipment (optional) | D3: Document Number | E3: Document Title | F3: Revision | G3: Owner | H3: Reviewer | I3: Workflow Status | J3: Readiness Gate | K3: Target Submission Date | L3: Target Approval Date | M3: Actual Submission Date | N3: Actual Approval Date | O3: Days Late | P3: Criticality | Q3: Comments | S3: Approved | T3: Progress % | U3: Days Remaining | V3: Flag | W3: Rank Key
A4: System Commissioning Programme | B4: SC-01 | C4: TR-TSS-02 Traction Substation Alpha | D4: DMIC-SC-01-SCP-001 | E4: Traction Power — System Commissioning Programme | F4: B | G4: D. Petrov | H4: M. Haddad | I4: Under Review | J4: Readiness | K4: =IF($L4="","",$L4-Cfg_ReviewDays) -> 46338 | L4: =IF($A4="","",IFERROR(Ctrl_PlannedStart-INDEX(Cfg_LeadDays,MATCH($A4,Cfg_LeadType,0)),"")) -> 46359 | O4: =IF($A4="","",IF($N4<>"",MAX(0,$N4-$L4),IF(AND($L4<>"",TODAY()>$L4),TODAY()-$L4,0))) -> 0 | P4: Critical | Q4: ◀ EXAMPLE ROW — overwrite with your own data | S4: =IF($A4="","",IFERROR(INDEX(Cfg_WfApproved,MATCH($I4,Cfg_WfList,0)),0)) -> 0 | T4: =IF($A4="","",IFERROR(INDEX(Cfg_WfPct,MATCH($I4,Cfg_WfList,0)),0)) -> 0.55 | U4: =IF(OR($A4="",$L4=""),"",$L4-TODAY()) -> 105 | V4: =IF($A4="","",IF($S4=1,"Approved",IF(AND($L4<>"",TODAY()>$L4),"Overdue",IF(AND($L4<>"",$L4-TODAY()<=Cfg_DocWindow),"Due Soon",IF($I4="Not Started","Not Started","On Track"))))) -> On Track | W4: =IF($A4="","",IF(AND($S4=0,$O4>0),$O4+ROW()/1000000,""))
K5: =IF($L5="","",$L5-Cfg_ReviewDays) | L5: =IF($A5="","",IFERROR(Ctrl_PlannedStart-INDEX(Cfg_LeadDays,MATCH($A5,Cfg_LeadType,0)),"")) | O5: =IF($A5="","",IF($N5<>"",MAX(0,$N5-$L5),IF(AND($L5<>"",TODAY()>$L5),TODAY()-$L5,0))) | S5: =IF($A5="","",IFERROR(INDEX(Cfg_WfApproved,MATCH($I5,Cfg_WfList,0)),0)) | T5: =IF($A5="","",IFERROR(INDEX(Cfg_WfPct,MATCH($I5,Cfg_WfList,0)),0)) | U5: =IF(OR($A5="",$L5=""),"",$L5-TODAY()) | V5: =IF($A5="","",IF($S5=1,"Approved",IF(AND($L5<>"",TODAY()>$L5),"Overdue",IF(AND($L5<>"",$L5-TODAY()<=Cfg_DocWindow),"Due Soon",IF($I5="Not Started","Not Started","On Track"))))) | W5: =IF($A5="","",IF(AND($S5=0,$O5>0),$O5+ROW()/1000000,""))
K6: =IF($L6="","",$L6-Cfg_ReviewDays) | L6: =IF($A6="","",IFERROR(Ctrl_PlannedStart-INDEX(Cfg_LeadDays,MATCH($A6,Cfg_LeadType,0)),"")) | O6: =IF($A6="","",IF($N6<>"",MAX(0,$N6-$L6),IF(AND($L6<>"",TODAY()>$L6),TODAY()-$L6,0))) | S6: =IF($A6="","",IFERROR(INDEX(Cfg_WfApproved,MATCH($I6,Cfg_WfList,0)),0)) | T6: =IF($A6="","",IFERROR(INDEX(Cfg_WfPct,MATCH($I6,Cfg_WfList,0)),0)) | U6: =IF(OR($A6="",$L6=""),"",$L6-TODAY()) | V6: =IF($A6="","",IF($S6=1,"Approved",IF(AND($L6<>"",TODAY()>$L6),"Overdue",IF(AND($L6<>"",$L6-TODAY()<=Cfg_DocWindow),"Due Soon",IF($I6="Not Started","Not Started","On Track"))))) | W6: =IF($A6="","",IF(AND($S6=0,$O6>0),$O6+ROW()/1000000,""))
K7: =IF($L7="","",$L7-Cfg_ReviewDays) | L7: =IF($A7="","",IFERROR(Ctrl_PlannedStart-INDEX(Cfg_LeadDays,MATCH($A7,Cfg_LeadType,0)),"")) | O7: =IF($A7="","",IF($N7<>"",MAX(0,$N7-$L7),IF(AND($L7<>"",TODAY()>$L7),TODAY()-$L7,0))) | S7: =IF($A7="","",IFERROR(INDEX(Cfg_WfApproved,MATCH($I7,Cfg_WfList,0)),0)) | T7: =IF($A7="","",IFERROR(INDEX(Cfg_WfPct,MATCH($I7,Cfg_WfList,0)),0)) | U7: =IF(OR($A7="",$L7=""),"",$L7-TODAY()) | V7: =IF($A7="","",IF($S7=1,"Approved",IF(AND($L7<>"",TODAY()>$L7),"Overdue",IF(AND($L7<>"",$L7-TODAY()<=Cfg_DocWindow),"Due Soon",IF($I7="Not Started","Not Started","On Track"))))) | W7: =IF($A7="","",IF(AND($S7=0,$O7>0),$O7+ROW()/1000000,""))
K8: =IF($L8="","",$L8-Cfg_ReviewDays) | L8: =IF($A8="","",IFERROR(Ctrl_PlannedStart-INDEX(Cfg_LeadDays,MATCH($A8,Cfg_LeadType,0)),"")) | O8: =IF($A8="","",IF($N8<>"",MAX(0,$N8-$L8),IF(AND($L8<>"",TODAY()>$L8),TODAY()-$L8,0))) | S8: =IF($A8="","",IFERROR(INDEX(Cfg_WfApproved,MATCH($I8,Cfg_WfList,0)),0)) | T8: =IF($A8="","",IFERROR(INDEX(Cfg_WfPct,MATCH($I8,Cfg_WfList,0)),0)) | U8: =IF(OR($A8="",$L8=""),"",$L8-TODAY()) | V8: =IF($A8="","",IF($S8=1,"Approved",IF(AND($L8<>"",TODAY()>$L8),"Overdue",IF(AND($L8<>"",$L8-TODAY()<=Cfg_DocWindow),"Due Soon",IF($I8="Not Started","Not Started","On Track"))))) | W8: =IF($A8="","",IF(AND($S8=0,$O8>0),$O8+ROW()/1000000,""))
K9: =IF($L9="","",$L9-Cfg_ReviewDays) | L9: =IF($A9="","",IFERROR(Ctrl_PlannedStart-INDEX(Cfg_LeadDays,MATCH($A9,Cfg_LeadType,0)),"")) | O9: =IF($A9="","",IF($N9<>"",MAX(0,$N9-$L9),IF(AND($L9<>"",TODAY()>$L9),TODAY()-$L9,0))) | S9: =IF($A9="","",IFERROR(INDEX(Cfg_WfApproved,MATCH($I9,Cfg_WfList,0)),0)) | T9: =IF($A9="","",IFERROR(INDEX(Cfg_WfPct,MATCH($I9,Cfg_WfList,0)),0)) | U9: =IF(OR($A9="",$L9=""),"",$L9-TODAY()) | V9: =IF($A9="","",IF($S9=1,"Approved",IF(AND($L9<>"",TODAY()>$L9),"Overdue",IF(AND($L9<>"",$L9-TODAY()<=Cfg_DocWindow),"Due Soon",IF($I9="Not Started","Not Started","On Track"))))) | W9: =IF($A9="","",IF(AND($S9=0,$O9>0),$O9+ROW()/1000000,""))
K10: =IF($L10="","",$L10-Cfg_ReviewDays) | L10: =IF($A10="","",IFERROR(Ctrl_PlannedStart-INDEX(Cfg_LeadDays,MATCH($A10,Cfg_LeadType,0)),"")) | O10: =IF($A10="","",IF($N10<>"",MAX(0,$N10-$L10),IF(AND($L10<>"",TODAY()>$L10),TODAY()-$L10,0))) | S10: =IF($A10="","",IFERROR(INDEX(Cfg_WfApproved,MATCH($I10,Cfg_WfList,0)),0)) | T10: =IF($A10="","",IFERROR(INDEX(Cfg_WfPct,MATCH($I10,Cfg_WfList,0)),0)) | U10: =IF(OR($A10="",$L10=""),"",$L10-TODAY()) | V10: =IF($A10="","",IF($S10=1,"Approved",IF(AND($L10<>"",TODAY()>$L10),"Overdue",IF(AND($L10<>"",$L10-TODAY()<=Cfg_DocWindow),"Due Soon",IF($I10="Not Started","Not Started","On Track"))))) | W10: =IF($A10="","",IF(AND($S10=0,$O10>0),$O10+ROW()/1000000,""))
K11: =IF($L11="","",$L11-Cfg_ReviewDays) | L11: =IF($A11="","",IFERROR(Ctrl_PlannedStart-INDEX(Cfg_LeadDays,MATCH($A11,Cfg_LeadType,0)),"")) | O11: =IF($A11="","",IF($N11<>"",MAX(0,$N11-$L11),IF(AND($L11<>"",TODAY()>$L11),TODAY()-$L11,0))) | S11: =IF($A11="","",IFERROR(INDEX(Cfg_WfApproved,MATCH($I11,Cfg_WfList,0)),0)) | T11: =IF($A11="","",IFERROR(INDEX(Cfg_WfPct,MATCH($I11,Cfg_WfList,0)),0)) | U11: =IF(OR($A11="",$L11=""),"",$L11-TODAY()) | V11: =IF($A11="","",IF($S11=1,"Approved",IF(AND($L11<>"",TODAY()>$L11),"Overdue",IF(AND($L11<>"",$L11-TODAY()<=Cfg_DocWindow),"Due Soon",IF($I11="Not Started","Not Started","On Track"))))) | W11: =IF($A11="","",IF(AND($S11=0,$O11>0),$O11+ROW()/1000000,""))
K12: =IF($L12="","",$L12-Cfg_ReviewDays) | L12: =IF($A12="","",IFERROR(Ctrl_PlannedStart-INDEX(Cfg_LeadDays,MATCH($A12,Cfg_LeadType,0)),"")) | O12: =IF($A12="","",IF($N12<>"",MAX(0,$N12-$L12),IF(AND($L12<>"",TODAY()>$L12),TODAY()-$L12,0))) | S12: =IF($A12="","",IFERROR(INDEX(Cfg_WfApproved,MATCH($I12,Cfg_WfList,0)),0)) | T12: =IF($A12="","",IFERROR(INDEX(Cfg_WfPct,MATCH($I12,Cfg_WfList,0)),0)) | U12: =IF(OR($A12="",$L12=""),"",$L12-TODAY()) | V12: =IF($A12="","",IF($S12=1,"Approved",IF(AND($L12<>"",TODAY()>$L12),"Overdue",IF(AND($L12<>"",$L12-TODAY()<=Cfg_DocWindow),"Due Soon",IF($I12="Not Started","Not Started","On Track"))))) | W12: =IF($A12="","",IF(AND($S12=0,$O12>0),$O12+ROW()/1000000,""))
K13: =IF($L13="","",$L13-Cfg_ReviewDays) | L13: =IF($A13="","",IFERROR(Ctrl_PlannedStart-INDEX(Cfg_LeadDays,MATCH($A13,Cfg_LeadType,0)),"")) | O13: =IF($A13="","",IF($N13<>"",MAX(0,$N13-$L13),IF(AND($L13<>"",TODAY()>$L13),TODAY()-$L13,0))) | S13: =IF($A13="","",IFERROR(INDEX(Cfg_WfApproved,MATCH($I13,Cfg_WfList,0)),0)) | T13: =IF($A13="","",IFERROR(INDEX(Cfg_WfPct,MATCH($I13,Cfg_WfList,0)),0)) | U13: =IF(OR($A13="",$L13=""),"",$L13-TODAY()) | V13: =IF($A13="","",IF($S13=1,"Approved",IF(AND($L13<>"",TODAY()>$L13),"Overdue",IF(AND($L13<>"",$L13-TODAY()<=Cfg_DocWindow),"Due Soon",IF($I13="Not Started","Not Started","On Track"))))) | W13: =IF($A13="","",IF(AND($S13=0,$O13>0),$O13+ROW()/1000000,""))
K14: =IF($L14="","",$L14-Cfg_ReviewDays) | L14: =IF($A14="","",IFERROR(Ctrl_PlannedStart-INDEX(Cfg_LeadDays,MATCH($A14,Cfg_LeadType,0)),"")) | O14: =IF($A14="","",IF($N14<>"",MAX(0,$N14-$L14),IF(AND($L14<>"",TODAY()>$L14),TODAY()-$L14,0))) | S14: =IF($A14="","",IFERROR(INDEX(Cfg_WfApproved,MATCH($I14,Cfg_WfList,0)),0)) | T14: =IF($A14="","",IFERROR(INDEX(Cfg_WfPct,MATCH($I14,Cfg_WfList,0)),0)) | U14: =IF(OR($A14="",$L14=""),"",$L14-TODAY()) | V14: =IF($A14="","",IF($S14=1,"Approved",IF(AND($L14<>"",TODAY()>$L14),"Overdue",IF(AND($L14<>"",$L14-TODAY()<=Cfg_DocWindow),"Due Soon",IF($I14="Not Started","Not Started","On Track"))))) | W14: =IF($A14="","",IF(AND($S14=0,$O14>0),$O14+ROW()/1000000,""))
K15: =IF($L15="","",$L15-Cfg_ReviewDays) | L15: =IF($A15="","",IFERROR(Ctrl_PlannedStart-INDEX(Cfg_LeadDays,MATCH($A15,Cfg_LeadType,0)),"")) | O15: =IF($A15="","",IF($N15<>"",MAX(0,$N15-$L15),IF(AND($L15<>"",TODAY()>$L15),TODAY()-$L15,0))) | S15: =IF($A15="","",IFERROR(INDEX(Cfg_WfApproved,MATCH($I15,Cfg_WfList,0)),0)) | T15: =IF($A15="","",IFERROR(INDEX(Cfg_WfPct,MATCH($I15,Cfg_WfList,0)),0)) | U15: =IF(OR($A15="",$L15=""),"",$L15-TODAY()) | V15: =IF($A15="","",IF($S15=1,"Approved",IF(AND($L15<>"",TODAY()>$L15),"Overdue",IF(AND($L15<>"",$L15-TODAY()<=Cfg_DocWindow),"Due Soon",IF($I15="Not Started","Not Started","On Track"))))) | W15: =IF($A15="","",IF(AND($S15=0,$O15>0),$O15+ROW()/1000000,""))
K16: =IF($L16="","",$L16-Cfg_ReviewDays) | L16: =IF($A16="","",IFERROR(Ctrl_PlannedStart-INDEX(Cfg_LeadDays,MATCH($A16,Cfg_LeadType,0)),"")) | O16: =IF($A16="","",IF($N16<>"",MAX(0,$N16-$L16),IF(AND($L16<>"",TODAY()>$L16),TODAY()-$L16,0))) | S16: =IF($A16="","",IFERROR(INDEX(Cfg_WfApproved,MATCH($I16,Cfg_WfList,0)),0)) | T16: =IF($A16="","",IFERROR(INDEX(Cfg_WfPct,MATCH($I16,Cfg_WfList,0)),0)) | U16: =IF(OR($A16="",$L16=""),"",$L16-TODAY()) | V16: =IF($A16="","",IF($S16=1,"Approved",IF(AND($L16<>"",TODAY()>$L16),"Overdue",IF(AND($L16<>"",$L16-TODAY()<=Cfg_DocWindow),"Due Soon",IF($I16="Not Started","Not Started","On Track"))))) | W16: =IF($A16="","",IF(AND($S16=0,$O16>0),$O16+ROW()/1000000,""))
... K153: =IF($L153="","",$L153-Cfg_ReviewDays) | L153: =IF($A153="","",IFERROR(Ctrl_PlannedStart-INDEX(Cfg_LeadDays,MATCH($A153,Cfg_LeadType,0)),"")) | O153: =IF($A153="","",IF($N153<>"",MAX(0,$N153-$L153),IF(AND($L153<>"",TODAY()>$L153),TODAY()-$L153,0))) | S153: =IF($A153="","",IFERROR(INDEX(Cfg_WfApproved,MATCH($I153,Cfg_WfList,0)),0)) | T153: =IF($A153="","",IFERROR(INDEX(Cfg_WfPct,MATCH($I153,Cfg_WfList,0)),0)) | U153: =IF(OR($A153="",$L153=""),"",$L153-TODAY()) | V153: =IF($A153="","",IF($S153=1,"Approved",IF(AND($L153<>"",TODAY()>$L153),"Overdue",IF(AND($L153<>"",$L153-TODAY()<=Cfg_DocWindow),"Due Soon",IF($I153="Not Started","Not Started","On Track"))))) | W153: =IF($A153="","",IF(AND($S153=0,$O153>0),$O153+ROW()/1000000,""))

Sheet Action Tracker
A1: ACTION TRACKER
A2: One row per Action. Rows colour themselves by priority and lateness — see the Read Me sheet for the colour key.
A3: Action ID | B3: Action Description | C3: Category | D3: Linked Scope | E3: Linked Equipment | F3: Linked Document | G3: Owner | H3: Support Owner | I3: Date Raised | J3: Due Date | K3: Completion Date | L3: Priority | M3: Commissioning Blocker | N3: Status | O3: Comments | Q3: Days To Due | R3: Overdue | S3: Rank Key
A4: ACT-001 | B4: Close out RAMS comments raised by the Client safety review | C4: Safety | D4: SC-01 | E4: TR-TSS-02 Traction Substation Alpha | F4: DMIC-SC-01-SCP-001 | G4: A. Mercer | H4: M. Haddad | I4: 46240 | J4: 46261 | L4: High | M4: Yes | N4: Open | O4: ◀ EXAMPLE ROW — overwrite with your own data | Q4: =IF($A4="","",IF(OR($K4<>"",$J4=""),"",$J4-TODAY())) -> 7 | R4: =IF($A4="",0,IF(AND($N4<>"Closed",$K4="",$J4<>"",$J4<TODAY()),1,0)) -> 0 | S4: =IF($A4="","",IF($R4=1,(TODAY()-$J4)+ROW()/1000000,""))
Q5: =IF($A5="","",IF(OR($K5<>"",$J5=""),"",$J5-TODAY())) | R5: =IF($A5="",0,IF(AND($N5<>"Closed",$K5="",$J5<>"",$J5<TODAY()),1,0)) -> 0 | S5: =IF($A5="","",IF($R5=1,(TODAY()-$J5)+ROW()/1000000,""))
Q6: =IF($A6="","",IF(OR($K6<>"",$J6=""),"",$J6-TODAY())) | R6: =IF($A6="",0,IF(AND($N6<>"Closed",$K6="",$J6<>"",$J6<TODAY()),1,0)) -> 0 | S6: =IF($A6="","",IF($R6=1,(TODAY()-$J6)+ROW()/1000000,""))
Q7: =IF($A7="","",IF(OR($K7<>"",$J7=""),"",$J7-TODAY())) | R7: =IF($A7="",0,IF(AND($N7<>"Closed",$K7="",$J7<>"",$J7<TODAY()),1,0)) -> 0 | S7: =IF($A7="","",IF($R7=1,(TODAY()-$J7)+ROW()/1000000,""))
Q8: =IF($A8="","",IF(OR($K8<>"",$J8=""),"",$J8-TODAY())) | R8: =IF($A8="",0,IF(AND($N8<>"Closed",$K8="",$J8<>"",$J8<TODAY()),1,0)) -> 0 | S8: =IF($A8="","",IF($R8=1,(TODAY()-$J8)+ROW()/1000000,""))
Q9: =IF($A9="","",IF(OR($K9<>"",$J9=""),"",$J9-TODAY())) | R9: =IF($A9="",0,IF(AND($N9<>"Closed",$K9="",$J9<>"",$J9<TODAY()),1,0)) -> 0 | S9: =IF($A9="","",IF($R9=1,(TODAY()-$J9)+ROW()/1000000,""))
Q10: =IF($A10="","",IF(OR($K10<>"",$J10=""),"",$J10-TODAY())) | R10: =IF($A10="",0,IF(AND($N10<>"Closed",$K10="",$J10<>"",$J10<TODAY()),1,0)) -> 0 | S10: =IF($A10="","",IF($R10=1,(TODAY()-$J10)+ROW()/1000000,""))
Q11: =IF($A11="","",IF(OR($K11<>"",$J11=""),"",$J11-TODAY())) | R11: =IF($A11="",0,IF(AND($N11<>"Closed",$K11="",$J11<>"",$J11<TODAY()),1,0)) -> 0 | S11: =IF($A11="","",IF($R11=1,(TODAY()-$J11)+ROW()/1000000,""))
Q12: =IF($A12="","",IF(OR($K12<>"",$J12=""),"",$J12-TODAY())) | R12: =IF($A12="",0,IF(AND($N12<>"Closed",$K12="",$J12<>"",$J12<TODAY()),1,0)) -> 0 | S12: =IF($A12="","",IF($R12=1,(TODAY()-$J12)+ROW()/1000000,""))
Q13: =IF($A13="","",IF(OR($K13<>"",$J13=""),"",$J13-TODAY())) | R13: =IF($A13="",0,IF(AND($N13<>"Closed",$K13="",$J13<>"",$J13<TODAY()),1,0)) -> 0 | S13: =IF($A13="","",IF($R13=1,(TODAY()-$J13)+ROW()/1000000,""))
Q14: =IF($A14="","",IF(OR($K14<>"",$J14=""),"",$J14-TODAY())) | R14: =IF($A14="",0,IF(AND($N14<>"Closed",$K14="",$J14<>"",$J14<TODAY()),1,0)) -> 0 | S14: =IF($A14="","",IF($R14=1,(TODAY()-$J14)+ROW()/1000000,""))
Q15: =IF($A15="","",IF(OR($K15<>"",$J15=""),"",$J15-TODAY())) | R15: =IF($A15="",0,IF(AND($N15<>"Closed",$K15="",$J15<>"",$J15<TODAY()),1,0)) -> 0 | S15: =IF($A15="","",IF($R15=1,(TODAY()-$J15)+ROW()/1000000,""))
Q16: =IF($A16="","",IF(OR($K16<>"",$J16=""),"",$J16-TODAY())) | R16: =IF($A16="",0,IF(AND($N16<>"Closed",$K16="",$J16<>"",$J16<TODAY()),1,0)) -> 0 | S16: =IF($A16="","",IF($R16=1,(TODAY()-$J16)+ROW()/1000000,""))
... Q103: =IF($A103="","",IF(OR($K103<>"",$J103=""),"",$J103-TODAY())) | R103: =IF($A103="",0,IF(AND($N103<>"Closed",$K103="",$J103<>"",$J103<TODAY()),1,0)) -> 0 | S103: =IF($A103="","",IF($R103=1,(TODAY()-$J103)+ROW()/1000000,""))

Sheet Dashboard
B1: EXECUTIVE DASHBOARD & MILESTONES
B2: Everything on this sheet is calculated. Nothing here needs typing except the Milestone Tracker and the Readiness Trend log.
B3: CONTRACT HEALTH INDEX
B5: =$L$12 -> 0.56 | F5: Health Category | G5: =IF($L$12>=Cfg_ThrExcellent,"Excellent",IF($L$12>=Cfg_ThrGood,"Good",IF($L$12>=Cfg_ThrAttention,"Attention Required","Critical"))) -> Attention Required | I5: Component | J5: Score | K5: Weight | L5: Weighted
F6: RAG Status | G6: =IF($L$12>=Cfg_RagGreen,"GREEN",IF($L$12>=Cfg_RagAmber,"AMBER","RED")) -> AMBER | I6: Documents | J6: =IFERROR(AVERAGE(Doc_Progress),0) -> 0.55 | K6: =Configuration!$L$30 -> 0.4 | L6: =$J6*$K6 -> 0.22
F7: Contract Readiness | G7: =IFERROR(AVERAGE(Eq_Readiness),0) -> 0.225 | I7: Readiness | J7: =IFERROR(AVERAGE(Eq_Readiness),0) -> 0.225 | K7: =Configuration!$L$31 -> 0.2 | L7: =$J7*$K7 -> 0.045
F8: ATS Readiness | G8: =Configuration!$B$57 -> 0 | I8: Actions | J8: =IF(COUNTA(Act_ID)=0,1,1-SUM(Act_Overdue)/COUNTA(Act_ID)) -> 1 | K8: =Configuration!$L$32 -> 0.15 | L8: =$J8*$K8 -> 0.15
I9: Milestones | J9: =IF(COUNTA(Ms_Name)=0,1,1-(COUNTIF(Ms_Status,"At Risk")+COUNTIF(Ms_Status,"Delayed"))/COUNTA(Ms_Name)) -> 1 | K9: =Configuration!$L$33 -> 0.1 | L9: =$J9*$K9 -> 0.1
I10: Equipment Progress | J10: =IFERROR(AVERAGE(Eq_PhasePct),0) -> 0.45 | K10: =Configuration!$L$34 -> 0.1 | L10: =$J10*$K10 -> 0.045
I11: Handovers | J11: =IF((COUNTIF(Doc_Gate,"Handover")+COUNTIF(Doc_Gate,"Final Takeover"))=0,0,(COUNTIFS(Doc_Gate,"Handover",Doc_Approved,1)+COUNTIFS(Doc_Gate,"Final Takeover",Doc_Approved,1))/(COUNTIF(Doc_Gate,"Handover")+COUNTIF(Doc_Gate,"Final Takeover"))) -> 0 | K11: =Configuration!$L$35 -> 0.05 | L11: =$J11*$K11 -> 0
I12: CONTRACT HEALTH INDEX | L12: =SUM(L6:L11) -> 0.56
B14: THE DASHBOARD ANSWERS
B15: What is late? | C15: =COUNTIF(Doc_Flag,"Overdue")&" documents overdue, "&SUM(Act_Overdue)&" actions overdue" -> 0 documents overdue, 0 actions overdue
B16: What is missing? | C16: =COUNTIF(Doc_Workflow,"Not Started")&" deliverables not started" -> 0 deliverables not started
B17: What is blocking commissioning? | C17: =COUNTIFS(Act_Blocker,"Yes",Act_Status,"<>Closed")&" open commissioning blockers" -> 1 open commissioning blockers
B18: Who owns the blocker? | C18: =IF(MAX(Cfg_OwnerBlockers)=0,"No open blockers",IFERROR(INDEX(Cfg_OwnerList,MATCH(MAX(Cfg_OwnerBlockers),Cfg_OwnerBlockers,0))&" ("&MAX(Cfg_OwnerBlockers)&")","—")) -> A. Mercer (1)
B19: Which scopes are not ready? | C19: =COUNTIFS(Sc_ID,"<>",Sc_Readiness,"<"&Cfg_ScopeReady)&" of "&COUNTA(Sc_ID)&" scopes below the ready threshold" -> 1 of 1 scopes below the ready threshold
B20: Which equipment items are behind schedule? | C20: =COUNTIF(Eq_Status,"Behind Schedule")&" equipment items past planned finish" -> 0 equipment items past planned finish
B21: Which documents are not approved? | C21: =COUNTIF(Doc_Approved,0)&" of "&COUNTA(Doc_Type)&" deliverables not yet approved" -> 1 of 1 deliverables not yet approved
B22: Which milestones are at risk? | C22: =COUNTIF(Ms_Status,"At Risk")+COUNTIF(Ms_Status,"Delayed")&" milestones at risk or delayed" -> 0 milestones at risk or delayed
B23: Which actions are due this week? | C23: =COUNTIFS(Act_DaysToDue,">=0",Act_DaysToDue,"<=7")&" actions due within 7 days" -> 1 actions due within 7 days
B25: MILESTONE TRACKER | J25: READINESS TREND LOG
B26: Milestone | C26: Scope | D26: Planned Date | E26: Forecast Date | F26: Actual Date | G26: Status | H26: Owner | I26: Days | J26: Snapshot Date | K26: Contract Readiness %
B27: Kick Off Meeting | D27: =IFERROR(Ctrl_PlannedStart-INDEX(Cfg_MsLeadDays,MATCH($B27,Cfg_MsList,0)),"") -> 46179 | I27: =IF($B27="","",IF($G27="Achieved","",IF($E27<>"",$E27-TODAY(),IF($D27<>"",$D27-TODAY(),"")))) -> -75
B28: Commissioning Readiness Review | D28: =IFERROR(Ctrl_PlannedStart-INDEX(Cfg_MsLeadDays,MATCH($B28,Cfg_MsList,0)),"") -> 46479 | I28: =IF($B28="","",IF($G28="Achieved","",IF($E28<>"",$E28-TODAY(),IF($D28<>"",$D28-TODAY(),"")))) -> 225
B29: Authority To Start | D29: =IFERROR(Ctrl_PlannedStart-INDEX(Cfg_MsLeadDays,MATCH($B29,Cfg_MsList,0)),"") -> 46525 | I29: =IF($B29="","",IF($G29="Achieved","",IF($E29<>"",$E29-TODAY(),IF($D29<>"",$D29-TODAY(),"")))) -> 271
B30: Commissioning Start | D30: =IFERROR(Ctrl_PlannedStart-INDEX(Cfg_MsLeadDays,MATCH($B30,Cfg_MsList,0)),"") -> 46539 | I30: =IF($B30="","",IF($G30="Achieved","",IF($E30<>"",$E30-TODAY(),IF($D30<>"",$D30-TODAY(),"")))) -> 285
B31: Functional Takeover | D31: =IFERROR(Ctrl_PlannedStart-INDEX(Cfg_MsLeadDays,MATCH($B31,Cfg_MsList,0)),"") -> 46614 | I31: =IF($B31="","",IF($G31="Achieved","",IF($E31<>"",$E31-TODAY(),IF($D31<>"",$D31-TODAY(),"")))) -> 360
B32: Beneficial Use | D32: =IFERROR(Ctrl_PlannedStart-INDEX(Cfg_MsLeadDays,MATCH($B32,Cfg_MsList,0)),"") -> 46624 | I32: =IF($B32="","",IF($G32="Achieved","",IF($E32<>"",$E32-TODAY(),IF($D32<>"",$D32-TODAY(),"")))) -> 370
B33: Maintenance Transfer | D33: =IFERROR(Ctrl_PlannedStart-INDEX(Cfg_MsLeadDays,MATCH($B33,Cfg_MsList,0)),"") -> 46639 | I33: =IF($B33="","",IF($G33="Achieved","",IF($E33<>"",$E33-TODAY(),IF($D33<>"",$D33-TODAY(),"")))) -> 385
B34: Temporary Operations Transfer | D34: =IFERROR(Ctrl_PlannedStart-INDEX(Cfg_MsLeadDays,MATCH($B34,Cfg_MsList,0)),"") -> 46654 | I34: =IF($B34="","",IF($G34="Achieved","",IF($E34<>"",$E34-TODAY(),IF($D34<>"",$D34-TODAY(),"")))) -> 400
B35: Final Takeover | D35: =IFERROR(Ctrl_PlannedStart-INDEX(Cfg_MsLeadDays,MATCH($B35,Cfg_MsList,0)),"") -> 46669 | I35: =IF($B35="","",IF($G35="Achieved","",IF($E35<>"",$E35-TODAY(),IF($D35<>"",$D35-TODAY(),"")))) -> 415
I36: =IF($B36="","",IF($G36="Achieved","",IF($E36<>"",$E36-TODAY(),IF($D36<>"",$D36-TODAY(),""))))
I37: =IF($B37="","",IF($G37="Achieved","",IF($E37<>"",$E37-TODAY(),IF($D37<>"",$D37-TODAY(),""))))
I38: =IF($B38="","",IF($G38="Achieved","",IF($E38<>"",$E38-TODAY(),IF($D38<>"",$D38-TODAY(),""))))
I39: =IF($B39="","",IF($G39="Achieved","",IF($E39<>"",$E39-TODAY(),IF($D39<>"",$D39-TODAY(),""))))
I40: =IF($B40="","",IF($G40="Achieved","",IF($E40<>"",$E40-TODAY(),IF($D40<>"",$D40-TODAY(),""))))
I41: =IF($B41="","",IF($G41="Achieved","",IF($E41<>"",$E41-TODAY(),IF($D41<>"",$D41-TODAY(),""))))
I42: =IF($B42="","",IF($G42="Achieved","",IF($E42<>"",$E42-TODAY(),IF($D42<>"",$D42-TODAY(),""))))
I43: =IF($B43="","",IF($G43="Achieved","",IF($E43<>"",$E43-TODAY(),IF($D43<>"",$D43-TODAY(),""))))
...

Sheet Configuration
A1: CONFIGURATION — WORKBOOK LOGIC
A2: Administrative sheet. Dropdown lists, progress maps, Health Index weights and RAG thresholds live here. Lead times are edited on the Control Panel. Do not delete rows or columns — every other sheet references these ranges by name.
A4: Contract Status | B4: Scope Status | C4: Commissioning Phase | D4: Workflow Status | E4: Readiness Gate | F4: Priority | G4: Action Status | H4: Criticality | I4: Yes / No | J4: Milestone Status | K4: Document Type | L4: Personnel | M4: Action Category | N4: Milestone Name
A5: Not Started | B5: Not Started | C5: Pre-Commissioning | D5: Not Started | E5: Preparation | F5: Critical | G5: Open | H5: Critical | I5: Yes | J5: Not Started | K5: Basis of Commissioning | L5: A. Mercer | M5: Document | N5: Kick Off Meeting
A6: Preparation | B6: Preparation | C6: Commissioning Preparation | D6: Draft | E6: Readiness | F6: High | G6: In Progress | H6: High | I6: No | J6: In Progress | K6: Surveillance Strategy | L6: S. Okonkwo | M6: Technical | N6: Commissioning Readiness Review
A7: In Progress | B7: Review | C7: Documentation Review | D7: Internal Review | E7: Authority To Start | F7: Medium | G7: Waiting | H7: Medium | J7: At Risk | K7: Surveillance Programme | L7: L. Fontaine | M7: Quality | N7: Authority To Start
A8: Commissioning | B8: Ready | C8: Testing Preparation | D8: Submitted | E8: Commissioning | F8: Low | G8: Closed | H8: Low | J8: Delayed | K8: Competency Evidence | L8: D. Petrov | M8: Safety | N8: Commissioning Start
A9: Handover | B9: In Progress | C9: Testing In Progress | D9: Under Review | E9: Results | J9: Achieved | K9: Safe System Of Work | L9: M. Haddad | M9: Commercial | N9: Functional Takeover
A10: Complete | B10: Complete | C10: Results Review | D10: Comments Received | E10: Handover | K10: Risk Assessment And Method Statement | L10: J. Whitfield | M10: Resource | N10: Beneficial Use
A11: On Hold | B11: On Hold | C11: Ready For Handover | D11: Rework | E11: Final Takeover | K11: System Commissioning Programme | L11: K. Rasmussen | M11: Interface | N11: Maintenance Transfer
C12: Beneficial Use | D12: Resubmitted | K12: Commissioning Procedure | L12: P. Nakamura | M12: Client | N12: Temporary Operations Transfer
C13: Further Testing | D13: Approved | K13: Inspection and Test Plan | L13: R. Bellamy | N13: Final Takeover
C14: Final Handover | D14: Released | K14: Initial End Of Erection Status Report | L14: T. Oyelaran
C15: Complete | D15: Implemented | K15: Planned End Of Erection Status Report | L15: N. Bergstrom
D16: Closed | K16: Authority To Start Evidence | L16: C. Vasquez
K17: Commissioning Results Sheet | L17: H. Lindqvist
K18: Commissioning Phase Report | L18: F. Moreau
K19: Handover Certificate | L19: G. Ashworth
K20: Functional Takeover Package | L20: E. Devereux
K21: Care And Maintenance Plan
K22: Maintenance Transfer Package
K23: Temporary Operations Transfer Package
K24: Final End Of Erection Status Report
A28: PHASE PROGRESS MAP | D28: WORKFLOW STATUS MAP | H28: READINESS & TIMING PARAMETERS | K28: CONTRACT HEALTH INDEX WEIGHTS | N28: THRESHOLDS
A29: Commissioning Phase | B29: Progress % | D29: Workflow Status | E29: Progress % | F29: Counts As Approved | H29: Parameter | I29: Value | K29: Component | L29: Weight | N29: Threshold | O29: Value
A30: Pre-Commissioning | B30: 0 | D30: Not Started | E30: 0 | F30: 0 | H30: Equipment readiness — phase weight | I30: 0.5 | K30: Documents | L30: 0.4 | N30: Health — Excellent (min) | O30: 0.9
A31: Commissioning Preparation | B31: 0.1 | D31: Draft | E31: 0.15 | F31: 0 | H31: Equipment readiness — document weight | I31: 0.5 | K31: Readiness | L31: 0.2 | N31: Health — Good (min) | O31: 0.75
A32: Documentation Review | B32: 0.2 | D32: Internal Review | E32: 0.3 | F32: 0 | H32: Review days (submission → approval) | I32: 21 | K32: Actions | L32: 0.15 | N32: Health — Attention Required (min) | O32: 0.5
A33: Testing Preparation | B33: 0.3 | D33: Submitted | E33: 0.45 | F33: 0 | K33: Milestones | L33: 0.1 | N33: RAG — Green (min) | O33: 0.75
A34: Testing In Progress | B34: 0.45 | D34: Under Review | E34: 0.55 | F34: 0 | H34: Equipment with no linked documents falls back to 100% phase weight. | K34: Equipment Progress | L34: 0.1 | N34: RAG — Amber (min) | O34: 0.5
A35: Results Review | B35: 0.6 | D35: Comments Received | E35: 0.5 | F35: 0 | K35: Handovers | L35: 0.05 | N35: Document due-soon window (days) | O35: 30
A36: Ready For Handover | B36: 0.7 | D36: Rework | E36: 0.4 | F36: 0 | K36: TOTAL | L36: =SUM(L30:L35) -> 1 | N36: Action due-soon window (days) | O36: 14
A37: Beneficial Use | B37: 0.8 | D37: Resubmitted | E37: 0.7 | F37: 0 | N37: Scope 'Ready' threshold | O37: 0.8
A38: Further Testing | B38: 0.85 | D38: Approved | E38: 0.9 | F38: 1 | N38: Upcoming milestone window (days) | O38: 30
A39: Final Handover | B39: 0.95 | D39: Released | E39: 0.95 | F39: 1
A40: Complete | B40: 1 | D40: Implemented | E40: 0.98 | F40: 1
D41: Closed | E41: 1 | F41: 1
A42: Assumption: the % ramp across the 11 spec phases is not defined in the source document. Edit the blue cells to retune.
A44: ATS READINESS GATE — MINIMUM REQUIRED APPROVED DELIVERABLES
A45: Required Document Type | B45: Approved | C45: Outstanding | D45: Met (1/0)
...
