Workbook
Name S_DONE: SETUP!$C$18
Name S_LATE: SETUP!$C$19
Name S_WIP: SETUP!$C$20
Name S_RISK: SETUP!$C$21
Name S_COMING: SETUP!$C$22
Name S_NOTYET: SETUP!$C$23
Name S_INACT: SETUP!$C$24
Name S_ONTRACK: SETUP!$C$25
Name S_NOSCOPE: SETUP!$C$26
Name S_NOTARGET: SETUP!$C$27
Name S_TYPEKO: SETUP!$C$28
Name S_NODUE: SETUP!$C$29
Name RAG_RED: SETUP!$C$32
Name RAG_AMB: SETUP!$C$33
Name RAG_GRN: SETUP!$C$34
Name A_OPEN: SETUP!$C$37
Name A_WIP: SETUP!$C$38
Name A_HOLD: SETUP!$C$39
Name A_DONE: SETUP!$C$40
Name CTR_NUM: SETUP!$C$5
Name CTR_NAME: SETUP!$C$6
Name FEN_DOC: SETUP!$C$12
Name FEN_ACT: SETUP!$C$13
Name HORIZON: SETUP!$C$14
Name CTR_EARLIEST: SETUP!$C$15
Name WF_CODE: SETUP!$B$44:$B$67
Name WF_CLASS: SETUP!$D$44:$D$67
Name MS_NOM: SETUP!$B$71:$B$85
Name MS_PLAN: SETUP!$E$71:$E$85
Name SYS_ID: SETUP!$B$89:$B$113
Name SYS_EARLIEST: SETUP!$E$89:$E$113
Name SYS_LATE: SETUP!$I$89:$I$113
Name EQP_SYS: SETUP!$B$117:$B$196
Name EQP_NOM: SETUP!$C$117:$C$196
Name EQP_START: SETUP!$D$117:$D$196
Name EQP_DOCS: SETUP!$H$117:$H$196
Name EQP_DONE: SETUP!$I$117:$I$196
Name EQP_LATE: SETUP!$J$117:$J$196
Name EQP_CORE: SETUP!$K$117:$K$196
Name EQP_PCT: SETUP!$L$117:$L$196
Name EQP_STATUS: SETUP!$M$117:$M$196
Name EQW_KEY: SETUP!$N$117:$N$196
Name TYP_TYPE: SETUP!$B$200:$B$219
Name TYP_PHASE: SETUP!$C$200:$C$219
Name TYP_CORE: SETUP!$D$200:$D$219
Name TYP_ANCHOR: SETUP!$E$200:$E$219
Name TYP_LEAD: SETUP!$F$200:$F$219
Name TYP_SCOPE: SETUP!$G$200:$G$219
Name TYP_COREKEY: SETUP!$I$200:$I$219
Name PHASE_LIST: SETUP!$B$223:$B$225
Name ACT_STATUS_LIST: SETUP!$C$37:$C$40
Name PPL_NAME: SETUP!$B$229:$B$258
Name DOC_TYPE: TRACKER!$A$4:$A$503
Name DOC_SCOPE: TRACKER!$B$4:$B$503
Name DOC_SYS: TRACKER!$C$4:$C$503
Name DOC_EQP: TRACKER!$D$4:$D$503
Name DOC_NUM: TRACKER!$E$4:$E$503
Name DOC_TARGET: TRACKER!$K$4:$K$503
Name DOC_STATE: TRACKER!$O$4:$O$503
Name DOC_CHECK: TRACKER!$P$4:$P$503

Sheet DASHBOARD
B1: COMMISSIONING DASHBOARD
B2: =IF(CTR_NAME="","Set the contract name in SETUP",CTR_NAME&" - "&CTR_NUM)&" | what is late, what has never been created, what is coming."
B4: CONTRACT STATUS
B6: =IF(OR(COUNTIF(DOC_STATE,S_LATE)>0,COUNTIF(ACT_STATE,S_LATE)>0),RAG_RED,IF(OR(COUNTIF(DOC_STATE,S_RISK)>0,COUNTIF(ACT_STATE,S_RISK)>0,COUNT(GAP_KEY)>0),RAG_AMB,RAG_GRN)) | E6: Worst item | G6: =IF(COUNT(CMB_KLATE)=0,"nothing late",IFERROR(INDEX(CMB_SUBJ,MATCH(MAX(CMB_KLATE),CMB_KLATE,0))&" ("&INT(MAX(CMB_KLATE))&" d late - "&INDEX(CMB_SCOPE,MATCH(MAX(CMB_KLATE),CMB_KLATE,0))&")","-"))
E7: Share late | G7: =IF(SUM(DOC_ACTIVE)+COUNTIF(ACT_ID,"?*")=0,"-",(COUNTIF(DOC_STATE,S_LATE)+COUNTIF(ACT_STATE,S_LATE))/(SUM(DOC_ACTIVE)+COUNTIF(ACT_ID,"?*")))
E8: Earliest commissioning start | G8: =IF(CTR_EARLIEST="","not set yet",TEXT(CTR_EARLIEST,"DD-MMM-YYYY")&IF(CTR_EARLIEST<TODAY()," started "&TODAY()-CTR_EARLIEST&" d ago"," in "&CTR_EARLIEST-TODAY()&" d"))
E9: Core deliverables missing | G9: =COUNT(GAP_KEY)
E10: Data quality flags | G10: =COUNTIF(DOC_CHECK,"?*")
B12: PROGRESS
C13: Done | D13: In progress | E13: Late | F13: Inactive | G13: Missing | H13: Total | I13: % done
B14: DOCUMENTS | C14: =COUNTIF(DOC_STATE,S_DONE) | D14: =COUNTIF(DOC_STATE,S_WIP) | E14: =COUNTIF(DOC_STATE,S_LATE) | F14: =COUNTIF(DOC_STATE,S_INACT) | G14: =COUNT(GAP_KEY) | H14: =SUM(DOC_ACTIVE) | I14: =IF($H14=0,"",$C14/$H14)
B15: ACTIONS | C15: =COUNTIF(ACT_STATE,S_DONE) | D15: =COUNTIF(ACT_STATE,S_WIP) | E15: =COUNTIF(ACT_STATE,S_LATE) | F15: =COUNTIF(ACT_STATUS,A_HOLD) | G15: =COUNTIF(ACT_STATE,S_NODUE) | H15: =COUNTIF(ACT_ID,"?*") | I15: =IF($H15=0,"",$C15/$H15)
B17: ="1. IN PROGRESS work started, or already late. Most late first. Showing "&MIN(10,COUNT(CMB_KWIP))&" of "&COUNT(CMB_KWIP)
B18: Kind | C18: Subject | D18: Scope | E18: Owner | F18: Target date | G18: Days late
B19: =IF($R19="","",IFERROR(INDEX(CMB_KIND,MATCH($R19,CMB_KWIP,0)),"")) | C19: =IF($R19="","",IFERROR(INDEX(CMB_SUBJ,MATCH($R19,CMB_KWIP,0)),"")) | D19: =IF($R19="","",IFERROR(INDEX(CMB_SCOPE,MATCH($R19,CMB_KWIP,0)),"")) | E19: =IF($R19="","",IFERROR(INDEX(CMB_OWNER,MATCH($R19,CMB_KWIP,0)),"")) | F19: =IF($R19="","",IFERROR(INDEX(CMB_TARGET,MATCH($R19,CMB_KWIP,0)),"")) | G19: =IF($R19="","",IFERROR(INDEX(CMB_DAYS,MATCH($R19,CMB_KWIP,0)),"")) | R19: =IFERROR(LARGE(CMB_KWIP,1),"")
B20: =IF($R20="","",IFERROR(INDEX(CMB_KIND,MATCH($R20,CMB_KWIP,0)),"")) | C20: =IF($R20="","",IFERROR(INDEX(CMB_SUBJ,MATCH($R20,CMB_KWIP,0)),"")) | D20: =IF($R20="","",IFERROR(INDEX(CMB_SCOPE,MATCH($R20,CMB_KWIP,0)),"")) | E20: =IF($R20="","",IFERROR(INDEX(CMB_OWNER,MATCH($R20,CMB_KWIP,0)),"")) | F20: =IF($R20="","",IFERROR(INDEX(CMB_TARGET,MATCH($R20,CMB_KWIP,0)),"")) | G20: =IF($R20="","",IFERROR(INDEX(CMB_DAYS,MATCH($R20,CMB_KWIP,0)),"")) | R20: =IFERROR(LARGE(CMB_KWIP,2),"")
B21: =IF($R21="","",IFERROR(INDEX(CMB_KIND,MATCH($R21,CMB_KWIP,0)),"")) | C21: =IF($R21="","",IFERROR(INDEX(CMB_SUBJ,MATCH($R21,CMB_KWIP,0)),"")) | D21: =IF($R21="","",IFERROR(INDEX(CMB_SCOPE,MATCH($R21,CMB_KWIP,0)),"")) | E21: =IF($R21="","",IFERROR(INDEX(CMB_OWNER,MATCH($R21,CMB_KWIP,0)),"")) | F21: =IF($R21="","",IFERROR(INDEX(CMB_TARGET,MATCH($R21,CMB_KWIP,0)),"")) | G21: =IF($R21="","",IFERROR(INDEX(CMB_DAYS,MATCH($R21,CMB_KWIP,0)),"")) | R21: =IFERROR(LARGE(CMB_KWIP,3),"")
B22: =IF($R22="","",IFERROR(INDEX(CMB_KIND,MATCH($R22,CMB_KWIP,0)),"")) | C22: =IF($R22="","",IFERROR(INDEX(CMB_SUBJ,MATCH($R22,CMB_KWIP,0)),"")) | D22: =IF($R22="","",IFERROR(INDEX(CMB_SCOPE,MATCH($R22,CMB_KWIP,0)),"")) | E22: =IF($R22="","",IFERROR(INDEX(CMB_OWNER,MATCH($R22,CMB_KWIP,0)),"")) | F22: =IF($R22="","",IFERROR(INDEX(CMB_TARGET,MATCH($R22,CMB_KWIP,0)),"")) | G22: =IF($R22="","",IFERROR(INDEX(CMB_DAYS,MATCH($R22,CMB_KWIP,0)),"")) | R22: =IFERROR(LARGE(CMB_KWIP,4),"")
B23: =IF($R23="","",IFERROR(INDEX(CMB_KIND,MATCH($R23,CMB_KWIP,0)),"")) | C23: =IF($R23="","",IFERROR(INDEX(CMB_SUBJ,MATCH($R23,CMB_KWIP,0)),"")) | D23: =IF($R23="","",IFERROR(INDEX(CMB_SCOPE,MATCH($R23,CMB_KWIP,0)),"")) | E23: =IF($R23="","",IFERROR(INDEX(CMB_OWNER,MATCH($R23,CMB_KWIP,0)),"")) | F23: =IF($R23="","",IFERROR(INDEX(CMB_TARGET,MATCH($R23,CMB_KWIP,0)),"")) | G23: =IF($R23="","",IFERROR(INDEX(CMB_DAYS,MATCH($R23,CMB_KWIP,0)),"")) | R23: =IFERROR(LARGE(CMB_KWIP,5),"")
B24: =IF($R24="","",IFERROR(INDEX(CMB_KIND,MATCH($R24,CMB_KWIP,0)),"")) | C24: =IF($R24="","",IFERROR(INDEX(CMB_SUBJ,MATCH($R24,CMB_KWIP,0)),"")) | D24: =IF($R24="","",IFERROR(INDEX(CMB_SCOPE,MATCH($R24,CMB_KWIP,0)),"")) | E24: =IF($R24="","",IFERROR(INDEX(CMB_OWNER,MATCH($R24,CMB_KWIP,0)),"")) | F24: =IF($R24="","",IFERROR(INDEX(CMB_TARGET,MATCH($R24,CMB_KWIP,0)),"")) | G24: =IF($R24="","",IFERROR(INDEX(CMB_DAYS,MATCH($R24,CMB_KWIP,0)),"")) | R24: =IFERROR(LARGE(CMB_KWIP,6),"")
B25: =IF($R25="","",IFERROR(INDEX(CMB_KIND,MATCH($R25,CMB_KWIP,0)),"")) | C25: =IF($R25="","",IFERROR(INDEX(CMB_SUBJ,MATCH($R25,CMB_KWIP,0)),"")) | D25: =IF($R25="","",IFERROR(INDEX(CMB_SCOPE,MATCH($R25,CMB_KWIP,0)),"")) | E25: =IF($R25="","",IFERROR(INDEX(CMB_OWNER,MATCH($R25,CMB_KWIP,0)),"")) | F25: =IF($R25="","",IFERROR(INDEX(CMB_TARGET,MATCH($R25,CMB_KWIP,0)),"")) | G25: =IF($R25="","",IFERROR(INDEX(CMB_DAYS,MATCH($R25,CMB_KWIP,0)),"")) | R25: =IFERROR(LARGE(CMB_KWIP,7),"")
B26: =IF($R26="","",IFERROR(INDEX(CMB_KIND,MATCH($R26,CMB_KWIP,0)),"")) | C26: =IF($R26="","",IFERROR(INDEX(CMB_SUBJ,MATCH($R26,CMB_KWIP,0)),"")) | D26: =IF($R26="","",IFERROR(INDEX(CMB_SCOPE,MATCH($R26,CMB_KWIP,0)),"")) | E26: =IF($R26="","",IFERROR(INDEX(CMB_OWNER,MATCH($R26,CMB_KWIP,0)),"")) | F26: =IF($R26="","",IFERROR(INDEX(CMB_TARGET,MATCH($R26,CMB_KWIP,0)),"")) | G26: =IF($R26="","",IFERROR(INDEX(CMB_DAYS,MATCH($R26,CMB_KWIP,0)),"")) | R26: =IFERROR(LARGE(CMB_KWIP,8),"")
B27: =IF($R27="","",IFERROR(INDEX(CMB_KIND,MATCH($R27,CMB_KWIP,0)),"")) | C27: =IF($R27="","",IFERROR(INDEX(CMB_SUBJ,MATCH($R27,CMB_KWIP,0)),"")) | D27: =IF($R27="","",IFERROR(INDEX(CMB_SCOPE,MATCH($R27,CMB_KWIP,0)),"")) | E27: =IF($R27="","",IFERROR(INDEX(CMB_OWNER,MATCH($R27,CMB_KWIP,0)),"")) | F27: =IF($R27="","",IFERROR(INDEX(CMB_TARGET,MATCH($R27,CMB_KWIP,0)),"")) | G27: =IF($R27="","",IFERROR(INDEX(CMB_DAYS,MATCH($R27,CMB_KWIP,0)),"")) | R27: =IFERROR(LARGE(CMB_KWIP,9),"")
B28: =IF($R28="","",IFERROR(INDEX(CMB_KIND,MATCH($R28,CMB_KWIP,0)),"")) | C28: =IF($R28="","",IFERROR(INDEX(CMB_SUBJ,MATCH($R28,CMB_KWIP,0)),"")) | D28: =IF($R28="","",IFERROR(INDEX(CMB_SCOPE,MATCH($R28,CMB_KWIP,0)),"")) | E28: =IF($R28="","",IFERROR(INDEX(CMB_OWNER,MATCH($R28,CMB_KWIP,0)),"")) | F28: =IF($R28="","",IFERROR(INDEX(CMB_TARGET,MATCH($R28,CMB_KWIP,0)),"")) | G28: =IF($R28="","",IFERROR(INDEX(CMB_DAYS,MATCH($R28,CMB_KWIP,0)),"")) | R28: =IFERROR(LARGE(CMB_KWIP,10),"")
B30: ="2. MISSING core deliverables that do not exist yet. Soonest needed first. Showing "&MIN(10,COUNT(GAP_KEY))&" of "&COUNT(GAP_KEY)
B31: Level | C31: Deliverable | D31: Where | E31: Needed by
B32: =IF($R32="","",IFERROR(INDEX(GAP_KIND,MATCH($R32,GAP_KEY,0)),"")) | C32: =IF($R32="","",IFERROR(INDEX(GAP_WHAT,MATCH($R32,GAP_KEY,0)),"")) | D32: =IF($R32="","",IFERROR(INDEX(GAP_WHERE,MATCH($R32,GAP_KEY,0)),"")) | E32: =IF($R32="","",IF(INT($R32)>=60000,"",INT($R32))) | R32: =IFERROR(SMALL(GAP_KEY,1),"")
B33: =IF($R33="","",IFERROR(INDEX(GAP_KIND,MATCH($R33,GAP_KEY,0)),"")) | C33: =IF($R33="","",IFERROR(INDEX(GAP_WHAT,MATCH($R33,GAP_KEY,0)),"")) | D33: =IF($R33="","",IFERROR(INDEX(GAP_WHERE,MATCH($R33,GAP_KEY,0)),"")) | E33: =IF($R33="","",IF(INT($R33)>=60000,"",INT($R33))) | R33: =IFERROR(SMALL(GAP_KEY,2),"")
B34: =IF($R34="","",IFERROR(INDEX(GAP_KIND,MATCH($R34,GAP_KEY,0)),"")) | C34: =IF($R34="","",IFERROR(INDEX(GAP_WHAT,MATCH($R34,GAP_KEY,0)),"")) | D34: =IF($R34="","",IFERROR(INDEX(GAP_WHERE,MATCH($R34,GAP_KEY,0)),"")) | E34: =IF($R34="","",IF(INT($R34)>=60000,"",INT($R34))) | R34: =IFERROR(SMALL(GAP_KEY,3),"")
B35: =IF($R35="","",IFERROR(INDEX(GAP_KIND,MATCH($R35,GAP_KEY,0)),"")) | C35: =IF($R35="","",IFERROR(INDEX(GAP_WHAT,MATCH($R35,GAP_KEY,0)),"")) | D35: =IF($R35="","",IFERROR(INDEX(GAP_WHERE,MATCH($R35,GAP_KEY,0)),"")) | E35: =IF($R35="","",IF(INT($R35)>=60000,"",INT($R35))) | R35: =IFERROR(SMALL(GAP_KEY,4),"")
B36: =IF($R36="","",IFERROR(INDEX(GAP_KIND,MATCH($R36,GAP_KEY,0)),"")) | C36: =IF($R36="","",IFERROR(INDEX(GAP_WHAT,MATCH($R36,GAP_KEY,0)),"")) | D36: =IF($R36="","",IFERROR(INDEX(GAP_WHERE,MATCH($R36,GAP_KEY,0)),"")) | E36: =IF($R36="","",IF(INT($R36)>=60000,"",INT($R36))) | R36: =IFERROR(SMALL(GAP_KEY,5),"")
B37: =IF($R37="","",IFERROR(INDEX(GAP_KIND,MATCH($R37,GAP_KEY,0)),"")) | C37: =IF($R37="","",IFERROR(INDEX(GAP_WHAT,MATCH($R37,GAP_KEY,0)),"")) | D37: =IF($R37="","",IFERROR(INDEX(GAP_WHERE,MATCH($R37,GAP_KEY,0)),"")) | E37: =IF($R37="","",IF(INT($R37)>=60000,"",INT($R37))) | R37: =IFERROR(SMALL(GAP_KEY,6),"")
B38: =IF($R38="","",IFERROR(INDEX(GAP_KIND,MATCH($R38,GAP_KEY,0)),"")) | C38: =IF($R38="","",IFERROR(INDEX(GAP_WHAT,MATCH($R38,GAP_KEY,0)),"")) | D38: =IF($R38="","",IFERROR(INDEX(GAP_WHERE,MATCH($R38,GAP_KEY,0)),"")) | E38: =IF($R38="","",IF(INT($R38)>=60000,"",INT($R38))) | R38: =IFERROR(SMALL(GAP_KEY,7),"")
B39: =IF($R39="","",IFERROR(INDEX(GAP_KIND,MATCH($R39,GAP_KEY,0)),"")) | C39: =IF($R39="","",IFERROR(INDEX(GAP_WHAT,MATCH($R39,GAP_KEY,0)),"")) | D39: =IF($R39="","",IFERROR(INDEX(GAP_WHERE,MATCH($R39,GAP_KEY,0)),"")) | E39: =IF($R39="","",IF(INT($R39)>=60000,"",INT($R39))) | R39: =IFERROR(SMALL(GAP_KEY,8),"")
B40: =IF($R40="","",IFERROR(INDEX(GAP_KIND,MATCH($R40,GAP_KEY,0)),"")) | C40: =IF($R40="","",IFERROR(INDEX(GAP_WHAT,MATCH($R40,GAP_KEY,0)),"")) | D40: =IF($R40="","",IFERROR(INDEX(GAP_WHERE,MATCH($R40,GAP_KEY,0)),"")) | E40: =IF($R40="","",IF(INT($R40)>=60000,"",INT($R40))) | R40: =IFERROR(SMALL(GAP_KEY,9),"")
B41: =IF($R41="","",IFERROR(INDEX(GAP_KIND,MATCH($R41,GAP_KEY,0)),"")) | C41: =IF($R41="","",IFERROR(INDEX(GAP_WHAT,MATCH($R41,GAP_KEY,0)),"")) | D41: =IF($R41="","",IFERROR(INDEX(GAP_WHERE,MATCH($R41,GAP_KEY,0)),"")) | E41: =IF($R41="","",IF(INT($R41)>=60000,"",INT($R41))) | R41: =IFERROR(SMALL(GAP_KEY,10),"")
B43: ="3. COMING not started, due inside the horizon set in SETUP. Soonest first. Showing "&MIN(10,COUNT(CMB_KCOME))&" of "&COUNT(CMB_KCOME)
B44: Kind | C44: Subject | D44: Scope | E44: Owner | F44: Target date | G44: Days left
B45: =IF($R45="","",IFERROR(INDEX(CMB_KIND,MATCH($R45,CMB_KCOME,0)),"")) | C45: =IF($R45="","",IFERROR(INDEX(CMB_SUBJ,MATCH($R45,CMB_KCOME,0)),"")) | D45: =IF($R45="","",IFERROR(INDEX(CMB_SCOPE,MATCH($R45,CMB_KCOME,0)),"")) | E45: =IF($R45="","",IFERROR(INDEX(CMB_OWNER,MATCH($R45,CMB_KCOME,0)),"")) | F45: =IF($R45="","",IFERROR(INDEX(CMB_TARGET,MATCH($R45,CMB_KCOME,0)),"")) | G45: =IF($R45="","",-INDEX(CMB_DAYS,MATCH($R45,CMB_KCOME,0))) | R45: =IFERROR(LARGE(CMB_KCOME,1),"")
B46: =IF($R46="","",IFERROR(INDEX(CMB_KIND,MATCH($R46,CMB_KCOME,0)),"")) | C46: =IF($R46="","",IFERROR(INDEX(CMB_SUBJ,MATCH($R46,CMB_KCOME,0)),"")) | D46: =IF($R46="","",IFERROR(INDEX(CMB_SCOPE,MATCH($R46,CMB_KCOME,0)),"")) | E46: =IF($R46="","",IFERROR(INDEX(CMB_OWNER,MATCH($R46,CMB_KCOME,0)),"")) | F46: =IF($R46="","",IFERROR(INDEX(CMB_TARGET,MATCH($R46,CMB_KCOME,0)),"")) | G46: =IF($R46="","",-INDEX(CMB_DAYS,MATCH($R46,CMB_KCOME,0))) | R46: =IFERROR(LARGE(CMB_KCOME,2),"")
...

Sheet TRACKER
A1: DELIVERABLES TRACKER
A2: One row per document per thing it covers: the whole contract (Scope = All), a system, or a piece of equipment. A document covering three systems is three rows. Fill Actual start when work begins. Days late: positive = late, negative = float.
A3: Type | B3: Scope | C3: System | D3: Equipment | E3: Document no. | F3: Responsible (drafting) | G3: Approver | H3: Status | I3: Actual start | J3: Target override | K3: Target approval | L3: Source | M3: Actual approval | N3: Days late | O3: State | P3: Check | Q3: Comment | R3: Scope date | S3: Auto target | T3: Active | U3: Done | V3: Inactive | W3: Phase | X3: k late | Y3: k wip | Z3: k coming
A4: Basis of Commissioning | B4: All | E4: DMIC-ALL-BOC-001 | F4: S. Okonkwo | G4: P. Nakamura | H4: P1 - For Implementation | K4: =IF($A4="","",IF($J4<>"",$J4,$S4)) | L4: =IF(OR($A4="",$E4=""),"",IF($J4<>"","Manual",IF($S4="","-","Auto"))) | M4: 45955 | N4: =IF($T4=0,"",IF($U4=1,IF($M4="","",$M4-$K4),IF($K4="","",TODAY()-$K4))) | O4: =IF(OR($A4="",$E4=""),"",IF($V4=1,S_INACT,IF(ISNA(MATCH($A4,TYP_TYPE,0)),S_TYPEKO,IF($U4=1,S_DONE,IF(AND($K4="",$R4=""),S_NOSCOPE,IF($K4="",S_NOTARGET,IF($N4>0,S_LATE,IF($I4<>"",S_WIP,IF(-$N4<=FEN_DOC,S_RISK,IF(-$N4<=HORIZON,S_COMING,S_NOTYET)))))))))) | P4: =IF(OR($A4="",$E4=""),"",IF($V4=1,"",IF(ISNA(MATCH($A4,TYP_TYPE,0)),"Type not in the library",IF($B4="","Scope not set",IF(AND($B4="System",$C4=""),"System not set",IF(AND($B4="Equipment",$D4=""),"Equipment not set",IF($F4="","Responsible not set",IF($K4="","No target date",IF(AND($B4="Equipment",$C4<>"",IFERROR(INDEX(EQP_SYS,MATCH($D4,EQP_NOM,0)),"")<>$C4),"Equipment not in that system",IF(AND($U4=1,$M4=""),"Approved with no approval date","")))))))))) | R4: =IF(OR($A4="",$B4=""),"",IF($B4="Equipment",IFERROR(INDEX(EQP_START,MATCH($D4,EQP_NOM,0)),""),IF($B4="System",IFERROR(INDEX(SYS_EARLIEST,MATCH($C4,SYS_ID,0)),""),IF($B4="All",CTR_EARLIEST,"")))) | S4: =IF(OR($A4="",$E4=""),"",IFERROR(IF(INDEX(TYP_ANCHOR,MATCH($A4,TYP_TYPE,0))="Commissioning Start",IF($R4="","",$R4-INDEX(TYP_LEAD,MATCH($A4,TYP_TYPE,0))),IF(INDEX(MS_PLAN,MATCH(INDEX(TYP_ANCHOR,MATCH($A4,TYP_TYPE,0)),MS_NOM,0))="","",INDEX(MS_PLAN,MATCH(INDEX(TYP_ANCHOR,MATCH($A4,TYP_TYPE,0)),MS_NOM,0))-INDEX(TYP_LEAD,MATCH($A4,TYP_TYPE,0)))),"")) | T4: =IF(OR($A4="",$E4=""),0,IF($V4=1,0,1)) | U4: =IF($T4=0,0,IF($M4<>"",1,IF(IFERROR(INDEX(WF_CLASS,MATCH($H4,WF_CODE,0)),"")="Done",1,0))) | V4: =IF(OR($A4="",$E4=""),0,IF(IFERROR(INDEX(WF_CLASS,MATCH($H4,WF_CODE,0)),"")="Inactive",1,0)) | W4: =IF($A4="","",IFERROR(INDEX(TYP_PHASE,MATCH($A4,TYP_TYPE,0)),"-")) | X4: =IF(AND($T4=1,$U4=0,N($N4)>0),$N4+ROW()/1000000,"") | Y4: =IF(AND($T4=1,$U4=0,OR($I4<>"",N($N4)>0)),N($N4)+ROW()/1000000,"") | Z4: =IF(AND($T4=1,$U4=0,$I4="",N($N4)<=0,-N($N4)<=HORIZON),N($N4)+ROW()/1000000,"")
A5: Surveillance Strategy | B5: All | E5: DMIC-ALL-SVS-002 | F5: L. Fontaine | G5: K. Rasmussen | H5: P6 - For Construction | K5: =IF($A5="","",IF($J5<>"",$J5,$S5)) | L5: =IF(OR($A5="",$E5=""),"",IF($J5<>"","Manual",IF($S5="","-","Auto"))) | M5: 45956 | N5: =IF($T5=0,"",IF($U5=1,IF($M5="","",$M5-$K5),IF($K5="","",TODAY()-$K5))) | O5: =IF(OR($A5="",$E5=""),"",IF($V5=1,S_INACT,IF(ISNA(MATCH($A5,TYP_TYPE,0)),S_TYPEKO,IF($U5=1,S_DONE,IF(AND($K5="",$R5=""),S_NOSCOPE,IF($K5="",S_NOTARGET,IF($N5>0,S_LATE,IF($I5<>"",S_WIP,IF(-$N5<=FEN_DOC,S_RISK,IF(-$N5<=HORIZON,S_COMING,S_NOTYET)))))))))) | P5: =IF(OR($A5="",$E5=""),"",IF($V5=1,"",IF(ISNA(MATCH($A5,TYP_TYPE,0)),"Type not in the library",IF($B5="","Scope not set",IF(AND($B5="System",$C5=""),"System not set",IF(AND($B5="Equipment",$D5=""),"Equipment not set",IF($F5="","Responsible not set",IF($K5="","No target date",IF(AND($B5="Equipment",$C5<>"",IFERROR(INDEX(EQP_SYS,MATCH($D5,EQP_NOM,0)),"")<>$C5),"Equipment not in that system",IF(AND($U5=1,$M5=""),"Approved with no approval date","")))))))))) | R5: =IF(OR($A5="",$B5=""),"",IF($B5="Equipment",IFERROR(INDEX(EQP_START,MATCH($D5,EQP_NOM,0)),""),IF($B5="System",IFERROR(INDEX(SYS_EARLIEST,MATCH($C5,SYS_ID,0)),""),IF($B5="All",CTR_EARLIEST,"")))) | S5: =IF(OR($A5="",$E5=""),"",IFERROR(IF(INDEX(TYP_ANCHOR,MATCH($A5,TYP_TYPE,0))="Commissioning Start",IF($R5="","",$R5-INDEX(TYP_LEAD,MATCH($A5,TYP_TYPE,0))),IF(INDEX(MS_PLAN,MATCH(INDEX(TYP_ANCHOR,MATCH($A5,TYP_TYPE,0)),MS_NOM,0))="","",INDEX(MS_PLAN,MATCH(INDEX(TYP_ANCHOR,MATCH($A5,TYP_TYPE,0)),MS_NOM,0))-INDEX(TYP_LEAD,MATCH($A5,TYP_TYPE,0)))),"")) | T5: =IF(OR($A5="",$E5=""),0,IF($V5=1,0,1)) | U5: =IF($T5=0,0,IF($M5<>"",1,IF(IFERROR(INDEX(WF_CLASS,MATCH($H5,WF_CODE,0)),"")="Done",1,0))) | V5: =IF(OR($A5="",$E5=""),0,IF(IFERROR(INDEX(WF_CLASS,MATCH($H5,WF_CODE,0)),"")="Inactive",1,0)) | W5: =IF($A5="","",IFERROR(INDEX(TYP_PHASE,MATCH($A5,TYP_TYPE,0)),"-")) | X5: =IF(AND($T5=1,$U5=0,N($N5)>0),$N5+ROW()/1000000,"") | Y5: =IF(AND($T5=1,$U5=0,OR($I5<>"",N($N5)>0)),N($N5)+ROW()/1000000,"") | Z5: =IF(AND($T5=1,$U5=0,$I5="",N($N5)<=0,-N($N5)<=HORIZON),N($N5)+ROW()/1000000,"")
A6: Competency Evidence | B6: All | E6: DMIC-ALL-CPE-003 | F6: D. Petrov | G6: R. Bellamy | H6: S4B - Comments | I6: 46001 | K6: =IF($A6="","",IF($J6<>"",$J6,$S6)) | L6: =IF(OR($A6="",$E6=""),"",IF($J6<>"","Manual",IF($S6="","-","Auto"))) | N6: =IF($T6=0,"",IF($U6=1,IF($M6="","",$M6-$K6),IF($K6="","",TODAY()-$K6))) | O6: =IF(OR($A6="",$E6=""),"",IF($V6=1,S_INACT,IF(ISNA(MATCH($A6,TYP_TYPE,0)),S_TYPEKO,IF($U6=1,S_DONE,IF(AND($K6="",$R6=""),S_NOSCOPE,IF($K6="",S_NOTARGET,IF($N6>0,S_LATE,IF($I6<>"",S_WIP,IF(-$N6<=FEN_DOC,S_RISK,IF(-$N6<=HORIZON,S_COMING,S_NOTYET)))))))))) | P6: =IF(OR($A6="",$E6=""),"",IF($V6=1,"",IF(ISNA(MATCH($A6,TYP_TYPE,0)),"Type not in the library",IF($B6="","Scope not set",IF(AND($B6="System",$C6=""),"System not set",IF(AND($B6="Equipment",$D6=""),"Equipment not set",IF($F6="","Responsible not set",IF($K6="","No target date",IF(AND($B6="Equipment",$C6<>"",IFERROR(INDEX(EQP_SYS,MATCH($D6,EQP_NOM,0)),"")<>$C6),"Equipment not in that system",IF(AND($U6=1,$M6=""),"Approved with no approval date","")))))))))) | R6: =IF(OR($A6="",$B6=""),"",IF($B6="Equipment",IFERROR(INDEX(EQP_START,MATCH($D6,EQP_NOM,0)),""),IF($B6="System",IFERROR(INDEX(SYS_EARLIEST,MATCH($C6,SYS_ID,0)),""),IF($B6="All",CTR_EARLIEST,"")))) | S6: =IF(OR($A6="",$E6=""),"",IFERROR(IF(INDEX(TYP_ANCHOR,MATCH($A6,TYP_TYPE,0))="Commissioning Start",IF($R6="","",$R6-INDEX(TYP_LEAD,MATCH($A6,TYP_TYPE,0))),IF(INDEX(MS_PLAN,MATCH(INDEX(TYP_ANCHOR,MATCH($A6,TYP_TYPE,0)),MS_NOM,0))="","",INDEX(MS_PLAN,MATCH(INDEX(TYP_ANCHOR,MATCH($A6,TYP_TYPE,0)),MS_NOM,0))-INDEX(TYP_LEAD,MATCH($A6,TYP_TYPE,0)))),"")) | T6: =IF(OR($A6="",$E6=""),0,IF($V6=1,0,1)) | U6: =IF($T6=0,0,IF($M6<>"",1,IF(IFERROR(INDEX(WF_CLASS,MATCH($H6,WF_CODE,0)),"")="Done",1,0))) | V6: =IF(OR($A6="",$E6=""),0,IF(IFERROR(INDEX(WF_CLASS,MATCH($H6,WF_CODE,0)),"")="Inactive",1,0)) | W6: =IF($A6="","",IFERROR(INDEX(TYP_PHASE,MATCH($A6,TYP_TYPE,0)),"-")) | X6: =IF(AND($T6=1,$U6=0,N($N6)>0),$N6+ROW()/1000000,"") | Y6: =IF(AND($T6=1,$U6=0,OR($I6<>"",N($N6)>0)),N($N6)+ROW()/1000000,"") | Z6: =IF(AND($T6=1,$U6=0,$I6="",N($N6)<=0,-N($N6)<=HORIZON),N($N6)+ROW()/1000000,"")
A7: Surveillance Programme | B7: System | C7: SYS-TP | E7: DMIC-SYS-TP-SVP-004 | F7: J. Whitfield | G7: N. Bergstrom | H7: P1 - For Implementation | K7: =IF($A7="","",IF($J7<>"",$J7,$S7)) | L7: =IF(OR($A7="",$E7=""),"",IF($J7<>"","Manual",IF($S7="","-","Auto"))) | M7: 46048 | N7: =IF($T7=0,"",IF($U7=1,IF($M7="","",$M7-$K7),IF($K7="","",TODAY()-$K7))) | O7: =IF(OR($A7="",$E7=""),"",IF($V7=1,S_INACT,IF(ISNA(MATCH($A7,TYP_TYPE,0)),S_TYPEKO,IF($U7=1,S_DONE,IF(AND($K7="",$R7=""),S_NOSCOPE,IF($K7="",S_NOTARGET,IF($N7>0,S_LATE,IF($I7<>"",S_WIP,IF(-$N7<=FEN_DOC,S_RISK,IF(-$N7<=HORIZON,S_COMING,S_NOTYET)))))))))) | P7: =IF(OR($A7="",$E7=""),"",IF($V7=1,"",IF(ISNA(MATCH($A7,TYP_TYPE,0)),"Type not in the library",IF($B7="","Scope not set",IF(AND($B7="System",$C7=""),"System not set",IF(AND($B7="Equipment",$D7=""),"Equipment not set",IF($F7="","Responsible not set",IF($K7="","No target date",IF(AND($B7="Equipment",$C7<>"",IFERROR(INDEX(EQP_SYS,MATCH($D7,EQP_NOM,0)),"")<>$C7),"Equipment not in that system",IF(AND($U7=1,$M7=""),"Approved with no approval date","")))))))))) | R7: =IF(OR($A7="",$B7=""),"",IF($B7="Equipment",IFERROR(INDEX(EQP_START,MATCH($D7,EQP_NOM,0)),""),IF($B7="System",IFERROR(INDEX(SYS_EARLIEST,MATCH($C7,SYS_ID,0)),""),IF($B7="All",CTR_EARLIEST,"")))) | S7: =IF(OR($A7="",$E7=""),"",IFERROR(IF(INDEX(TYP_ANCHOR,MATCH($A7,TYP_TYPE,0))="Commissioning Start",IF($R7="","",$R7-INDEX(TYP_LEAD,MATCH($A7,TYP_TYPE,0))),IF(INDEX(MS_PLAN,MATCH(INDEX(TYP_ANCHOR,MATCH($A7,TYP_TYPE,0)),MS_NOM,0))="","",INDEX(MS_PLAN,MATCH(INDEX(TYP_ANCHOR,MATCH($A7,TYP_TYPE,0)),MS_NOM,0))-INDEX(TYP_LEAD,MATCH($A7,TYP_TYPE,0)))),"")) | T7: =IF(OR($A7="",$E7=""),0,IF($V7=1,0,1)) | U7: =IF($T7=0,0,IF($M7<>"",1,IF(IFERROR(INDEX(WF_CLASS,MATCH($H7,WF_CODE,0)),"")="Done",1,0))) | V7: =IF(OR($A7="",$E7=""),0,IF(IFERROR(INDEX(WF_CLASS,MATCH($H7,WF_CODE,0)),"")="Inactive",1,0)) | W7: =IF($A7="","",IFERROR(INDEX(TYP_PHASE,MATCH($A7,TYP_TYPE,0)),"-")) | X7: =IF(AND($T7=1,$U7=0,N($N7)>0),$N7+ROW()/1000000,"") | Y7: =IF(AND($T7=1,$U7=0,OR($I7<>"",N($N7)>0)),N($N7)+ROW()/1000000,"") | Z7: =IF(AND($T7=1,$U7=0,$I7="",N($N7)<=0,-N($N7)<=HORIZON),N($N7)+ROW()/1000000,"")
A8: Safe System Of Work | B8: System | C8: SYS-TP | E8: DMIC-SYS-TP-SSW-005 | F8: P. Nakamura | G8: M. Haddad | H8: P6 - For Construction | J8: 46280 | K8: =IF($A8="","",IF($J8<>"",$J8,$S8)) | L8: =IF(OR($A8="",$E8=""),"",IF($J8<>"","Manual",IF($S8="","-","Auto"))) | M8: 46139 | N8: =IF($T8=0,"",IF($U8=1,IF($M8="","",$M8-$K8),IF($K8="","",TODAY()-$K8))) | O8: =IF(OR($A8="",$E8=""),"",IF($V8=1,S_INACT,IF(ISNA(MATCH($A8,TYP_TYPE,0)),S_TYPEKO,IF($U8=1,S_DONE,IF(AND($K8="",$R8=""),S_NOSCOPE,IF($K8="",S_NOTARGET,IF($N8>0,S_LATE,IF($I8<>"",S_WIP,IF(-$N8<=FEN_DOC,S_RISK,IF(-$N8<=HORIZON,S_COMING,S_NOTYET)))))))))) | P8: =IF(OR($A8="",$E8=""),"",IF($V8=1,"",IF(ISNA(MATCH($A8,TYP_TYPE,0)),"Type not in the library",IF($B8="","Scope not set",IF(AND($B8="System",$C8=""),"System not set",IF(AND($B8="Equipment",$D8=""),"Equipment not set",IF($F8="","Responsible not set",IF($K8="","No target date",IF(AND($B8="Equipment",$C8<>"",IFERROR(INDEX(EQP_SYS,MATCH($D8,EQP_NOM,0)),"")<>$C8),"Equipment not in that system",IF(AND($U8=1,$M8=""),"Approved with no approval date","")))))))))) | Q8: Target moved by agreement - waiting on the SYS-SG interface package. | R8: =IF(OR($A8="",$B8=""),"",IF($B8="Equipment",IFERROR(INDEX(EQP_START,MATCH($D8,EQP_NOM,0)),""),IF($B8="System",IFERROR(INDEX(SYS_EARLIEST,MATCH($C8,SYS_ID,0)),""),IF($B8="All",CTR_EARLIEST,"")))) | S8: =IF(OR($A8="",$E8=""),"",IFERROR(IF(INDEX(TYP_ANCHOR,MATCH($A8,TYP_TYPE,0))="Commissioning Start",IF($R8="","",$R8-INDEX(TYP_LEAD,MATCH($A8,TYP_TYPE,0))),IF(INDEX(MS_PLAN,MATCH(INDEX(TYP_ANCHOR,MATCH($A8,TYP_TYPE,0)),MS_NOM,0))="","",INDEX(MS_PLAN,MATCH(INDEX(TYP_ANCHOR,MATCH($A8,TYP_TYPE,0)),MS_NOM,0))-INDEX(TYP_LEAD,MATCH($A8,TYP_TYPE,0)))),"")) | T8: =IF(OR($A8="",$E8=""),0,IF($V8=1,0,1)) | U8: =IF($T8=0,0,IF($M8<>"",1,IF(IFERROR(INDEX(WF_CLASS,MATCH($H8,WF_CODE,0)),"")="Done",1,0))) | V8: =IF(OR($A8="",$E8=""),0,IF(IFERROR(INDEX(WF_CLASS,MATCH($H8,WF_CODE,0)),"")="Inactive",1,0)) | W8: =IF($A8="","",IFERROR(INDEX(TYP_PHASE,MATCH($A8,TYP_TYPE,0)),"-")) | X8: =IF(AND($T8=1,$U8=0,N($N8)>0),$N8+ROW()/1000000,"") | Y8: =IF(AND($T8=1,$U8=0,OR($I8<>"",N($N8)>0)),N($N8)+ROW()/1000000,"") | Z8: =IF(AND($T8=1,$U8=0,$I8="",N($N8)<=0,-N($N8)<=HORIZON),N($N8)+ROW()/1000000,"")
A9: Risk Assessment And Method Statement | B9: System | C9: SYS-TP | E9: DMIC-SYS-TP-RAM-006 | F9: K. Rasmussen | G9: C. Vasquez | H9: S4A - Approved | K9: =IF($A9="","",IF($J9<>"",$J9,$S9)) | L9: =IF(OR($A9="",$E9=""),"",IF($J9<>"","Manual",IF($S9="","-","Auto"))) | M9: 46140 | N9: =IF($T9=0,"",IF($U9=1,IF($M9="","",$M9-$K9),IF($K9="","",TODAY()-$K9))) | O9: =IF(OR($A9="",$E9=""),"",IF($V9=1,S_INACT,IF(ISNA(MATCH($A9,TYP_TYPE,0)),S_TYPEKO,IF($U9=1,S_DONE,IF(AND($K9="",$R9=""),S_NOSCOPE,IF($K9="",S_NOTARGET,IF($N9>0,S_LATE,IF($I9<>"",S_WIP,IF(-$N9<=FEN_DOC,S_RISK,IF(-$N9<=HORIZON,S_COMING,S_NOTYET)))))))))) | P9: =IF(OR($A9="",$E9=""),"",IF($V9=1,"",IF(ISNA(MATCH($A9,TYP_TYPE,0)),"Type not in the library",IF($B9="","Scope not set",IF(AND($B9="System",$C9=""),"System not set",IF(AND($B9="Equipment",$D9=""),"Equipment not set",IF($F9="","Responsible not set",IF($K9="","No target date",IF(AND($B9="Equipment",$C9<>"",IFERROR(INDEX(EQP_SYS,MATCH($D9,EQP_NOM,0)),"")<>$C9),"Equipment not in that system",IF(AND($U9=1,$M9=""),"Approved with no approval date","")))))))))) | R9: =IF(OR($A9="",$B9=""),"",IF($B9="Equipment",IFERROR(INDEX(EQP_START,MATCH($D9,EQP_NOM,0)),""),IF($B9="System",IFERROR(INDEX(SYS_EARLIEST,MATCH($C9,SYS_ID,0)),""),IF($B9="All",CTR_EARLIEST,"")))) | S9: =IF(OR($A9="",$E9=""),"",IFERROR(IF(INDEX(TYP_ANCHOR,MATCH($A9,TYP_TYPE,0))="Commissioning Start",IF($R9="","",$R9-INDEX(TYP_LEAD,MATCH($A9,TYP_TYPE,0))),IF(INDEX(MS_PLAN,MATCH(INDEX(TYP_ANCHOR,MATCH($A9,TYP_TYPE,0)),MS_NOM,0))="","",INDEX(MS_PLAN,MATCH(INDEX(TYP_ANCHOR,MATCH($A9,TYP_TYPE,0)),MS_NOM,0))-INDEX(TYP_LEAD,MATCH($A9,TYP_TYPE,0)))),"")) | T9: =IF(OR($A9="",$E9=""),0,IF($V9=1,0,1)) | U9: =IF($T9=0,0,IF($M9<>"",1,IF(IFERROR(INDEX(WF_CLASS,MATCH($H9,WF_CODE,0)),"")="Done",1,0))) | V9: =IF(OR($A9="",$E9=""),0,IF(IFERROR(INDEX(WF_CLASS,MATCH($H9,WF_CODE,0)),"")="Inactive",1,0)) | W9: =IF($A9="","",IFERROR(INDEX(TYP_PHASE,MATCH($A9,TYP_TYPE,0)),"-")) | X9: =IF(AND($T9=1,$U9=0,N($N9)>0),$N9+ROW()/1000000,"") | Y9: =IF(AND($T9=1,$U9=0,OR($I9<>"",N($N9)>0)),N($N9)+ROW()/1000000,"") | Z9: =IF(AND($T9=1,$U9=0,$I9="",N($N9)<=0,-N($N9)<=HORIZON),N($N9)+ROW()/1000000,"")
A10: System Commissioning Programme | B10: System | C10: SYS-TP | E10: DMIC-SYS-TP-SCP-007 | F10: R. Bellamy | G10: H. Lindqvist | H10: P1 - For Implementation | K10: =IF($A10="","",IF($J10<>"",$J10,$S10)) | L10: =IF(OR($A10="",$E10=""),"",IF($J10<>"","Manual",IF($S10="","-","Auto"))) | M10: 46141 | N10: =IF($T10=0,"",IF($U10=1,IF($M10="","",$M10-$K10),IF($K10="","",TODAY()-$K10))) | O10: =IF(OR($A10="",$E10=""),"",IF($V10=1,S_INACT,IF(ISNA(MATCH($A10,TYP_TYPE,0)),S_TYPEKO,IF($U10=1,S_DONE,IF(AND($K10="",$R10=""),S_NOSCOPE,IF($K10="",S_NOTARGET,IF($N10>0,S_LATE,IF($I10<>"",S_WIP,IF(-$N10<=FEN_DOC,S_RISK,IF(-$N10<=HORIZON,S_COMING,S_NOTYET)))))))))) | P10: =IF(OR($A10="",$E10=""),"",IF($V10=1,"",IF(ISNA(MATCH($A10,TYP_TYPE,0)),"Type not in the library",IF($B10="","Scope not set",IF(AND($B10="System",$C10=""),"System not set",IF(AND($B10="Equipment",$D10=""),"Equipment not set",IF($F10="","Responsible not set",IF($K10="","No target date",IF(AND($B10="Equipment",$C10<>"",IFERROR(INDEX(EQP_SYS,MATCH($D10,EQP_NOM,0)),"")<>$C10),"Equipment not in that system",IF(AND($U10=1,$M10=""),"Approved with no approval date","")))))))))) | R10: =IF(OR($A10="",$B10=""),"",IF($B10="Equipment",IFERROR(INDEX(EQP_START,MATCH($D10,EQP_NOM,0)),""),IF($B10="System",IFERROR(INDEX(SYS_EARLIEST,MATCH($C10,SYS_ID,0)),""),IF($B10="All",CTR_EARLIEST,"")))) | S10: =IF(OR($A10="",$E10=""),"",IFERROR(IF(INDEX(TYP_ANCHOR,MATCH($A10,TYP_TYPE,0))="Commissioning Start",IF($R10="","",$R10-INDEX(TYP_LEAD,MATCH($A10,TYP_TYPE,0))),IF(INDEX(MS_PLAN,MATCH(INDEX(TYP_ANCHOR,MATCH($A10,TYP_TYPE,0)),MS_NOM,0))="","",INDEX(MS_PLAN,MATCH(INDEX(TYP_ANCHOR,MATCH($A10,TYP_TYPE,0)),MS_NOM,0))-INDEX(TYP_LEAD,MATCH($A10,TYP_TYPE,0)))),"")) | T10: =IF(OR($A10="",$E10=""),0,IF($V10=1,0,1)) | U10: =IF($T10=0,0,IF($M10<>"",1,IF(IFERROR(INDEX(WF_CLASS,MATCH($H10,WF_CODE,0)),"")="Done",1,0))) | V10: =IF(OR($A10="",$E10=""),0,IF(IFERROR(INDEX(WF_CLASS,MATCH($H10,WF_CODE,0)),"")="Inactive",1,0)) | W10: =IF($A10="","",IFERROR(INDEX(TYP_PHASE,MATCH($A10,TYP_TYPE,0)),"-")) | X10: =IF(AND($T10=1,$U10=0,N($N10)>0),$N10+ROW()/1000000,"") | Y10: =IF(AND($T10=1,$U10=0,OR($I10<>"",N($N10)>0)),N($N10)+ROW()/1000000,"") | Z10: =IF(AND($T10=1,$U10=0,$I10="",N($N10)<=0,-N($N10)<=HORIZON),N($N10)+ROW()/1000000,"")
A11: Authority To Start Evidence | B11: System | C11: SYS-TP | E11: DMIC-SYS-TP-ATS-008 | F11: N. Bergstrom | G11: A. Mercer | H11: P6 - For Construction | K11: =IF($A11="","",IF($J11<>"",$J11,$S11)) | L11: =IF(OR($A11="",$E11=""),"",IF($J11<>"","Manual",IF($S11="","-","Auto"))) | M11: 46258 | N11: =IF($T11=0,"",IF($U11=1,IF($M11="","",$M11-$K11),IF($K11="","",TODAY()-$K11))) | O11: =IF(OR($A11="",$E11=""),"",IF($V11=1,S_INACT,IF(ISNA(MATCH($A11,TYP_TYPE,0)),S_TYPEKO,IF($U11=1,S_DONE,IF(AND($K11="",$R11=""),S_NOSCOPE,IF($K11="",S_NOTARGET,IF($N11>0,S_LATE,IF($I11<>"",S_WIP,IF(-$N11<=FEN_DOC,S_RISK,IF(-$N11<=HORIZON,S_COMING,S_NOTYET)))))))))) | P11: =IF(OR($A11="",$E11=""),"",IF($V11=1,"",IF(ISNA(MATCH($A11,TYP_TYPE,0)),"Type not in the library",IF($B11="","Scope not set",IF(AND($B11="System",$C11=""),"System not set",IF(AND($B11="Equipment",$D11=""),"Equipment not set",IF($F11="","Responsible not set",IF($K11="","No target date",IF(AND($B11="Equipment",$C11<>"",IFERROR(INDEX(EQP_SYS,MATCH($D11,EQP_NOM,0)),"")<>$C11),"Equipment not in that system",IF(AND($U11=1,$M11=""),"Approved with no approval date","")))))))))) | R11: =IF(OR($A11="",$B11=""),"",IF($B11="Equipment",IFERROR(INDEX(EQP_START,MATCH($D11,EQP_NOM,0)),""),IF($B11="System",IFERROR(INDEX(SYS_EARLIEST,MATCH($C11,SYS_ID,0)),""),IF($B11="All",CTR_EARLIEST,"")))) | S11: =IF(OR($A11="",$E11=""),"",IFERROR(IF(INDEX(TYP_ANCHOR,MATCH($A11,TYP_TYPE,0))="Commissioning Start",IF($R11="","",$R11-INDEX(TYP_LEAD,MATCH($A11,TYP_TYPE,0))),IF(INDEX(MS_PLAN,MATCH(INDEX(TYP_ANCHOR,MATCH($A11,TYP_TYPE,0)),MS_NOM,0))="","",INDEX(MS_PLAN,MATCH(INDEX(TYP_ANCHOR,MATCH($A11,TYP_TYPE,0)),MS_NOM,0))-INDEX(TYP_LEAD,MATCH($A11,TYP_TYPE,0)))),"")) | T11: =IF(OR($A11="",$E11=""),0,IF($V11=1,0,1)) | U11: =IF($T11=0,0,IF($M11<>"",1,IF(IFERROR(INDEX(WF_CLASS,MATCH($H11,WF_CODE,0)),"")="Done",1,0))) | V11: =IF(OR($A11="",$E11=""),0,IF(IFERROR(INDEX(WF_CLASS,MATCH($H11,WF_CODE,0)),"")="Inactive",1,0)) | W11: =IF($A11="","",IFERROR(INDEX(TYP_PHASE,MATCH($A11,TYP_TYPE,0)),"-")) | X11: =IF(AND($T11=1,$U11=0,N($N11)>0),$N11+ROW()/1000000,"") | Y11: =IF(AND($T11=1,$U11=0,OR($I11<>"",N($N11)>0)),N($N11)+ROW()/1000000,"") | Z11: =IF(AND($T11=1,$U11=0,$I11="",N($N11)<=0,-N($N11)<=HORIZON),N($N11)+ROW()/1000000,"")
A12: Surveillance Programme | B12: System | C12: SYS-SG | E12: DMIC-SYS-SG-SVP-009 | F12: M. Haddad | G12: S. Okonkwo | H12: S4A - Approved | K12: =IF($A12="","",IF($J12<>"",$J12,$S12)) | L12: =IF(OR($A12="",$E12=""),"",IF($J12<>"","Manual",IF($S12="","-","Auto"))) | M12: 46143 | N12: =IF($T12=0,"",IF($U12=1,IF($M12="","",$M12-$K12),IF($K12="","",TODAY()-$K12))) | O12: =IF(OR($A12="",$E12=""),"",IF($V12=1,S_INACT,IF(ISNA(MATCH($A12,TYP_TYPE,0)),S_TYPEKO,IF($U12=1,S_DONE,IF(AND($K12="",$R12=""),S_NOSCOPE,IF($K12="",S_NOTARGET,IF($N12>0,S_LATE,IF($I12<>"",S_WIP,IF(-$N12<=FEN_DOC,S_RISK,IF(-$N12<=HORIZON,S_COMING,S_NOTYET)))))))))) | P12: =IF(OR($A12="",$E12=""),"",IF($V12=1,"",IF(ISNA(MATCH($A12,TYP_TYPE,0)),"Type not in the library",IF($B12="","Scope not set",IF(AND($B12="System",$C12=""),"System not set",IF(AND($B12="Equipment",$D12=""),"Equipment not set",IF($F12="","Responsible not set",IF($K12="","No target date",IF(AND($B12="Equipment",$C12<>"",IFERROR(INDEX(EQP_SYS,MATCH($D12,EQP_NOM,0)),"")<>$C12),"Equipment not in that system",IF(AND($U12=1,$M12=""),"Approved with no approval date","")))))))))) | R12: =IF(OR($A12="",$B12=""),"",IF($B12="Equipment",IFERROR(INDEX(EQP_START,MATCH($D12,EQP_NOM,0)),""),IF($B12="System",IFERROR(INDEX(SYS_EARLIEST,MATCH($C12,SYS_ID,0)),""),IF($B12="All",CTR_EARLIEST,"")))) | S12: =IF(OR($A12="",$E12=""),"",IFERROR(IF(INDEX(TYP_ANCHOR,MATCH($A12,TYP_TYPE,0))="Commissioning Start",IF($R12="","",$R12-INDEX(TYP_LEAD,MATCH($A12,TYP_TYPE,0))),IF(INDEX(MS_PLAN,MATCH(INDEX(TYP_ANCHOR,MATCH($A12,TYP_TYPE,0)),MS_NOM,0))="","",INDEX(MS_PLAN,MATCH(INDEX(TYP_ANCHOR,MATCH($A12,TYP_TYPE,0)),MS_NOM,0))-INDEX(TYP_LEAD,MATCH($A12,TYP_TYPE,0)))),"")) | T12: =IF(OR($A12="",$E12=""),0,IF($V12=1,0,1)) | U12: =IF($T12=0,0,IF($M12<>"",1,IF(IFERROR(INDEX(WF_CLASS,MATCH($H12,WF_CODE,0)),"")="Done",1,0))) | V12: =IF(OR($A12="",$E12=""),0,IF(IFERROR(INDEX(WF_CLASS,MATCH($H12,WF_CODE,0)),"")="Inactive",1,0)) | W12: =IF($A12="","",IFERROR(INDEX(TYP_PHASE,MATCH($A12,TYP_TYPE,0)),"-")) | X12: =IF(AND($T12=1,$U12=0,N($N12)>0),$N12+ROW()/1000000,"") | Y12: =IF(AND($T12=1,$U12=0,OR($I12<>"",N($N12)>0)),N($N12)+ROW()/1000000,"") | Z12: =IF(AND($T12=1,$U12=0,$I12="",N($N12)<=0,-N($N12)<=HORIZON),N($N12)+ROW()/1000000,"")
A13: Safe System Of Work | B13: System | C13: SYS-SG | E13: DMIC-SYS-SG-SSW-010 | F13: C. Vasquez | G13: L. Fontaine | H13: S3 - For Review | I13: 46174 | K13: =IF($A13="","",IF($J13<>"",$J13,$S13)) | L13: =IF(OR($A13="",$E13=""),"",IF($J13<>"","Manual",IF($S13="","-","Auto"))) | N13: =IF($T13=0,"",IF($U13=1,IF($M13="","",$M13-$K13),IF($K13="","",TODAY()-$K13))) | O13: =IF(OR($A13="",$E13=""),"",IF($V13=1,S_INACT,IF(ISNA(MATCH($A13,TYP_TYPE,0)),S_TYPEKO,IF($U13=1,S_DONE,IF(AND($K13="",$R13=""),S_NOSCOPE,IF($K13="",S_NOTARGET,IF($N13>0,S_LATE,IF($I13<>"",S_WIP,IF(-$N13<=FEN_DOC,S_RISK,IF(-$N13<=HORIZON,S_COMING,S_NOTYET)))))))))) | P13: =IF(OR($A13="",$E13=""),"",IF($V13=1,"",IF(ISNA(MATCH($A13,TYP_TYPE,0)),"Type not in the library",IF($B13="","Scope not set",IF(AND($B13="System",$C13=""),"System not set",IF(AND($B13="Equipment",$D13=""),"Equipment not set",IF($F13="","Responsible not set",IF($K13="","No target date",IF(AND($B13="Equipment",$C13<>"",IFERROR(INDEX(EQP_SYS,MATCH($D13,EQP_NOM,0)),"")<>$C13),"Equipment not in that system",IF(AND($U13=1,$M13=""),"Approved with no approval date","")))))))))) | R13: =IF(OR($A13="",$B13=""),"",IF($B13="Equipment",IFERROR(INDEX(EQP_START,MATCH($D13,EQP_NOM,0)),""),IF($B13="System",IFERROR(INDEX(SYS_EARLIEST,MATCH($C13,SYS_ID,0)),""),IF($B13="All",CTR_EARLIEST,"")))) | S13: =IF(OR($A13="",$E13=""),"",IFERROR(IF(INDEX(TYP_ANCHOR,MATCH($A13,TYP_TYPE,0))="Commissioning Start",IF($R13="","",$R13-INDEX(TYP_LEAD,MATCH($A13,TYP_TYPE,0))),IF(INDEX(MS_PLAN,MATCH(INDEX(TYP_ANCHOR,MATCH($A13,TYP_TYPE,0)),MS_NOM,0))="","",INDEX(MS_PLAN,MATCH(INDEX(TYP_ANCHOR,MATCH($A13,TYP_TYPE,0)),MS_NOM,0))-INDEX(TYP_LEAD,MATCH($A13,TYP_TYPE,0)))),"")) | T13: =IF(OR($A13="",$E13=""),0,IF($V13=1,0,1)) | U13: =IF($T13=0,0,IF($M13<>"",1,IF(IFERROR(INDEX(WF_CLASS,MATCH($H13,WF_CODE,0)),"")="Done",1,0))) | V13: =IF(OR($A13="",$E13=""),0,IF(IFERROR(INDEX(WF_CLASS,MATCH($H13,WF_CODE,0)),"")="Inactive",1,0)) | W13: =IF($A13="","",IFERROR(INDEX(TYP_PHASE,MATCH($A13,TYP_TYPE,0)),"-")) | X13: =IF(AND($T13=1,$U13=0,N($N13)>0),$N13+ROW()/1000000,"") | Y13: =IF(AND($T13=1,$U13=0,OR($I13<>"",N($N13)>0)),N($N13)+ROW()/1000000,"") | Z13: =IF(AND($T13=1,$U13=0,$I13="",N($N13)<=0,-N($N13)<=HORIZON),N($N13)+ROW()/1000000,"")
A14: Risk Assessment And Method Statement | B14: System | C14: SYS-SG | E14: DMIC-SYS-SG-RAM-011 | F14: H. Lindqvist | G14: D. Petrov | H14: P6 - For Construction | K14: =IF($A14="","",IF($J14<>"",$J14,$S14)) | L14: =IF(OR($A14="",$E14=""),"",IF($J14<>"","Manual",IF($S14="","-","Auto"))) | M14: 46224 | N14: =IF($T14=0,"",IF($U14=1,IF($M14="","",$M14-$K14),IF($K14="","",TODAY()-$K14))) | O14: =IF(OR($A14="",$E14=""),"",IF($V14=1,S_INACT,IF(ISNA(MATCH($A14,TYP_TYPE,0)),S_TYPEKO,IF($U14=1,S_DONE,IF(AND($K14="",$R14=""),S_NOSCOPE,IF($K14="",S_NOTARGET,IF($N14>0,S_LATE,IF($I14<>"",S_WIP,IF(-$N14<=FEN_DOC,S_RISK,IF(-$N14<=HORIZON,S_COMING,S_NOTYET)))))))))) | P14: =IF(OR($A14="",$E14=""),"",IF($V14=1,"",IF(ISNA(MATCH($A14,TYP_TYPE,0)),"Type not in the library",IF($B14="","Scope not set",IF(AND($B14="System",$C14=""),"System not set",IF(AND($B14="Equipment",$D14=""),"Equipment not set",IF($F14="","Responsible not set",IF($K14="","No target date",IF(AND($B14="Equipment",$C14<>"",IFERROR(INDEX(EQP_SYS,MATCH($D14,EQP_NOM,0)),"")<>$C14),"Equipment not in that system",IF(AND($U14=1,$M14=""),"Approved with no approval date","")))))))))) | R14: =IF(OR($A14="",$B14=""),"",IF($B14="Equipment",IFERROR(INDEX(EQP_START,MATCH($D14,EQP_NOM,0)),""),IF($B14="System",IFERROR(INDEX(SYS_EARLIEST,MATCH($C14,SYS_ID,0)),""),IF($B14="All",CTR_EARLIEST,"")))) | S14: =IF(OR($A14="",$E14=""),"",IFERROR(IF(INDEX(TYP_ANCHOR,MATCH($A14,TYP_TYPE,0))="Commissioning Start",IF($R14="","",$R14-INDEX(TYP_LEAD,MATCH($A14,TYP_TYPE,0))),IF(INDEX(MS_PLAN,MATCH(INDEX(TYP_ANCHOR,MATCH($A14,TYP_TYPE,0)),MS_NOM,0))="","",INDEX(MS_PLAN,MATCH(INDEX(TYP_ANCHOR,MATCH($A14,TYP_TYPE,0)),MS_NOM,0))-INDEX(TYP_LEAD,MATCH($A14,TYP_TYPE,0)))),"")) | T14: =IF(OR($A14="",$E14=""),0,IF($V14=1,0,1)) | U14: =IF($T14=0,0,IF($M14<>"",1,IF(IFERROR(INDEX(WF_CLASS,MATCH($H14,WF_CODE,0)),"")="Done",1,0))) | V14: =IF(OR($A14="",$E14=""),0,IF(IFERROR(INDEX(WF_CLASS,MATCH($H14,WF_CODE,0)),"")="Inactive",1,0)) | W14: =IF($A14="","",IFERROR(INDEX(TYP_PHASE,MATCH($A14,TYP_TYPE,0)),"-")) | X14: =IF(AND($T14=1,$U14=0,N($N14)>0),$N14+ROW()/1000000,"") | Y14: =IF(AND($T14=1,$U14=0,OR($I14<>"",N($N14)>0)),N($N14)+ROW()/1000000,"") | Z14: =IF(AND($T14=1,$U14=0,$I14="",N($N14)<=0,-N($N14)<=HORIZON),N($N14)+ROW()/1000000,"")
A15: System Commissioning Programme | B15: System | C15: SYS-SG | E15: DMIC-SYS-SG-SCP-012 | F15: A. Mercer | G15: J. Whitfield | H15: S4A - Approved | K15: =IF($A15="","",IF($J15<>"",$J15,$S15)) | L15: =IF(OR($A15="",$E15=""),"",IF($J15<>"","Manual",IF($S15="","-","Auto"))) | M15: 46225 | N15: =IF($T15=0,"",IF($U15=1,IF($M15="","",$M15-$K15),IF($K15="","",TODAY()-$K15))) | O15: =IF(OR($A15="",$E15=""),"",IF($V15=1,S_INACT,IF(ISNA(MATCH($A15,TYP_TYPE,0)),S_TYPEKO,IF($U15=1,S_DONE,IF(AND($K15="",$R15=""),S_NOSCOPE,IF($K15="",S_NOTARGET,IF($N15>0,S_LATE,IF($I15<>"",S_WIP,IF(-$N15<=FEN_DOC,S_RISK,IF(-$N15<=HORIZON,S_COMING,S_NOTYET)))))))))) | P15: =IF(OR($A15="",$E15=""),"",IF($V15=1,"",IF(ISNA(MATCH($A15,TYP_TYPE,0)),"Type not in the library",IF($B15="","Scope not set",IF(AND($B15="System",$C15=""),"System not set",IF(AND($B15="Equipment",$D15=""),"Equipment not set",IF($F15="","Responsible not set",IF($K15="","No target date",IF(AND($B15="Equipment",$C15<>"",IFERROR(INDEX(EQP_SYS,MATCH($D15,EQP_NOM,0)),"")<>$C15),"Equipment not in that system",IF(AND($U15=1,$M15=""),"Approved with no approval date","")))))))))) | R15: =IF(OR($A15="",$B15=""),"",IF($B15="Equipment",IFERROR(INDEX(EQP_START,MATCH($D15,EQP_NOM,0)),""),IF($B15="System",IFERROR(INDEX(SYS_EARLIEST,MATCH($C15,SYS_ID,0)),""),IF($B15="All",CTR_EARLIEST,"")))) | S15: =IF(OR($A15="",$E15=""),"",IFERROR(IF(INDEX(TYP_ANCHOR,MATCH($A15,TYP_TYPE,0))="Commissioning Start",IF($R15="","",$R15-INDEX(TYP_LEAD,MATCH($A15,TYP_TYPE,0))),IF(INDEX(MS_PLAN,MATCH(INDEX(TYP_ANCHOR,MATCH($A15,TYP_TYPE,0)),MS_NOM,0))="","",INDEX(MS_PLAN,MATCH(INDEX(TYP_ANCHOR,MATCH($A15,TYP_TYPE,0)),MS_NOM,0))-INDEX(TYP_LEAD,MATCH($A15,TYP_TYPE,0)))),"")) | T15: =IF(OR($A15="",$E15=""),0,IF($V15=1,0,1)) | U15: =IF($T15=0,0,IF($M15<>"",1,IF(IFERROR(INDEX(WF_CLASS,MATCH($H15,WF_CODE,0)),"")="Done",1,0))) | V15: =IF(OR($A15="",$E15=""),0,IF(IFERROR(INDEX(WF_CLASS,MATCH($H15,WF_CODE,0)),"")="Inactive",1,0)) | W15: =IF($A15="","",IFERROR(INDEX(TYP_PHASE,MATCH($A15,TYP_TYPE,0)),"-")) | X15: =IF(AND($T15=1,$U15=0,N($N15)>0),$N15+ROW()/1000000,"") | Y15: =IF(AND($T15=1,$U15=0,OR($I15<>"",N($N15)>0)),N($N15)+ROW()/1000000,"") | Z15: =IF(AND($T15=1,$U15=0,$I15="",N($N15)<=0,-N($N15)<=HORIZON),N($N15)+ROW()/1000000,"")
A16: Authority To Start Evidence | B16: System | C16: SYS-SG | E16: DMIC-SYS-SG-ATS-013 | F16: S. Okonkwo | G16: P. Nakamura | H16: P1 - For Implementation | K16: =IF($A16="","",IF($J16<>"",$J16,$S16)) | L16: =IF(OR($A16="",$E16=""),"",IF($J16<>"","Manual",IF($S16="","-","Auto"))) | M16: 46253 | N16: =IF($T16=0,"",IF($U16=1,IF($M16="","",$M16-$K16),IF($K16="","",TODAY()-$K16))) | O16: =IF(OR($A16="",$E16=""),"",IF($V16=1,S_INACT,IF(ISNA(MATCH($A16,TYP_TYPE,0)),S_TYPEKO,IF($U16=1,S_DONE,IF(AND($K16="",$R16=""),S_NOSCOPE,IF($K16="",S_NOTARGET,IF($N16>0,S_LATE,IF($I16<>"",S_WIP,IF(-$N16<=FEN_DOC,S_RISK,IF(-$N16<=HORIZON,S_COMING,S_NOTYET)))))))))) | P16: =IF(OR($A16="",$E16=""),"",IF($V16=1,"",IF(ISNA(MATCH($A16,TYP_TYPE,0)),"Type not in the library",IF($B16="","Scope not set",IF(AND($B16="System",$C16=""),"System not set",IF(AND($B16="Equipment",$D16=""),"Equipment not set",IF($F16="","Responsible not set",IF($K16="","No target date",IF(AND($B16="Equipment",$C16<>"",IFERROR(INDEX(EQP_SYS,MATCH($D16,EQP_NOM,0)),"")<>$C16),"Equipment not in that system",IF(AND($U16=1,$M16=""),"Approved with no approval date","")))))))))) | R16: =IF(OR($A16="",$B16=""),"",IF($B16="Equipment",IFERROR(INDEX(EQP_START,MATCH($D16,EQP_NOM,0)),""),IF($B16="System",IFERROR(INDEX(SYS_EARLIEST,MATCH($C16,SYS_ID,0)),""),IF($B16="All",CTR_EARLIEST,"")))) | S16: =IF(OR($A16="",$E16=""),"",IFERROR(IF(INDEX(TYP_ANCHOR,MATCH($A16,TYP_TYPE,0))="Commissioning Start",IF($R16="","",$R16-INDEX(TYP_LEAD,MATCH($A16,TYP_TYPE,0))),IF(INDEX(MS_PLAN,MATCH(INDEX(TYP_ANCHOR,MATCH($A16,TYP_TYPE,0)),MS_NOM,0))="","",INDEX(MS_PLAN,MATCH(INDEX(TYP_ANCHOR,MATCH($A16,TYP_TYPE,0)),MS_NOM,0))-INDEX(TYP_LEAD,MATCH($A16,TYP_TYPE,0)))),"")) | T16: =IF(OR($A16="",$E16=""),0,IF($V16=1,0,1)) | U16: =IF($T16=0,0,IF($M16<>"",1,IF(IFERROR(INDEX(WF_CLASS,MATCH($H16,WF_CODE,0)),"")="Done",1,0))) | V16: =IF(OR($A16="",$E16=""),0,IF(IFERROR(INDEX(WF_CLASS,MATCH($H16,WF_CODE,0)),"")="Inactive",1,0)) | W16: =IF($A16="","",IFERROR(INDEX(TYP_PHASE,MATCH($A16,TYP_TYPE,0)),"-")) | X16: =IF(AND($T16=1,$U16=0,N($N16)>0),$N16+ROW()/1000000,"") | Y16: =IF(AND($T16=1,$U16=0,OR($I16<>"",N($N16)>0)),N($N16)+ROW()/1000000,"") | Z16: =IF(AND($T16=1,$U16=0,$I16="",N($N16)<=0,-N($N16)<=HORIZON),N($N16)+ROW()/1000000,"")
A17: Surveillance Programme | B17: System | C17: SYS-TV | E17: DMIC-SYS-TV-SVP-014 | F17: L. Fontaine | G17: K. Rasmussen | H17: W1 - Draft | I17: 46170 | K17: =IF($A17="","",IF($J17<>"",$J17,$S17)) | L17: =IF(OR($A17="",$E17=""),"",IF($J17<>"","Manual",IF($S17="","-","Auto"))) | N17: =IF($T17=0,"",IF($U17=1,IF($M17="","",$M17-$K17),IF($K17="","",TODAY()-$K17))) | O17: =IF(OR($A17="",$E17=""),"",IF($V17=1,S_INACT,IF(ISNA(MATCH($A17,TYP_TYPE,0)),S_TYPEKO,IF($U17=1,S_DONE,IF(AND($K17="",$R17=""),S_NOSCOPE,IF($K17="",S_NOTARGET,IF($N17>0,S_LATE,IF($I17<>"",S_WIP,IF(-$N17<=FEN_DOC,S_RISK,IF(-$N17<=HORIZON,S_COMING,S_NOTYET)))))))))) | P17: =IF(OR($A17="",$E17=""),"",IF($V17=1,"",IF(ISNA(MATCH($A17,TYP_TYPE,0)),"Type not in the library",IF($B17="","Scope not set",IF(AND($B17="System",$C17=""),"System not set",IF(AND($B17="Equipment",$D17=""),"Equipment not set",IF($F17="","Responsible not set",IF($K17="","No target date",IF(AND($B17="Equipment",$C17<>"",IFERROR(INDEX(EQP_SYS,MATCH($D17,EQP_NOM,0)),"")<>$C17),"Equipment not in that system",IF(AND($U17=1,$M17=""),"Approved with no approval date","")))))))))) | R17: =IF(OR($A17="",$B17=""),"",IF($B17="Equipment",IFERROR(INDEX(EQP_START,MATCH($D17,EQP_NOM,0)),""),IF($B17="System",IFERROR(INDEX(SYS_EARLIEST,MATCH($C17,SYS_ID,0)),""),IF($B17="All",CTR_EARLIEST,"")))) | S17: =IF(OR($A17="",$E17=""),"",IFERROR(IF(INDEX(TYP_ANCHOR,MATCH($A17,TYP_TYPE,0))="Commissioning Start",IF($R17="","",$R17-INDEX(TYP_LEAD,MATCH($A17,TYP_TYPE,0))),IF(INDEX(MS_PLAN,MATCH(INDEX(TYP_ANCHOR,MATCH($A17,TYP_TYPE,0)),MS_NOM,0))="","",INDEX(MS_PLAN,MATCH(INDEX(TYP_ANCHOR,MATCH($A17,TYP_TYPE,0)),MS_NOM,0))-INDEX(TYP_LEAD,MATCH($A17,TYP_TYPE,0)))),"")) | T17: =IF(OR($A17="",$E17=""),0,IF($V17=1,0,1)) | U17: =IF($T17=0,0,IF($M17<>"",1,IF(IFERROR(INDEX(WF_CLASS,MATCH($H17,WF_CODE,0)),"")="Done",1,0))) | V17: =IF(OR($A17="",$E17=""),0,IF(IFERROR(INDEX(WF_CLASS,MATCH($H17,WF_CODE,0)),"")="Inactive",1,0)) | W17: =IF($A17="","",IFERROR(INDEX(TYP_PHASE,MATCH($A17,TYP_TYPE,0)),"-")) | X17: =IF(AND($T17=1,$U17=0,N($N17)>0),$N17+ROW()/1000000,"") | Y17: =IF(AND($T17=1,$U17=0,OR($I17<>"",N($N17)>0)),N($N17)+ROW()/1000000,"") | Z17: =IF(AND($T17=1,$U17=0,$I17="",N($N17)<=0,-N($N17)<=HORIZON),N($N17)+ROW()/1000000,"")
A18: Safe System Of Work | B18: System | C18: SYS-TV | E18: DMIC-SYS-TV-SSW-015 | F18: D. Petrov | G18: R. Bellamy | H18: S4A - Approved | K18: =IF($A18="","",IF($J18<>"",$J18,$S18)) | L18: =IF(OR($A18="",$E18=""),"",IF($J18<>"","Manual",IF($S18="","-","Auto"))) | M18: 46258 | N18: =IF($T18=0,"",IF($U18=1,IF($M18="","",$M18-$K18),IF($K18="","",TODAY()-$K18))) | O18: =IF(OR($A18="",$E18=""),"",IF($V18=1,S_INACT,IF(ISNA(MATCH($A18,TYP_TYPE,0)),S_TYPEKO,IF($U18=1,S_DONE,IF(AND($K18="",$R18=""),S_NOSCOPE,IF($K18="",S_NOTARGET,IF($N18>0,S_LATE,IF($I18<>"",S_WIP,IF(-$N18<=FEN_DOC,S_RISK,IF(-$N18<=HORIZON,S_COMING,S_NOTYET)))))))))) | P18: =IF(OR($A18="",$E18=""),"",IF($V18=1,"",IF(ISNA(MATCH($A18,TYP_TYPE,0)),"Type not in the library",IF($B18="","Scope not set",IF(AND($B18="System",$C18=""),"System not set",IF(AND($B18="Equipment",$D18=""),"Equipment not set",IF($F18="","Responsible not set",IF($K18="","No target date",IF(AND($B18="Equipment",$C18<>"",IFERROR(INDEX(EQP_SYS,MATCH($D18,EQP_NOM,0)),"")<>$C18),"Equipment not in that system",IF(AND($U18=1,$M18=""),"Approved with no approval date","")))))))))) | R18: =IF(OR($A18="",$B18=""),"",IF($B18="Equipment",IFERROR(INDEX(EQP_START,MATCH($D18,EQP_NOM,0)),""),IF($B18="System",IFERROR(INDEX(SYS_EARLIEST,MATCH($C18,SYS_ID,0)),""),IF($B18="All",CTR_EARLIEST,"")))) | S18: =IF(OR($A18="",$E18=""),"",IFERROR(IF(INDEX(TYP_ANCHOR,MATCH($A18,TYP_TYPE,0))="Commissioning Start",IF($R18="","",$R18-INDEX(TYP_LEAD,MATCH($A18,TYP_TYPE,0))),IF(INDEX(MS_PLAN,MATCH(INDEX(TYP_ANCHOR,MATCH($A18,TYP_TYPE,0)),MS_NOM,0))="","",INDEX(MS_PLAN,MATCH(INDEX(TYP_ANCHOR,MATCH($A18,TYP_TYPE,0)),MS_NOM,0))-INDEX(TYP_LEAD,MATCH($A18,TYP_TYPE,0)))),"")) | T18: =IF(OR($A18="",$E18=""),0,IF($V18=1,0,1)) | U18: =IF($T18=0,0,IF($M18<>"",1,IF(IFERROR(INDEX(WF_CLASS,MATCH($H18,WF_CODE,0)),"")="Done",1,0))) | V18: =IF(OR($A18="",$E18=""),0,IF(IFERROR(INDEX(WF_CLASS,MATCH($H18,WF_CODE,0)),"")="Inactive",1,0)) | W18: =IF($A18="","",IFERROR(INDEX(TYP_PHASE,MATCH($A18,TYP_TYPE,0)),"-")) | X18: =IF(AND($T18=1,$U18=0,N($N18)>0),$N18+ROW()/1000000,"") | Y18: =IF(AND($T18=1,$U18=0,OR($I18<>"",N($N18)>0)),N($N18)+ROW()/1000000,"") | Z18: =IF(AND($T18=1,$U18=0,$I18="",N($N18)<=0,-N($N18)<=HORIZON),N($N18)+ROW()/1000000,"")
A19: Risk Assessment And Method Statement | B19: System | C19: SYS-TV | E19: DMIC-SYS-TV-RAM-016 | F19: J. Whitfield | G19: N. Bergstrom | H19: S4 - For Internal Approval | I19: 46258 | K19: =IF($A19="","",IF($J19<>"",$J19,$S19)) | L19: =IF(OR($A19="",$E19=""),"",IF($J19<>"","Manual",IF($S19="","-","Auto"))) | N19: =IF($T19=0,"",IF($U19=1,IF($M19="","",$M19-$K19),IF($K19="","",TODAY()-$K19))) | O19: =IF(OR($A19="",$E19=""),"",IF($V19=1,S_INACT,IF(ISNA(MATCH($A19,TYP_TYPE,0)),S_TYPEKO,IF($U19=1,S_DONE,IF(AND($K19="",$R19=""),S_NOSCOPE,IF($K19="",S_NOTARGET,IF($N19>0,S_LATE,IF($I19<>"",S_WIP,IF(-$N19<=FEN_DOC,S_RISK,IF(-$N19<=HORIZON,S_COMING,S_NOTYET)))))))))) | P19: =IF(OR($A19="",$E19=""),"",IF($V19=1,"",IF(ISNA(MATCH($A19,TYP_TYPE,0)),"Type not in the library",IF($B19="","Scope not set",IF(AND($B19="System",$C19=""),"System not set",IF(AND($B19="Equipment",$D19=""),"Equipment not set",IF($F19="","Responsible not set",IF($K19="","No target date",IF(AND($B19="Equipment",$C19<>"",IFERROR(INDEX(EQP_SYS,MATCH($D19,EQP_NOM,0)),"")<>$C19),"Equipment not in that system",IF(AND($U19=1,$M19=""),"Approved with no approval date","")))))))))) | R19: =IF(OR($A19="",$B19=""),"",IF($B19="Equipment",IFERROR(INDEX(EQP_START,MATCH($D19,EQP_NOM,0)),""),IF($B19="System",IFERROR(INDEX(SYS_EARLIEST,MATCH($C19,SYS_ID,0)),""),IF($B19="All",CTR_EARLIEST,"")))) | S19: =IF(OR($A19="",$E19=""),"",IFERROR(IF(INDEX(TYP_ANCHOR,MATCH($A19,TYP_TYPE,0))="Commissioning Start",IF($R19="","",$R19-INDEX(TYP_LEAD,MATCH($A19,TYP_TYPE,0))),IF(INDEX(MS_PLAN,MATCH(INDEX(TYP_ANCHOR,MATCH($A19,TYP_TYPE,0)),MS_NOM,0))="","",INDEX(MS_PLAN,MATCH(INDEX(TYP_ANCHOR,MATCH($A19,TYP_TYPE,0)),MS_NOM,0))-INDEX(TYP_LEAD,MATCH($A19,TYP_TYPE,0)))),"")) | T19: =IF(OR($A19="",$E19=""),0,IF($V19=1,0,1)) | U19: =IF($T19=0,0,IF($M19<>"",1,IF(IFERROR(INDEX(WF_CLASS,MATCH($H19,WF_CODE,0)),"")="Done",1,0))) | V19: =IF(OR($A19="",$E19=""),0,IF(IFERROR(INDEX(WF_CLASS,MATCH($H19,WF_CODE,0)),"")="Inactive",1,0)) | W19: =IF($A19="","",IFERROR(INDEX(TYP_PHASE,MATCH($A19,TYP_TYPE,0)),"-")) | X19: =IF(AND($T19=1,$U19=0,N($N19)>0),$N19+ROW()/1000000,"") | Y19: =IF(AND($T19=1,$U19=0,OR($I19<>"",N($N19)>0)),N($N19)+ROW()/1000000,"") | Z19: =IF(AND($T19=1,$U19=0,$I19="",N($N19)<=0,-N($N19)<=HORIZON),N($N19)+ROW()/1000000,"")
A20: System Commissioning Programme | B20: System | C20: SYS-TV | E20: DMIC-SYS-TV-SCP-017 | F20: P. Nakamura | G20: M. Haddad | H20: S6 - For Acceptance | I20: 46257 | K20: =IF($A20="","",IF($J20<>"",$J20,$S20)) | L20: =IF(OR($A20="",$E20=""),"",IF($J20<>"","Manual",IF($S20="","-","Auto"))) | N20: =IF($T20=0,"",IF($U20=1,IF($M20="","",$M20-$K20),IF($K20="","",TODAY()-$K20))) | O20: =IF(OR($A20="",$E20=""),"",IF($V20=1,S_INACT,IF(ISNA(MATCH($A20,TYP_TYPE,0)),S_TYPEKO,IF($U20=1,S_DONE,IF(AND($K20="",$R20=""),S_NOSCOPE,IF($K20="",S_NOTARGET,IF($N20>0,S_LATE,IF($I20<>"",S_WIP,IF(-$N20<=FEN_DOC,S_RISK,IF(-$N20<=HORIZON,S_COMING,S_NOTYET)))))))))) | P20: =IF(OR($A20="",$E20=""),"",IF($V20=1,"",IF(ISNA(MATCH($A20,TYP_TYPE,0)),"Type not in the library",IF($B20="","Scope not set",IF(AND($B20="System",$C20=""),"System not set",IF(AND($B20="Equipment",$D20=""),"Equipment not set",IF($F20="","Responsible not set",IF($K20="","No target date",IF(AND($B20="Equipment",$C20<>"",IFERROR(INDEX(EQP_SYS,MATCH($D20,EQP_NOM,0)),"")<>$C20),"Equipment not in that system",IF(AND($U20=1,$M20=""),"Approved with no approval date","")))))))))) | R20: =IF(OR($A20="",$B20=""),"",IF($B20="Equipment",IFERROR(INDEX(EQP_START,MATCH($D20,EQP_NOM,0)),""),IF($B20="System",IFERROR(INDEX(SYS_EARLIEST,MATCH($C20,SYS_ID,0)),""),IF($B20="All",CTR_EARLIEST,"")))) | S20: =IF(OR($A20="",$E20=""),"",IFERROR(IF(INDEX(TYP_ANCHOR,MATCH($A20,TYP_TYPE,0))="Commissioning Start",IF($R20="","",$R20-INDEX(TYP_LEAD,MATCH($A20,TYP_TYPE,0))),IF(INDEX(MS_PLAN,MATCH(INDEX(TYP_ANCHOR,MATCH($A20,TYP_TYPE,0)),MS_NOM,0))="","",INDEX(MS_PLAN,MATCH(INDEX(TYP_ANCHOR,MATCH($A20,TYP_TYPE,0)),MS_NOM,0))-INDEX(TYP_LEAD,MATCH($A20,TYP_TYPE,0)))),"")) | T20: =IF(OR($A20="",$E20=""),0,IF($V20=1,0,1)) | U20: =IF($T20=0,0,IF($M20<>"",1,IF(IFERROR(INDEX(WF_CLASS,MATCH($H20,WF_CODE,0)),"")="Done",1,0))) | V20: =IF(OR($A20="",$E20=""),0,IF(IFERROR(INDEX(WF_CLASS,MATCH($H20,WF_CODE,0)),"")="Inactive",1,0)) | W20: =IF($A20="","",IFERROR(INDEX(TYP_PHASE,MATCH($A20,TYP_TYPE,0)),"-")) | X20: =IF(AND($T20=1,$U20=0,N($N20)>0),$N20+ROW()/1000000,"") | Y20: =IF(AND($T20=1,$U20=0,OR($I20<>"",N($N20)>0)),N($N20)+ROW()/1000000,"") | Z20: =IF(AND($T20=1,$U20=0,$I20="",N($N20)<=0,-N($N20)<=HORIZON),N($N20)+ROW()/1000000,"")
A21: Authority To Start Evidence | B21: System | C21: SYS-TV | E21: DMIC-SYS-TV-ATS-018 | F21: K. Rasmussen | G21: C. Vasquez | H21: S4A - Approved | K21: =IF($A21="","",IF($J21<>"",$J21,$S21)) | L21: =IF(OR($A21="",$E21=""),"",IF($J21<>"","Manual",IF($S21="","-","Auto"))) | M21: 46255 | N21: =IF($T21=0,"",IF($U21=1,IF($M21="","",$M21-$K21),IF($K21="","",TODAY()-$K21))) | O21: =IF(OR($A21="",$E21=""),"",IF($V21=1,S_INACT,IF(ISNA(MATCH($A21,TYP_TYPE,0)),S_TYPEKO,IF($U21=1,S_DONE,IF(AND($K21="",$R21=""),S_NOSCOPE,IF($K21="",S_NOTARGET,IF($N21>0,S_LATE,IF($I21<>"",S_WIP,IF(-$N21<=FEN_DOC,S_RISK,IF(-$N21<=HORIZON,S_COMING,S_NOTYET)))))))))) | P21: =IF(OR($A21="",$E21=""),"",IF($V21=1,"",IF(ISNA(MATCH($A21,TYP_TYPE,0)),"Type not in the library",IF($B21="","Scope not set",IF(AND($B21="System",$C21=""),"System not set",IF(AND($B21="Equipment",$D21=""),"Equipment not set",IF($F21="","Responsible not set",IF($K21="","No target date",IF(AND($B21="Equipment",$C21<>"",IFERROR(INDEX(EQP_SYS,MATCH($D21,EQP_NOM,0)),"")<>$C21),"Equipment not in that system",IF(AND($U21=1,$M21=""),"Approved with no approval date","")))))))))) | R21: =IF(OR($A21="",$B21=""),"",IF($B21="Equipment",IFERROR(INDEX(EQP_START,MATCH($D21,EQP_NOM,0)),""),IF($B21="System",IFERROR(INDEX(SYS_EARLIEST,MATCH($C21,SYS_ID,0)),""),IF($B21="All",CTR_EARLIEST,"")))) | S21: =IF(OR($A21="",$E21=""),"",IFERROR(IF(INDEX(TYP_ANCHOR,MATCH($A21,TYP_TYPE,0))="Commissioning Start",IF($R21="","",$R21-INDEX(TYP_LEAD,MATCH($A21,TYP_TYPE,0))),IF(INDEX(MS_PLAN,MATCH(INDEX(TYP_ANCHOR,MATCH($A21,TYP_TYPE,0)),MS_NOM,0))="","",INDEX(MS_PLAN,MATCH(INDEX(TYP_ANCHOR,MATCH($A21,TYP_TYPE,0)),MS_NOM,0))-INDEX(TYP_LEAD,MATCH($A21,TYP_TYPE,0)))),"")) | T21: =IF(OR($A21="",$E21=""),0,IF($V21=1,0,1)) | U21: =IF($T21=0,0,IF($M21<>"",1,IF(IFERROR(INDEX(WF_CLASS,MATCH($H21,WF_CODE,0)),"")="Done",1,0))) | V21: =IF(OR($A21="",$E21=""),0,IF(IFERROR(INDEX(WF_CLASS,MATCH($H21,WF_CODE,0)),"")="Inactive",1,0)) | W21: =IF($A21="","",IFERROR(INDEX(TYP_PHASE,MATCH($A21,TYP_TYPE,0)),"-")) | X21: =IF(AND($T21=1,$U21=0,N($N21)>0),$N21+ROW()/1000000,"") | Y21: =IF(AND($T21=1,$U21=0,OR($I21<>"",N($N21)>0)),N($N21)+ROW()/1000000,"") | Z21: =IF(AND($T21=1,$U21=0,$I21="",N($N21)<=0,-N($N21)<=HORIZON),N($N21)+ROW()/1000000,"")
A22: Surveillance Programme | B22: System | C22: SYS-FA | E22: DMIC-SYS-FA-SVP-019 | F22: R. Bellamy | G22: H. Lindqvist | H22: W1 - Draft | I22: 46255 | K22: =IF($A22="","",IF($J22<>"",$J22,$S22)) | L22: =IF(OR($A22="",$E22=""),"",IF($J22<>"","Manual",IF($S22="","-","Auto"))) | N22: =IF($T22=0,"",IF($U22=1,IF($M22="","",$M22-$K22),IF($K22="","",TODAY()-$K22))) | O22: =IF(OR($A22="",$E22=""),"",IF($V22=1,S_INACT,IF(ISNA(MATCH($A22,TYP_TYPE,0)),S_TYPEKO,IF($U22=1,S_DONE,IF(AND($K22="",$R22=""),S_NOSCOPE,IF($K22="",S_NOTARGET,IF($N22>0,S_LATE,IF($I22<>"",S_WIP,IF(-$N22<=FEN_DOC,S_RISK,IF(-$N22<=HORIZON,S_COMING,S_NOTYET)))))))))) | P22: =IF(OR($A22="",$E22=""),"",IF($V22=1,"",IF(ISNA(MATCH($A22,TYP_TYPE,0)),"Type not in the library",IF($B22="","Scope not set",IF(AND($B22="System",$C22=""),"System not set",IF(AND($B22="Equipment",$D22=""),"Equipment not set",IF($F22="","Responsible not set",IF($K22="","No target date",IF(AND($B22="Equipment",$C22<>"",IFERROR(INDEX(EQP_SYS,MATCH($D22,EQP_NOM,0)),"")<>$C22),"Equipment not in that system",IF(AND($U22=1,$M22=""),"Approved with no approval date","")))))))))) | R22: =IF(OR($A22="",$B22=""),"",IF($B22="Equipment",IFERROR(INDEX(EQP_START,MATCH($D22,EQP_NOM,0)),""),IF($B22="System",IFERROR(INDEX(SYS_EARLIEST,MATCH($C22,SYS_ID,0)),""),IF($B22="All",CTR_EARLIEST,"")))) | S22: =IF(OR($A22="",$E22=""),"",IFERROR(IF(INDEX(TYP_ANCHOR,MATCH($A22,TYP_TYPE,0))="Commissioning Start",IF($R22="","",$R22-INDEX(TYP_LEAD,MATCH($A22,TYP_TYPE,0))),IF(INDEX(MS_PLAN,MATCH(INDEX(TYP_ANCHOR,MATCH($A22,TYP_TYPE,0)),MS_NOM,0))="","",INDEX(MS_PLAN,MATCH(INDEX(TYP_ANCHOR,MATCH($A22,TYP_TYPE,0)),MS_NOM,0))-INDEX(TYP_LEAD,MATCH($A22,TYP_TYPE,0)))),"")) | T22: =IF(OR($A22="",$E22=""),0,IF($V22=1,0,1)) | U22: =IF($T22=0,0,IF($M22<>"",1,IF(IFERROR(INDEX(WF_CLASS,MATCH($H22,WF_CODE,0)),"")="Done",1,0))) | V22: =IF(OR($A22="",$E22=""),0,IF(IFERROR(INDEX(WF_CLASS,MATCH($H22,WF_CODE,0)),"")="Inactive",1,0)) | W22: =IF($A22="","",IFERROR(INDEX(TYP_PHASE,MATCH($A22,TYP_TYPE,0)),"-")) | X22: =IF(AND($T22=1,$U22=0,N($N22)>0),$N22+ROW()/1000000,"") | Y22: =IF(AND($T22=1,$U22=0,OR($I22<>"",N($N22)>0)),N($N22)+ROW()/1000000,"") | Z22: =IF(AND($T22=1,$U22=0,$I22="",N($N22)<=0,-N($N22)<=HORIZON),N($N22)+ROW()/1000000,"")
A23: Safe System Of Work | B23: System | C23: SYS-FA | E23: DMIC-SYS-FA-SSW-020 | F23: N. Bergstrom | G23: A. Mercer | H23: S3 - For Review | K23: =IF($A23="","",IF($J23<>"",$J23,$S23)) | L23: =IF(OR($A23="",$E23=""),"",IF($J23<>"","Manual",IF($S23="","-","Auto"))) | N23: =IF($T23=0,"",IF($U23=1,IF($M23="","",$M23-$K23),IF($K23="","",TODAY()-$K23))) | O23: =IF(OR($A23="",$E23=""),"",IF($V23=1,S_INACT,IF(ISNA(MATCH($A23,TYP_TYPE,0)),S_TYPEKO,IF($U23=1,S_DONE,IF(AND($K23="",$R23=""),S_NOSCOPE,IF($K23="",S_NOTARGET,IF($N23>0,S_LATE,IF($I23<>"",S_WIP,IF(-$N23<=FEN_DOC,S_RISK,IF(-$N23<=HORIZON,S_COMING,S_NOTYET)))))))))) | P23: =IF(OR($A23="",$E23=""),"",IF($V23=1,"",IF(ISNA(MATCH($A23,TYP_TYPE,0)),"Type not in the library",IF($B23="","Scope not set",IF(AND($B23="System",$C23=""),"System not set",IF(AND($B23="Equipment",$D23=""),"Equipment not set",IF($F23="","Responsible not set",IF($K23="","No target date",IF(AND($B23="Equipment",$C23<>"",IFERROR(INDEX(EQP_SYS,MATCH($D23,EQP_NOM,0)),"")<>$C23),"Equipment not in that system",IF(AND($U23=1,$M23=""),"Approved with no approval date","")))))))))) | R23: =IF(OR($A23="",$B23=""),"",IF($B23="Equipment",IFERROR(INDEX(EQP_START,MATCH($D23,EQP_NOM,0)),""),IF($B23="System",IFERROR(INDEX(SYS_EARLIEST,MATCH($C23,SYS_ID,0)),""),IF($B23="All",CTR_EARLIEST,"")))) | S23: =IF(OR($A23="",$E23=""),"",IFERROR(IF(INDEX(TYP_ANCHOR,MATCH($A23,TYP_TYPE,0))="Commissioning Start",IF($R23="","",$R23-INDEX(TYP_LEAD,MATCH($A23,TYP_TYPE,0))),IF(INDEX(MS_PLAN,MATCH(INDEX(TYP_ANCHOR,MATCH($A23,TYP_TYPE,0)),MS_NOM,0))="","",INDEX(MS_PLAN,MATCH(INDEX(TYP_ANCHOR,MATCH($A23,TYP_TYPE,0)),MS_NOM,0))-INDEX(TYP_LEAD,MATCH($A23,TYP_TYPE,0)))),"")) | T23: =IF(OR($A23="",$E23=""),0,IF($V23=1,0,1)) | U23: =IF($T23=0,0,IF($M23<>"",1,IF(IFERROR(INDEX(WF_CLASS,MATCH($H23,WF_CODE,0)),"")="Done",1,0))) | V23: =IF(OR($A23="",$E23=""),0,IF(IFERROR(INDEX(WF_CLASS,MATCH($H23,WF_CODE,0)),"")="Inactive",1,0)) | W23: =IF($A23="","",IFERROR(INDEX(TYP_PHASE,MATCH($A23,TYP_TYPE,0)),"-")) | X23: =IF(AND($T23=1,$U23=0,N($N23)>0),$N23+ROW()/1000000,"") | Y23: =IF(AND($T23=1,$U23=0,OR($I23<>"",N($N23)>0)),N($N23)+ROW()/1000000,"") | Z23: =IF(AND($T23=1,$U23=0,$I23="",N($N23)<=0,-N($N23)<=HORIZON),N($N23)+ROW()/1000000,"")
