Workbook
Name CONTRACT_ID: 'DMIC List - master'!$B$6:$B$65
Name CC_CONTRACT_ID: 'Competency&Complexity'!$B$6:$B$65

Sheet Overview
B2: DMIC Contract Overview | J2: As of | K2: =TODAY()
B3: Live rollup across all contracts - pulled from Contracts, Schedule & Status and Risk & Phase.
N4: Systems by contract
N5: Choose a contract: | O5: UK-EX01
B6: Total contracts | D6: Average risk | F6: Critical (risk ≥ 60%) | H6: Watch (30–59%)
N7: {=IFERROR(TEXTJOIN(CHAR(10),TRUE,IF(Systems!$B$6:$B$65=$O$5,Systems!$C$6:$C$65,"")),"")}
B8: =COUNTA('DMIC List - master'!$B$6:$B$65) | D8: =IFERROR(AVERAGE('DMIC DMS Commissioning-master'!$U$6:$U$65),"—") | F8: =COUNTIF('DMIC DMS Commissioning-master'!$U$6:$U$65,">=0.6") | H8: =COUNTIFS('DMIC DMS Commissioning-master'!$U$6:$U$65,">=0.3",'DMIC DMS Commissioning-master'!$U$6:$U$65,"<0.6")
B13: Contract Number | C13: Area | D13: Contractor | E13: Description | F13: Current Phase | G13: Total Risk % | H13: Next Milestone | I13: Days to Milestone | J13: Commissioning Engineer | K13: Commissioning Manager | L13: DMIC Co-ordinator | M13: Status
B14: =IFERROR(IF('DMIC List - master'!B6="","",'DMIC List - master'!B6),"") | C14: =IFERROR(IF($B14="","",'DMIC List - master'!C6),"") | D14: =IFERROR(IF($B14="","",'DMIC List - master'!D6),"") | E14: =IFERROR(IF($B14="","",'DMIC List - master'!E6),"") | F14: =IFERROR(IF($B14="","",IF(INDEX('DMIC DMS Commissioning-master'!$O$6:$O$65,MATCH($B14,'DMIC DMS Commissioning-master'!$B$6:$B$65,0))=0,"",INDEX('DMIC DMS Commissioning-master'!$O$6:$O$65,MATCH($B14,'DMIC DMS Commissioning-master'!$B$6:$B$65,0)))),"") | G14: =IFERROR(IF($B14="","",INDEX('DMIC DMS Commissioning-master'!$U$6:$U$65,MATCH($B14,'DMIC DMS Commissioning-master'!$B$6:$B$65,0))),"") | H14: =IFERROR(IF($B14="","",IF(INDEX('Commissioning Readiness'!$N$6:$N$65,MATCH($B14,'Commissioning Readiness'!$B$6:$B$65,0))=0,"",INDEX('Commissioning Readiness'!$N$6:$N$65,MATCH($B14,'Commissioning Readiness'!$B$6:$B$65,0)))),"") | I14: =IF(OR($B14="",$H14=""),"",$H14-TODAY()) | J14: =IFERROR(IF($B14="","",'DMIC List - master'!P6),"") | K14: =IFERROR(IF($B14="","",'DMIC List - master'!Q6),"") | L14: =IFERROR(IF($B14="","",'DMIC List - master'!U6),"") | M14: =IF($B14="","",IF(OR($G14<>""),IF(OR($G14>=0.6,AND($I14<>"",$I14<0)),"Critical",IF(OR($G14>=0.3,AND($I14<>"",$I14>=0,$I14<=60)),"Watch","On track")),"No data"))
B15: =IFERROR(IF('DMIC List - master'!B7="","",'DMIC List - master'!B7),"") | C15: =IFERROR(IF($B15="","",'DMIC List - master'!C7),"") | D15: =IFERROR(IF($B15="","",'DMIC List - master'!D7),"") | E15: =IFERROR(IF($B15="","",'DMIC List - master'!E7),"") | F15: =IFERROR(IF($B15="","",IF(INDEX('DMIC DMS Commissioning-master'!$O$6:$O$65,MATCH($B15,'DMIC DMS Commissioning-master'!$B$6:$B$65,0))=0,"",INDEX('DMIC DMS Commissioning-master'!$O$6:$O$65,MATCH($B15,'DMIC DMS Commissioning-master'!$B$6:$B$65,0)))),"") | G15: =IFERROR(IF($B15="","",INDEX('DMIC DMS Commissioning-master'!$U$6:$U$65,MATCH($B15,'DMIC DMS Commissioning-master'!$B$6:$B$65,0))),"") | H15: =IFERROR(IF($B15="","",IF(INDEX('Commissioning Readiness'!$N$6:$N$65,MATCH($B15,'Commissioning Readiness'!$B$6:$B$65,0))=0,"",INDEX('Commissioning Readiness'!$N$6:$N$65,MATCH($B15,'Commissioning Readiness'!$B$6:$B$65,0)))),"") | I15: =IF(OR($B15="",$H15=""),"",$H15-TODAY()) | J15: =IFERROR(IF($B15="","",'DMIC List - master'!P7),"") | K15: =IFERROR(IF($B15="","",'DMIC List - master'!Q7),"") | L15: =IFERROR(IF($B15="","",'DMIC List - master'!U7),"") | M15: =IF($B15="","",IF(OR($G15<>""),IF(OR($G15>=0.6,AND($I15<>"",$I15<0)),"Critical",IF(OR($G15>=0.3,AND($I15<>"",$I15>=0,$I15<=60)),"Watch","On track")),"No data"))
B16: =IFERROR(IF('DMIC List - master'!B8="","",'DMIC List - master'!B8),"") | C16: =IFERROR(IF($B16="","",'DMIC List - master'!C8),"") | D16: =IFERROR(IF($B16="","",'DMIC List - master'!D8),"") | E16: =IFERROR(IF($B16="","",'DMIC List - master'!E8),"") | F16: =IFERROR(IF($B16="","",IF(INDEX('DMIC DMS Commissioning-master'!$O$6:$O$65,MATCH($B16,'DMIC DMS Commissioning-master'!$B$6:$B$65,0))=0,"",INDEX('DMIC DMS Commissioning-master'!$O$6:$O$65,MATCH($B16,'DMIC DMS Commissioning-master'!$B$6:$B$65,0)))),"") | G16: =IFERROR(IF($B16="","",INDEX('DMIC DMS Commissioning-master'!$U$6:$U$65,MATCH($B16,'DMIC DMS Commissioning-master'!$B$6:$B$65,0))),"") | H16: =IFERROR(IF($B16="","",IF(INDEX('Commissioning Readiness'!$N$6:$N$65,MATCH($B16,'Commissioning Readiness'!$B$6:$B$65,0))=0,"",INDEX('Commissioning Readiness'!$N$6:$N$65,MATCH($B16,'Commissioning Readiness'!$B$6:$B$65,0)))),"") | I16: =IF(OR($B16="",$H16=""),"",$H16-TODAY()) | J16: =IFERROR(IF($B16="","",'DMIC List - master'!P8),"") | K16: =IFERROR(IF($B16="","",'DMIC List - master'!Q8),"") | L16: =IFERROR(IF($B16="","",'DMIC List - master'!U8),"") | M16: =IF($B16="","",IF(OR($G16<>""),IF(OR($G16>=0.6,AND($I16<>"",$I16<0)),"Critical",IF(OR($G16>=0.3,AND($I16<>"",$I16>=0,$I16<=60)),"Watch","On track")),"No data"))
B17: =IFERROR(IF('DMIC List - master'!B9="","",'DMIC List - master'!B9),"") | C17: =IFERROR(IF($B17="","",'DMIC List - master'!C9),"") | D17: =IFERROR(IF($B17="","",'DMIC List - master'!D9),"") | E17: =IFERROR(IF($B17="","",'DMIC List - master'!E9),"") | F17: =IFERROR(IF($B17="","",IF(INDEX('DMIC DMS Commissioning-master'!$O$6:$O$65,MATCH($B17,'DMIC DMS Commissioning-master'!$B$6:$B$65,0))=0,"",INDEX('DMIC DMS Commissioning-master'!$O$6:$O$65,MATCH($B17,'DMIC DMS Commissioning-master'!$B$6:$B$65,0)))),"") | G17: =IFERROR(IF($B17="","",INDEX('DMIC DMS Commissioning-master'!$U$6:$U$65,MATCH($B17,'DMIC DMS Commissioning-master'!$B$6:$B$65,0))),"") | H17: =IFERROR(IF($B17="","",IF(INDEX('Commissioning Readiness'!$N$6:$N$65,MATCH($B17,'Commissioning Readiness'!$B$6:$B$65,0))=0,"",INDEX('Commissioning Readiness'!$N$6:$N$65,MATCH($B17,'Commissioning Readiness'!$B$6:$B$65,0)))),"") | I17: =IF(OR($B17="",$H17=""),"",$H17-TODAY()) | J17: =IFERROR(IF($B17="","",'DMIC List - master'!P9),"") | K17: =IFERROR(IF($B17="","",'DMIC List - master'!Q9),"") | L17: =IFERROR(IF($B17="","",'DMIC List - master'!U9),"") | M17: =IF($B17="","",IF(OR($G17<>""),IF(OR($G17>=0.6,AND($I17<>"",$I17<0)),"Critical",IF(OR($G17>=0.3,AND($I17<>"",$I17>=0,$I17<=60)),"Watch","On track")),"No data"))
B18: =IFERROR(IF('DMIC List - master'!B10="","",'DMIC List - master'!B10),"") | C18: =IFERROR(IF($B18="","",'DMIC List - master'!C10),"") | D18: =IFERROR(IF($B18="","",'DMIC List - master'!D10),"") | E18: =IFERROR(IF($B18="","",'DMIC List - master'!E10),"") | F18: =IFERROR(IF($B18="","",IF(INDEX('DMIC DMS Commissioning-master'!$O$6:$O$65,MATCH($B18,'DMIC DMS Commissioning-master'!$B$6:$B$65,0))=0,"",INDEX('DMIC DMS Commissioning-master'!$O$6:$O$65,MATCH($B18,'DMIC DMS Commissioning-master'!$B$6:$B$65,0)))),"") | G18: =IFERROR(IF($B18="","",INDEX('DMIC DMS Commissioning-master'!$U$6:$U$65,MATCH($B18,'DMIC DMS Commissioning-master'!$B$6:$B$65,0))),"") | H18: =IFERROR(IF($B18="","",IF(INDEX('Commissioning Readiness'!$N$6:$N$65,MATCH($B18,'Commissioning Readiness'!$B$6:$B$65,0))=0,"",INDEX('Commissioning Readiness'!$N$6:$N$65,MATCH($B18,'Commissioning Readiness'!$B$6:$B$65,0)))),"") | I18: =IF(OR($B18="",$H18=""),"",$H18-TODAY()) | J18: =IFERROR(IF($B18="","",'DMIC List - master'!P10),"") | K18: =IFERROR(IF($B18="","",'DMIC List - master'!Q10),"") | L18: =IFERROR(IF($B18="","",'DMIC List - master'!U10),"") | M18: =IF($B18="","",IF(OR($G18<>""),IF(OR($G18>=0.6,AND($I18<>"",$I18<0)),"Critical",IF(OR($G18>=0.3,AND($I18<>"",$I18>=0,$I18<=60)),"Watch","On track")),"No data"))
B19: =IFERROR(IF('DMIC List - master'!B11="","",'DMIC List - master'!B11),"") | C19: =IFERROR(IF($B19="","",'DMIC List - master'!C11),"") | D19: =IFERROR(IF($B19="","",'DMIC List - master'!D11),"") | E19: =IFERROR(IF($B19="","",'DMIC List - master'!E11),"") | F19: =IFERROR(IF($B19="","",IF(INDEX('DMIC DMS Commissioning-master'!$O$6:$O$65,MATCH($B19,'DMIC DMS Commissioning-master'!$B$6:$B$65,0))=0,"",INDEX('DMIC DMS Commissioning-master'!$O$6:$O$65,MATCH($B19,'DMIC DMS Commissioning-master'!$B$6:$B$65,0)))),"") | G19: =IFERROR(IF($B19="","",INDEX('DMIC DMS Commissioning-master'!$U$6:$U$65,MATCH($B19,'DMIC DMS Commissioning-master'!$B$6:$B$65,0))),"") | H19: =IFERROR(IF($B19="","",IF(INDEX('Commissioning Readiness'!$N$6:$N$65,MATCH($B19,'Commissioning Readiness'!$B$6:$B$65,0))=0,"",INDEX('Commissioning Readiness'!$N$6:$N$65,MATCH($B19,'Commissioning Readiness'!$B$6:$B$65,0)))),"") | I19: =IF(OR($B19="",$H19=""),"",$H19-TODAY()) | J19: =IFERROR(IF($B19="","",'DMIC List - master'!P11),"") | K19: =IFERROR(IF($B19="","",'DMIC List - master'!Q11),"") | L19: =IFERROR(IF($B19="","",'DMIC List - master'!U11),"") | M19: =IF($B19="","",IF(OR($G19<>""),IF(OR($G19>=0.6,AND($I19<>"",$I19<0)),"Critical",IF(OR($G19>=0.3,AND($I19<>"",$I19>=0,$I19<=60)),"Watch","On track")),"No data"))
B20: =IFERROR(IF('DMIC List - master'!B12="","",'DMIC List - master'!B12),"") | C20: =IFERROR(IF($B20="","",'DMIC List - master'!C12),"") | D20: =IFERROR(IF($B20="","",'DMIC List - master'!D12),"") | E20: =IFERROR(IF($B20="","",'DMIC List - master'!E12),"") | F20: =IFERROR(IF($B20="","",IF(INDEX('DMIC DMS Commissioning-master'!$O$6:$O$65,MATCH($B20,'DMIC DMS Commissioning-master'!$B$6:$B$65,0))=0,"",INDEX('DMIC DMS Commissioning-master'!$O$6:$O$65,MATCH($B20,'DMIC DMS Commissioning-master'!$B$6:$B$65,0)))),"") | G20: =IFERROR(IF($B20="","",INDEX('DMIC DMS Commissioning-master'!$U$6:$U$65,MATCH($B20,'DMIC DMS Commissioning-master'!$B$6:$B$65,0))),"") | H20: =IFERROR(IF($B20="","",IF(INDEX('Commissioning Readiness'!$N$6:$N$65,MATCH($B20,'Commissioning Readiness'!$B$6:$B$65,0))=0,"",INDEX('Commissioning Readiness'!$N$6:$N$65,MATCH($B20,'Commissioning Readiness'!$B$6:$B$65,0)))),"") | I20: =IF(OR($B20="",$H20=""),"",$H20-TODAY()) | J20: =IFERROR(IF($B20="","",'DMIC List - master'!P12),"") | K20: =IFERROR(IF($B20="","",'DMIC List - master'!Q12),"") | L20: =IFERROR(IF($B20="","",'DMIC List - master'!U12),"") | M20: =IF($B20="","",IF(OR($G20<>""),IF(OR($G20>=0.6,AND($I20<>"",$I20<0)),"Critical",IF(OR($G20>=0.3,AND($I20<>"",$I20>=0,$I20<=60)),"Watch","On track")),"No data"))
B21: =IFERROR(IF('DMIC List - master'!B13="","",'DMIC List - master'!B13),"") | C21: =IFERROR(IF($B21="","",'DMIC List - master'!C13),"") | D21: =IFERROR(IF($B21="","",'DMIC List - master'!D13),"") | E21: =IFERROR(IF($B21="","",'DMIC List - master'!E13),"") | F21: =IFERROR(IF($B21="","",IF(INDEX('DMIC DMS Commissioning-master'!$O$6:$O$65,MATCH($B21,'DMIC DMS Commissioning-master'!$B$6:$B$65,0))=0,"",INDEX('DMIC DMS Commissioning-master'!$O$6:$O$65,MATCH($B21,'DMIC DMS Commissioning-master'!$B$6:$B$65,0)))),"") | G21: =IFERROR(IF($B21="","",INDEX('DMIC DMS Commissioning-master'!$U$6:$U$65,MATCH($B21,'DMIC DMS Commissioning-master'!$B$6:$B$65,0))),"") | H21: =IFERROR(IF($B21="","",IF(INDEX('Commissioning Readiness'!$N$6:$N$65,MATCH($B21,'Commissioning Readiness'!$B$6:$B$65,0))=0,"",INDEX('Commissioning Readiness'!$N$6:$N$65,MATCH($B21,'Commissioning Readiness'!$B$6:$B$65,0)))),"") | I21: =IF(OR($B21="",$H21=""),"",$H21-TODAY()) | J21: =IFERROR(IF($B21="","",'DMIC List - master'!P13),"") | K21: =IFERROR(IF($B21="","",'DMIC List - master'!Q13),"") | L21: =IFERROR(IF($B21="","",'DMIC List - master'!U13),"") | M21: =IF($B21="","",IF(OR($G21<>""),IF(OR($G21>=0.6,AND($I21<>"",$I21<0)),"Critical",IF(OR($G21>=0.3,AND($I21<>"",$I21>=0,$I21<=60)),"Watch","On track")),"No data"))
B22: =IFERROR(IF('DMIC List - master'!B14="","",'DMIC List - master'!B14),"") | C22: =IFERROR(IF($B22="","",'DMIC List - master'!C14),"") | D22: =IFERROR(IF($B22="","",'DMIC List - master'!D14),"") | E22: =IFERROR(IF($B22="","",'DMIC List - master'!E14),"") | F22: =IFERROR(IF($B22="","",IF(INDEX('DMIC DMS Commissioning-master'!$O$6:$O$65,MATCH($B22,'DMIC DMS Commissioning-master'!$B$6:$B$65,0))=0,"",INDEX('DMIC DMS Commissioning-master'!$O$6:$O$65,MATCH($B22,'DMIC DMS Commissioning-master'!$B$6:$B$65,0)))),"") | G22: =IFERROR(IF($B22="","",INDEX('DMIC DMS Commissioning-master'!$U$6:$U$65,MATCH($B22,'DMIC DMS Commissioning-master'!$B$6:$B$65,0))),"") | H22: =IFERROR(IF($B22="","",IF(INDEX('Commissioning Readiness'!$N$6:$N$65,MATCH($B22,'Commissioning Readiness'!$B$6:$B$65,0))=0,"",INDEX('Commissioning Readiness'!$N$6:$N$65,MATCH($B22,'Commissioning Readiness'!$B$6:$B$65,0)))),"") | I22: =IF(OR($B22="",$H22=""),"",$H22-TODAY()) | J22: =IFERROR(IF($B22="","",'DMIC List - master'!P14),"") | K22: =IFERROR(IF($B22="","",'DMIC List - master'!Q14),"") | L22: =IFERROR(IF($B22="","",'DMIC List - master'!U14),"") | M22: =IF($B22="","",IF(OR($G22<>""),IF(OR($G22>=0.6,AND($I22<>"",$I22<0)),"Critical",IF(OR($G22>=0.3,AND($I22<>"",$I22>=0,$I22<=60)),"Watch","On track")),"No data"))
B23: =IFERROR(IF('DMIC List - master'!B15="","",'DMIC List - master'!B15),"") | C23: =IFERROR(IF($B23="","",'DMIC List - master'!C15),"") | D23: =IFERROR(IF($B23="","",'DMIC List - master'!D15),"") | E23: =IFERROR(IF($B23="","",'DMIC List - master'!E15),"") | F23: =IFERROR(IF($B23="","",IF(INDEX('DMIC DMS Commissioning-master'!$O$6:$O$65,MATCH($B23,'DMIC DMS Commissioning-master'!$B$6:$B$65,0))=0,"",INDEX('DMIC DMS Commissioning-master'!$O$6:$O$65,MATCH($B23,'DMIC DMS Commissioning-master'!$B$6:$B$65,0)))),"") | G23: =IFERROR(IF($B23="","",INDEX('DMIC DMS Commissioning-master'!$U$6:$U$65,MATCH($B23,'DMIC DMS Commissioning-master'!$B$6:$B$65,0))),"") | H23: =IFERROR(IF($B23="","",IF(INDEX('Commissioning Readiness'!$N$6:$N$65,MATCH($B23,'Commissioning Readiness'!$B$6:$B$65,0))=0,"",INDEX('Commissioning Readiness'!$N$6:$N$65,MATCH($B23,'Commissioning Readiness'!$B$6:$B$65,0)))),"") | I23: =IF(OR($B23="",$H23=""),"",$H23-TODAY()) | J23: =IFERROR(IF($B23="","",'DMIC List - master'!P15),"") | K23: =IFERROR(IF($B23="","",'DMIC List - master'!Q15),"") | L23: =IFERROR(IF($B23="","",'DMIC List - master'!U15),"") | M23: =IF($B23="","",IF(OR($G23<>""),IF(OR($G23>=0.6,AND($I23<>"",$I23<0)),"Critical",IF(OR($G23>=0.3,AND($I23<>"",$I23>=0,$I23<=60)),"Watch","On track")),"No data"))
B24: =IFERROR(IF('DMIC List - master'!B16="","",'DMIC List - master'!B16),"") | C24: =IFERROR(IF($B24="","",'DMIC List - master'!C16),"") | D24: =IFERROR(IF($B24="","",'DMIC List - master'!D16),"") | E24: =IFERROR(IF($B24="","",'DMIC List - master'!E16),"") | F24: =IFERROR(IF($B24="","",IF(INDEX('DMIC DMS Commissioning-master'!$O$6:$O$65,MATCH($B24,'DMIC DMS Commissioning-master'!$B$6:$B$65,0))=0,"",INDEX('DMIC DMS Commissioning-master'!$O$6:$O$65,MATCH($B24,'DMIC DMS Commissioning-master'!$B$6:$B$65,0)))),"") | G24: =IFERROR(IF($B24="","",INDEX('DMIC DMS Commissioning-master'!$U$6:$U$65,MATCH($B24,'DMIC DMS Commissioning-master'!$B$6:$B$65,0))),"") | H24: =IFERROR(IF($B24="","",IF(INDEX('Commissioning Readiness'!$N$6:$N$65,MATCH($B24,'Commissioning Readiness'!$B$6:$B$65,0))=0,"",INDEX('Commissioning Readiness'!$N$6:$N$65,MATCH($B24,'Commissioning Readiness'!$B$6:$B$65,0)))),"") | I24: =IF(OR($B24="",$H24=""),"",$H24-TODAY()) | J24: =IFERROR(IF($B24="","",'DMIC List - master'!P16),"") | K24: =IFERROR(IF($B24="","",'DMIC List - master'!Q16),"") | L24: =IFERROR(IF($B24="","",'DMIC List - master'!U16),"") | M24: =IF($B24="","",IF(OR($G24<>""),IF(OR($G24>=0.6,AND($I24<>"",$I24<0)),"Critical",IF(OR($G24>=0.3,AND($I24<>"",$I24>=0,$I24<=60)),"Watch","On track")),"No data"))
B25: =IFERROR(IF('DMIC List - master'!B17="","",'DMIC List - master'!B17),"") | C25: =IFERROR(IF($B25="","",'DMIC List - master'!C17),"") | D25: =IFERROR(IF($B25="","",'DMIC List - master'!D17),"") | E25: =IFERROR(IF($B25="","",'DMIC List - master'!E17),"") | F25: =IFERROR(IF($B25="","",IF(INDEX('DMIC DMS Commissioning-master'!$O$6:$O$65,MATCH($B25,'DMIC DMS Commissioning-master'!$B$6:$B$65,0))=0,"",INDEX('DMIC DMS Commissioning-master'!$O$6:$O$65,MATCH($B25,'DMIC DMS Commissioning-master'!$B$6:$B$65,0)))),"") | G25: =IFERROR(IF($B25="","",INDEX('DMIC DMS Commissioning-master'!$U$6:$U$65,MATCH($B25,'DMIC DMS Commissioning-master'!$B$6:$B$65,0))),"") | H25: =IFERROR(IF($B25="","",IF(INDEX('Commissioning Readiness'!$N$6:$N$65,MATCH($B25,'Commissioning Readiness'!$B$6:$B$65,0))=0,"",INDEX('Commissioning Readiness'!$N$6:$N$65,MATCH($B25,'Commissioning Readiness'!$B$6:$B$65,0)))),"") | I25: =IF(OR($B25="",$H25=""),"",$H25-TODAY()) | J25: =IFERROR(IF($B25="","",'DMIC List - master'!P17),"") | K25: =IFERROR(IF($B25="","",'DMIC List - master'!Q17),"") | L25: =IFERROR(IF($B25="","",'DMIC List - master'!U17),"") | M25: =IF($B25="","",IF(OR($G25<>""),IF(OR($G25>=0.6,AND($I25<>"",$I25<0)),"Critical",IF(OR($G25>=0.3,AND($I25<>"",$I25>=0,$I25<=60)),"Watch","On track")),"No data"))
... B73: =IFERROR(IF('DMIC List - master'!B65="","",'DMIC List - master'!B65),"") | C73: =IFERROR(IF($B73="","",'DMIC List - master'!C65),"") | D73: =IFERROR(IF($B73="","",'DMIC List - master'!D65),"") | E73: =IFERROR(IF($B73="","",'DMIC List - master'!E65),"") | F73: =IFERROR(IF($B73="","",IF(INDEX('DMIC DMS Commissioning-master'!$O$6:$O$65,MATCH($B73,'DMIC DMS Commissioning-master'!$B$6:$B$65,0))=0,"",INDEX('DMIC DMS Commissioning-master'!$O$6:$O$65,MATCH($B73,'DMIC DMS Commissioning-master'!$B$6:$B$65,0)))),"") | G73: =IFERROR(IF($B73="","",INDEX('DMIC DMS Commissioning-master'!$U$6:$U$65,MATCH($B73,'DMIC DMS Commissioning-master'!$B$6:$B$65,0))),"") | H73: =IFERROR(IF($B73="","",IF(INDEX('Commissioning Readiness'!$N$6:$N$65,MATCH($B73,'Commissioning Readiness'!$B$6:$B$65,0))=0,"",INDEX('Commissioning Readiness'!$N$6:$N$65,MATCH($B73,'Commissioning Readiness'!$B$6:$B$65,0)))),"") | I73: =IF(OR($B73="",$H73=""),"",$H73-TODAY()) | J73: =IFERROR(IF($B73="","",'DMIC List - master'!P65),"") | K73: =IFERROR(IF($B73="","",'DMIC List - master'!Q65),"") | L73: =IFERROR(IF($B73="","",'DMIC List - master'!U65),"") | M73: =IF($B73="","",IF(OR($G73<>""),IF(OR($G73>=0.6,AND($I73<>"",$I73<0)),"Critical",IF(OR($G73>=0.3,AND($I73<>"",$I73>=0,$I73<=60)),"Watch","On track")),"No data"))

Sheet DMIC List - master
B2: Contracts
B3: Single source of truth — contract identity and key personnel. Every other tab looks this up, never retypes it.
B4: Contract Information | K4: Key Personnel | W4: Notes
B5: Contract Number | C5: Area | D5: Contractor | E5: Description | F5: Programme | G5: Contract Type | H5: Contract Form | I5: Contractor Commissioning Level | K5: Delivery Manager | L5: Senior Project Manager | M5: PM / APM | N5: Commercial Lead | O5: Commercial Manager | P5: Commissioning Engineer | Q5: Commissioning Manager | R5: Quality Management Lead | S5: Contractor Project Director / Manager | T5: Contractor Construction / Site Manager | U5: DMIC Co-ordinator | W5: Notes
B6: UK-EX01 | C6: Nuclear Island | D6: REEL (formerly NFM) | E6: Airlocks | F6: FH&L | G6: FIDIC - DMIC | H6: Two-Stage | I6: Full | K6: David Munro | L6: Keith Nailard | M6: James Fayemiwo | N6: John Gallagher | O6: John Gallagher | P6: Adrian Kraemer | Q6: Feng Liu | R6: Priya Anand | S6: Kevin McDevitt | T6: Leigh Yule | U6: Sofia Marchetti
B7: UK-EX02 | C7: Conventional Island and BOP | D7: APCO | E7: Polar Crane | F7: FH&L | G7: FIDIC - DMIC | H7: Single-Stage | I7: Partial | K7: David Munro | L7: Keith Nailard | M7: Simon Stacey | N7: John Gallagher | O7: Richard Brown | P7: Richard Brown | Q7: Leigh Yule | R7: Priya Anand | S7: Kevin McDevitt | T7: Leigh Yule | U7: Sofia Marchetti
B8: UK-EX03 | C8: Site Wide / I&C | D8: Balfour Beatty | E8: Control Systems Integration | F8: I&C | G8: NEC4 | H8: Two-Stage | I8: Support Only | K8: David Munro | L8: Keith Nailard | M8: Stuart Cameron | N8: John Gallagher | O8: Gustavo Aguilar | P8: Samuel Everett | Q8: Leigh Yule | R8: Priya Anand | S8: Kevin McDevitt | T8: Leigh Yule | U8: Sofia Marchetti

Sheet Commissioning Readiness
B2: Schedule & Status | O2: Today's Date: | P2: =TODAY()
B3: Contract Number, contractor and key personnel are live look-ups from Contracts — never retyped here.
B4: Contract Information | G4: Key Personnel | K4: Schedule | S4: DMIC Kick-off | V4: Commissioning Contract Status | Z4: Software
B5: Contract Number | C5: Area | D5: Contractor | E5: Description | G5: Commissioning Engineer | H5: Commissioning Manager | I5: DMIC Co-ordinator | K5: First Date - as per P6 Schedule | L5: Date Changes (editable) | M5: Driver / Comment | N5: Next Phase Date (if in flight) | O5: Driver | P5: T - X Months | Q5: Schedule in P6 | S5: T-18 Kick-off Meeting Date (Incl. PM & Comm.) | T5: T-12 Kick-off Meeting Date (Contractor) | V5: Appendix 4 Revision CBL100100449 | W5: Appendix 4 - contract specific | X5: Appendix 4 Comments | Z5: NCRs on Switch | AA5: FCRs on Switch | AB5: Sonims | AC5: Open Points | AD5: TMDs | AE5: Standards & Expectations Day | AG5: Applicable System Codes
B6: =IF('DMIC List - master'!B6="","",'DMIC List - master'!B6) | C6: =IFERROR(IF(INDEX('DMIC List - master'!$C:$C,MATCH($B6,CONTRACT_ID,0)+5)="","",INDEX('DMIC List - master'!$C:$C,MATCH($B6,CONTRACT_ID,0)+5)),"") | D6: =IFERROR(IF(INDEX('DMIC List - master'!$D:$D,MATCH($B6,CONTRACT_ID,0)+5)="","",INDEX('DMIC List - master'!$D:$D,MATCH($B6,CONTRACT_ID,0)+5)),"") | E6: =IFERROR(IF(INDEX('DMIC List - master'!$E:$E,MATCH($B6,CONTRACT_ID,0)+5)="","",INDEX('DMIC List - master'!$E:$E,MATCH($B6,CONTRACT_ID,0)+5)),"") | G6: =IFERROR(IF(INDEX('DMIC List - master'!$P:$P,MATCH($B6,CONTRACT_ID,0)+5)="","",INDEX('DMIC List - master'!$P:$P,MATCH($B6,CONTRACT_ID,0)+5)),"") | H6: =IFERROR(IF(INDEX('DMIC List - master'!$Q:$Q,MATCH($B6,CONTRACT_ID,0)+5)="","",INDEX('DMIC List - master'!$Q:$Q,MATCH($B6,CONTRACT_ID,0)+5)),"") | I6: =IFERROR(IF(INDEX('DMIC List - master'!$U:$U,MATCH($B6,CONTRACT_ID,0)+5)="","",INDEX('DMIC List - master'!$U:$U,MATCH($B6,CONTRACT_ID,0)+5)),"") | K6: 46447 | N6: 46492 | O6: Next Phase kick-off | P6: =IFERROR(IF($B6="","",IF(N6<>"",(N6-$P$2)/30,IF(K6<>"",(K6-$P$2)/30,""))),"") | S6: 45944 | T6: 46127 | AG6: =IFERROR(IF($B6="","",IF(INDEX('DMIC DMS Commissioning-master'!$Z$6:$Z$65,MATCH($B6,'DMIC DMS Commissioning-master'!$B$6:$B$65,0))=0,"",INDEX('DMIC DMS Commissioning-master'!$Z$6:$Z$65,MATCH($B6,'DMIC DMS Commissioning-master'!$B$6:$B$65,0)))),"")
B7: =IF('DMIC List - master'!B7="","",'DMIC List - master'!B7) | C7: =IFERROR(IF(INDEX('DMIC List - master'!$C:$C,MATCH($B7,CONTRACT_ID,0)+5)="","",INDEX('DMIC List - master'!$C:$C,MATCH($B7,CONTRACT_ID,0)+5)),"") | D7: =IFERROR(IF(INDEX('DMIC List - master'!$D:$D,MATCH($B7,CONTRACT_ID,0)+5)="","",INDEX('DMIC List - master'!$D:$D,MATCH($B7,CONTRACT_ID,0)+5)),"") | E7: =IFERROR(IF(INDEX('DMIC List - master'!$E:$E,MATCH($B7,CONTRACT_ID,0)+5)="","",INDEX('DMIC List - master'!$E:$E,MATCH($B7,CONTRACT_ID,0)+5)),"") | G7: =IFERROR(IF(INDEX('DMIC List - master'!$P:$P,MATCH($B7,CONTRACT_ID,0)+5)="","",INDEX('DMIC List - master'!$P:$P,MATCH($B7,CONTRACT_ID,0)+5)),"") | H7: =IFERROR(IF(INDEX('DMIC List - master'!$Q:$Q,MATCH($B7,CONTRACT_ID,0)+5)="","",INDEX('DMIC List - master'!$Q:$Q,MATCH($B7,CONTRACT_ID,0)+5)),"") | I7: =IFERROR(IF(INDEX('DMIC List - master'!$U:$U,MATCH($B7,CONTRACT_ID,0)+5)="","",INDEX('DMIC List - master'!$U:$U,MATCH($B7,CONTRACT_ID,0)+5)),"") | K7: 46327 | N7: 46297 | O7: T-12 kick-off overdue | P7: =IFERROR(IF($B7="","",IF(N7<>"",(N7-$P$2)/30,IF(K7<>"",(K7-$P$2)/30,""))),"") | S7: 45749 | T7: 45932 | AG7: =IFERROR(IF($B7="","",IF(INDEX('DMIC DMS Commissioning-master'!$Z$6:$Z$65,MATCH($B7,'DMIC DMS Commissioning-master'!$B$6:$B$65,0))=0,"",INDEX('DMIC DMS Commissioning-master'!$Z$6:$Z$65,MATCH($B7,'DMIC DMS Commissioning-master'!$B$6:$B$65,0)))),"")
B8: =IF('DMIC List - master'!B8="","",'DMIC List - master'!B8) | C8: =IFERROR(IF(INDEX('DMIC List - master'!$C:$C,MATCH($B8,CONTRACT_ID,0)+5)="","",INDEX('DMIC List - master'!$C:$C,MATCH($B8,CONTRACT_ID,0)+5)),"") | D8: =IFERROR(IF(INDEX('DMIC List - master'!$D:$D,MATCH($B8,CONTRACT_ID,0)+5)="","",INDEX('DMIC List - master'!$D:$D,MATCH($B8,CONTRACT_ID,0)+5)),"") | E8: =IFERROR(IF(INDEX('DMIC List - master'!$E:$E,MATCH($B8,CONTRACT_ID,0)+5)="","",INDEX('DMIC List - master'!$E:$E,MATCH($B8,CONTRACT_ID,0)+5)),"") | G8: =IFERROR(IF(INDEX('DMIC List - master'!$P:$P,MATCH($B8,CONTRACT_ID,0)+5)="","",INDEX('DMIC List - master'!$P:$P,MATCH($B8,CONTRACT_ID,0)+5)),"") | H8: =IFERROR(IF(INDEX('DMIC List - master'!$Q:$Q,MATCH($B8,CONTRACT_ID,0)+5)="","",INDEX('DMIC List - master'!$Q:$Q,MATCH($B8,CONTRACT_ID,0)+5)),"") | I8: =IFERROR(IF(INDEX('DMIC List - master'!$U:$U,MATCH($B8,CONTRACT_ID,0)+5)="","",INDEX('DMIC List - master'!$U:$U,MATCH($B8,CONTRACT_ID,0)+5)),"") | K8: 46631 | N8: 46295 | O8: Standards & Expectations Day booked | P8: =IFERROR(IF($B8="","",IF(N8<>"",(N8-$P$2)/30,IF(K8<>"",(K8-$P$2)/30,""))),"") | S8: 45747 | T8: 45930 | AG8: =IFERROR(IF($B8="","",IF(INDEX('DMIC DMS Commissioning-master'!$Z$6:$Z$65,MATCH($B8,'DMIC DMS Commissioning-master'!$B$6:$B$65,0))=0,"",INDEX('DMIC DMS Commissioning-master'!$Z$6:$Z$65,MATCH($B8,'DMIC DMS Commissioning-master'!$B$6:$B$65,0)))),"")
B9: =IF('DMIC List - master'!B9="","",'DMIC List - master'!B9) | C9: =IFERROR(IF(INDEX('DMIC List - master'!$C:$C,MATCH($B9,CONTRACT_ID,0)+5)="","",INDEX('DMIC List - master'!$C:$C,MATCH($B9,CONTRACT_ID,0)+5)),"") | D9: =IFERROR(IF(INDEX('DMIC List - master'!$D:$D,MATCH($B9,CONTRACT_ID,0)+5)="","",INDEX('DMIC List - master'!$D:$D,MATCH($B9,CONTRACT_ID,0)+5)),"") | E9: =IFERROR(IF(INDEX('DMIC List - master'!$E:$E,MATCH($B9,CONTRACT_ID,0)+5)="","",INDEX('DMIC List - master'!$E:$E,MATCH($B9,CONTRACT_ID,0)+5)),"") | G9: =IFERROR(IF(INDEX('DMIC List - master'!$P:$P,MATCH($B9,CONTRACT_ID,0)+5)="","",INDEX('DMIC List - master'!$P:$P,MATCH($B9,CONTRACT_ID,0)+5)),"") | H9: =IFERROR(IF(INDEX('DMIC List - master'!$Q:$Q,MATCH($B9,CONTRACT_ID,0)+5)="","",INDEX('DMIC List - master'!$Q:$Q,MATCH($B9,CONTRACT_ID,0)+5)),"") | I9: =IFERROR(IF(INDEX('DMIC List - master'!$U:$U,MATCH($B9,CONTRACT_ID,0)+5)="","",INDEX('DMIC List - master'!$U:$U,MATCH($B9,CONTRACT_ID,0)+5)),"") | P9: =IFERROR(IF($B9="","",IF(N9<>"",(N9-$P$2)/30,IF(K9<>"",(K9-$P$2)/30,""))),"") | AG9: =IFERROR(IF($B9="","",IF(INDEX('DMIC DMS Commissioning-master'!$Z$6:$Z$65,MATCH($B9,'DMIC DMS Commissioning-master'!$B$6:$B$65,0))=0,"",INDEX('DMIC DMS Commissioning-master'!$Z$6:$Z$65,MATCH($B9,'DMIC DMS Commissioning-master'!$B$6:$B$65,0)))),"")
B10: =IF('DMIC List - master'!B10="","",'DMIC List - master'!B10) | C10: =IFERROR(IF(INDEX('DMIC List - master'!$C:$C,MATCH($B10,CONTRACT_ID,0)+5)="","",INDEX('DMIC List - master'!$C:$C,MATCH($B10,CONTRACT_ID,0)+5)),"") | D10: =IFERROR(IF(INDEX('DMIC List - master'!$D:$D,MATCH($B10,CONTRACT_ID,0)+5)="","",INDEX('DMIC List - master'!$D:$D,MATCH($B10,CONTRACT_ID,0)+5)),"") | E10: =IFERROR(IF(INDEX('DMIC List - master'!$E:$E,MATCH($B10,CONTRACT_ID,0)+5)="","",INDEX('DMIC List - master'!$E:$E,MATCH($B10,CONTRACT_ID,0)+5)),"") | G10: =IFERROR(IF(INDEX('DMIC List - master'!$P:$P,MATCH($B10,CONTRACT_ID,0)+5)="","",INDEX('DMIC List - master'!$P:$P,MATCH($B10,CONTRACT_ID,0)+5)),"") | H10: =IFERROR(IF(INDEX('DMIC List - master'!$Q:$Q,MATCH($B10,CONTRACT_ID,0)+5)="","",INDEX('DMIC List - master'!$Q:$Q,MATCH($B10,CONTRACT_ID,0)+5)),"") | I10: =IFERROR(IF(INDEX('DMIC List - master'!$U:$U,MATCH($B10,CONTRACT_ID,0)+5)="","",INDEX('DMIC List - master'!$U:$U,MATCH($B10,CONTRACT_ID,0)+5)),"") | P10: =IFERROR(IF($B10="","",IF(N10<>"",(N10-$P$2)/30,IF(K10<>"",(K10-$P$2)/30,""))),"") | AG10: =IFERROR(IF($B10="","",IF(INDEX('DMIC DMS Commissioning-master'!$Z$6:$Z$65,MATCH($B10,'DMIC DMS Commissioning-master'!$B$6:$B$65,0))=0,"",INDEX('DMIC DMS Commissioning-master'!$Z$6:$Z$65,MATCH($B10,'DMIC DMS Commissioning-master'!$B$6:$B$65,0)))),"")
B11: =IF('DMIC List - master'!B11="","",'DMIC List - master'!B11) | C11: =IFERROR(IF(INDEX('DMIC List - master'!$C:$C,MATCH($B11,CONTRACT_ID,0)+5)="","",INDEX('DMIC List - master'!$C:$C,MATCH($B11,CONTRACT_ID,0)+5)),"") | D11: =IFERROR(IF(INDEX('DMIC List - master'!$D:$D,MATCH($B11,CONTRACT_ID,0)+5)="","",INDEX('DMIC List - master'!$D:$D,MATCH($B11,CONTRACT_ID,0)+5)),"") | E11: =IFERROR(IF(INDEX('DMIC List - master'!$E:$E,MATCH($B11,CONTRACT_ID,0)+5)="","",INDEX('DMIC List - master'!$E:$E,MATCH($B11,CONTRACT_ID,0)+5)),"") | G11: =IFERROR(IF(INDEX('DMIC List - master'!$P:$P,MATCH($B11,CONTRACT_ID,0)+5)="","",INDEX('DMIC List - master'!$P:$P,MATCH($B11,CONTRACT_ID,0)+5)),"") | H11: =IFERROR(IF(INDEX('DMIC List - master'!$Q:$Q,MATCH($B11,CONTRACT_ID,0)+5)="","",INDEX('DMIC List - master'!$Q:$Q,MATCH($B11,CONTRACT_ID,0)+5)),"") | I11: =IFERROR(IF(INDEX('DMIC List - master'!$U:$U,MATCH($B11,CONTRACT_ID,0)+5)="","",INDEX('DMIC List - master'!$U:$U,MATCH($B11,CONTRACT_ID,0)+5)),"") | P11: =IFERROR(IF($B11="","",IF(N11<>"",(N11-$P$2)/30,IF(K11<>"",(K11-$P$2)/30,""))),"") | AG11: =IFERROR(IF($B11="","",IF(INDEX('DMIC DMS Commissioning-master'!$Z$6:$Z$65,MATCH($B11,'DMIC DMS Commissioning-master'!$B$6:$B$65,0))=0,"",INDEX('DMIC DMS Commissioning-master'!$Z$6:$Z$65,MATCH($B11,'DMIC DMS Commissioning-master'!$B$6:$B$65,0)))),"")
B12: =IF('DMIC List - master'!B12="","",'DMIC List - master'!B12) | C12: =IFERROR(IF(INDEX('DMIC List - master'!$C:$C,MATCH($B12,CONTRACT_ID,0)+5)="","",INDEX('DMIC List - master'!$C:$C,MATCH($B12,CONTRACT_ID,0)+5)),"") | D12: =IFERROR(IF(INDEX('DMIC List - master'!$D:$D,MATCH($B12,CONTRACT_ID,0)+5)="","",INDEX('DMIC List - master'!$D:$D,MATCH($B12,CONTRACT_ID,0)+5)),"") | E12: =IFERROR(IF(INDEX('DMIC List - master'!$E:$E,MATCH($B12,CONTRACT_ID,0)+5)="","",INDEX('DMIC List - master'!$E:$E,MATCH($B12,CONTRACT_ID,0)+5)),"") | G12: =IFERROR(IF(INDEX('DMIC List - master'!$P:$P,MATCH($B12,CONTRACT_ID,0)+5)="","",INDEX('DMIC List - master'!$P:$P,MATCH($B12,CONTRACT_ID,0)+5)),"") | H12: =IFERROR(IF(INDEX('DMIC List - master'!$Q:$Q,MATCH($B12,CONTRACT_ID,0)+5)="","",INDEX('DMIC List - master'!$Q:$Q,MATCH($B12,CONTRACT_ID,0)+5)),"") | I12: =IFERROR(IF(INDEX('DMIC List - master'!$U:$U,MATCH($B12,CONTRACT_ID,0)+5)="","",INDEX('DMIC List - master'!$U:$U,MATCH($B12,CONTRACT_ID,0)+5)),"") | P12: =IFERROR(IF($B12="","",IF(N12<>"",(N12-$P$2)/30,IF(K12<>"",(K12-$P$2)/30,""))),"") | AG12: =IFERROR(IF($B12="","",IF(INDEX('DMIC DMS Commissioning-master'!$Z$6:$Z$65,MATCH($B12,'DMIC DMS Commissioning-master'!$B$6:$B$65,0))=0,"",INDEX('DMIC DMS Commissioning-master'!$Z$6:$Z$65,MATCH($B12,'DMIC DMS Commissioning-master'!$B$6:$B$65,0)))),"")
B13: =IF('DMIC List - master'!B13="","",'DMIC List - master'!B13) | C13: =IFERROR(IF(INDEX('DMIC List - master'!$C:$C,MATCH($B13,CONTRACT_ID,0)+5)="","",INDEX('DMIC List - master'!$C:$C,MATCH($B13,CONTRACT_ID,0)+5)),"") | D13: =IFERROR(IF(INDEX('DMIC List - master'!$D:$D,MATCH($B13,CONTRACT_ID,0)+5)="","",INDEX('DMIC List - master'!$D:$D,MATCH($B13,CONTRACT_ID,0)+5)),"") | E13: =IFERROR(IF(INDEX('DMIC List - master'!$E:$E,MATCH($B13,CONTRACT_ID,0)+5)="","",INDEX('DMIC List - master'!$E:$E,MATCH($B13,CONTRACT_ID,0)+5)),"") | G13: =IFERROR(IF(INDEX('DMIC List - master'!$P:$P,MATCH($B13,CONTRACT_ID,0)+5)="","",INDEX('DMIC List - master'!$P:$P,MATCH($B13,CONTRACT_ID,0)+5)),"") | H13: =IFERROR(IF(INDEX('DMIC List - master'!$Q:$Q,MATCH($B13,CONTRACT_ID,0)+5)="","",INDEX('DMIC List - master'!$Q:$Q,MATCH($B13,CONTRACT_ID,0)+5)),"") | I13: =IFERROR(IF(INDEX('DMIC List - master'!$U:$U,MATCH($B13,CONTRACT_ID,0)+5)="","",INDEX('DMIC List - master'!$U:$U,MATCH($B13,CONTRACT_ID,0)+5)),"") | P13: =IFERROR(IF($B13="","",IF(N13<>"",(N13-$P$2)/30,IF(K13<>"",(K13-$P$2)/30,""))),"") | AG13: =IFERROR(IF($B13="","",IF(INDEX('DMIC DMS Commissioning-master'!$Z$6:$Z$65,MATCH($B13,'DMIC DMS Commissioning-master'!$B$6:$B$65,0))=0,"",INDEX('DMIC DMS Commissioning-master'!$Z$6:$Z$65,MATCH($B13,'DMIC DMS Commissioning-master'!$B$6:$B$65,0)))),"")
B14: =IF('DMIC List - master'!B14="","",'DMIC List - master'!B14) | C14: =IFERROR(IF(INDEX('DMIC List - master'!$C:$C,MATCH($B14,CONTRACT_ID,0)+5)="","",INDEX('DMIC List - master'!$C:$C,MATCH($B14,CONTRACT_ID,0)+5)),"") | D14: =IFERROR(IF(INDEX('DMIC List - master'!$D:$D,MATCH($B14,CONTRACT_ID,0)+5)="","",INDEX('DMIC List - master'!$D:$D,MATCH($B14,CONTRACT_ID,0)+5)),"") | E14: =IFERROR(IF(INDEX('DMIC List - master'!$E:$E,MATCH($B14,CONTRACT_ID,0)+5)="","",INDEX('DMIC List - master'!$E:$E,MATCH($B14,CONTRACT_ID,0)+5)),"") | G14: =IFERROR(IF(INDEX('DMIC List - master'!$P:$P,MATCH($B14,CONTRACT_ID,0)+5)="","",INDEX('DMIC List - master'!$P:$P,MATCH($B14,CONTRACT_ID,0)+5)),"") | H14: =IFERROR(IF(INDEX('DMIC List - master'!$Q:$Q,MATCH($B14,CONTRACT_ID,0)+5)="","",INDEX('DMIC List - master'!$Q:$Q,MATCH($B14,CONTRACT_ID,0)+5)),"") | I14: =IFERROR(IF(INDEX('DMIC List - master'!$U:$U,MATCH($B14,CONTRACT_ID,0)+5)="","",INDEX('DMIC List - master'!$U:$U,MATCH($B14,CONTRACT_ID,0)+5)),"") | P14: =IFERROR(IF($B14="","",IF(N14<>"",(N14-$P$2)/30,IF(K14<>"",(K14-$P$2)/30,""))),"") | AG14: =IFERROR(IF($B14="","",IF(INDEX('DMIC DMS Commissioning-master'!$Z$6:$Z$65,MATCH($B14,'DMIC DMS Commissioning-master'!$B$6:$B$65,0))=0,"",INDEX('DMIC DMS Commissioning-master'!$Z$6:$Z$65,MATCH($B14,'DMIC DMS Commissioning-master'!$B$6:$B$65,0)))),"")
B15: =IF('DMIC List - master'!B15="","",'DMIC List - master'!B15) | C15: =IFERROR(IF(INDEX('DMIC List - master'!$C:$C,MATCH($B15,CONTRACT_ID,0)+5)="","",INDEX('DMIC List - master'!$C:$C,MATCH($B15,CONTRACT_ID,0)+5)),"") | D15: =IFERROR(IF(INDEX('DMIC List - master'!$D:$D,MATCH($B15,CONTRACT_ID,0)+5)="","",INDEX('DMIC List - master'!$D:$D,MATCH($B15,CONTRACT_ID,0)+5)),"") | E15: =IFERROR(IF(INDEX('DMIC List - master'!$E:$E,MATCH($B15,CONTRACT_ID,0)+5)="","",INDEX('DMIC List - master'!$E:$E,MATCH($B15,CONTRACT_ID,0)+5)),"") | G15: =IFERROR(IF(INDEX('DMIC List - master'!$P:$P,MATCH($B15,CONTRACT_ID,0)+5)="","",INDEX('DMIC List - master'!$P:$P,MATCH($B15,CONTRACT_ID,0)+5)),"") | H15: =IFERROR(IF(INDEX('DMIC List - master'!$Q:$Q,MATCH($B15,CONTRACT_ID,0)+5)="","",INDEX('DMIC List - master'!$Q:$Q,MATCH($B15,CONTRACT_ID,0)+5)),"") | I15: =IFERROR(IF(INDEX('DMIC List - master'!$U:$U,MATCH($B15,CONTRACT_ID,0)+5)="","",INDEX('DMIC List - master'!$U:$U,MATCH($B15,CONTRACT_ID,0)+5)),"") | P15: =IFERROR(IF($B15="","",IF(N15<>"",(N15-$P$2)/30,IF(K15<>"",(K15-$P$2)/30,""))),"") | AG15: =IFERROR(IF($B15="","",IF(INDEX('DMIC DMS Commissioning-master'!$Z$6:$Z$65,MATCH($B15,'DMIC DMS Commissioning-master'!$B$6:$B$65,0))=0,"",INDEX('DMIC DMS Commissioning-master'!$Z$6:$Z$65,MATCH($B15,'DMIC DMS Commissioning-master'!$B$6:$B$65,0)))),"")
B16: =IF('DMIC List - master'!B16="","",'DMIC List - master'!B16) | C16: =IFERROR(IF(INDEX('DMIC List - master'!$C:$C,MATCH($B16,CONTRACT_ID,0)+5)="","",INDEX('DMIC List - master'!$C:$C,MATCH($B16,CONTRACT_ID,0)+5)),"") | D16: =IFERROR(IF(INDEX('DMIC List - master'!$D:$D,MATCH($B16,CONTRACT_ID,0)+5)="","",INDEX('DMIC List - master'!$D:$D,MATCH($B16,CONTRACT_ID,0)+5)),"") | E16: =IFERROR(IF(INDEX('DMIC List - master'!$E:$E,MATCH($B16,CONTRACT_ID,0)+5)="","",INDEX('DMIC List - master'!$E:$E,MATCH($B16,CONTRACT_ID,0)+5)),"") | G16: =IFERROR(IF(INDEX('DMIC List - master'!$P:$P,MATCH($B16,CONTRACT_ID,0)+5)="","",INDEX('DMIC List - master'!$P:$P,MATCH($B16,CONTRACT_ID,0)+5)),"") | H16: =IFERROR(IF(INDEX('DMIC List - master'!$Q:$Q,MATCH($B16,CONTRACT_ID,0)+5)="","",INDEX('DMIC List - master'!$Q:$Q,MATCH($B16,CONTRACT_ID,0)+5)),"") | I16: =IFERROR(IF(INDEX('DMIC List - master'!$U:$U,MATCH($B16,CONTRACT_ID,0)+5)="","",INDEX('DMIC List - master'!$U:$U,MATCH($B16,CONTRACT_ID,0)+5)),"") | P16: =IFERROR(IF($B16="","",IF(N16<>"",(N16-$P$2)/30,IF(K16<>"",(K16-$P$2)/30,""))),"") | AG16: =IFERROR(IF($B16="","",IF(INDEX('DMIC DMS Commissioning-master'!$Z$6:$Z$65,MATCH($B16,'DMIC DMS Commissioning-master'!$B$6:$B$65,0))=0,"",INDEX('DMIC DMS Commissioning-master'!$Z$6:$Z$65,MATCH($B16,'DMIC DMS Commissioning-master'!$B$6:$B$65,0)))),"")
B17: =IF('DMIC List - master'!B17="","",'DMIC List - master'!B17) | C17: =IFERROR(IF(INDEX('DMIC List - master'!$C:$C,MATCH($B17,CONTRACT_ID,0)+5)="","",INDEX('DMIC List - master'!$C:$C,MATCH($B17,CONTRACT_ID,0)+5)),"") | D17: =IFERROR(IF(INDEX('DMIC List - master'!$D:$D,MATCH($B17,CONTRACT_ID,0)+5)="","",INDEX('DMIC List - master'!$D:$D,MATCH($B17,CONTRACT_ID,0)+5)),"") | E17: =IFERROR(IF(INDEX('DMIC List - master'!$E:$E,MATCH($B17,CONTRACT_ID,0)+5)="","",INDEX('DMIC List - master'!$E:$E,MATCH($B17,CONTRACT_ID,0)+5)),"") | G17: =IFERROR(IF(INDEX('DMIC List - master'!$P:$P,MATCH($B17,CONTRACT_ID,0)+5)="","",INDEX('DMIC List - master'!$P:$P,MATCH($B17,CONTRACT_ID,0)+5)),"") | H17: =IFERROR(IF(INDEX('DMIC List - master'!$Q:$Q,MATCH($B17,CONTRACT_ID,0)+5)="","",INDEX('DMIC List - master'!$Q:$Q,MATCH($B17,CONTRACT_ID,0)+5)),"") | I17: =IFERROR(IF(INDEX('DMIC List - master'!$U:$U,MATCH($B17,CONTRACT_ID,0)+5)="","",INDEX('DMIC List - master'!$U:$U,MATCH($B17,CONTRACT_ID,0)+5)),"") | P17: =IFERROR(IF($B17="","",IF(N17<>"",(N17-$P$2)/30,IF(K17<>"",(K17-$P$2)/30,""))),"") | AG17: =IFERROR(IF($B17="","",IF(INDEX('DMIC DMS Commissioning-master'!$Z$6:$Z$65,MATCH($B17,'DMIC DMS Commissioning-master'!$B$6:$B$65,0))=0,"",INDEX('DMIC DMS Commissioning-master'!$Z$6:$Z$65,MATCH($B17,'DMIC DMS Commissioning-master'!$B$6:$B$65,0)))),"")
B18: =IF('DMIC List - master'!B18="","",'DMIC List - master'!B18) | C18: =IFERROR(IF(INDEX('DMIC List - master'!$C:$C,MATCH($B18,CONTRACT_ID,0)+5)="","",INDEX('DMIC List - master'!$C:$C,MATCH($B18,CONTRACT_ID,0)+5)),"") | D18: =IFERROR(IF(INDEX('DMIC List - master'!$D:$D,MATCH($B18,CONTRACT_ID,0)+5)="","",INDEX('DMIC List - master'!$D:$D,MATCH($B18,CONTRACT_ID,0)+5)),"") | E18: =IFERROR(IF(INDEX('DMIC List - master'!$E:$E,MATCH($B18,CONTRACT_ID,0)+5)="","",INDEX('DMIC List - master'!$E:$E,MATCH($B18,CONTRACT_ID,0)+5)),"") | G18: =IFERROR(IF(INDEX('DMIC List - master'!$P:$P,MATCH($B18,CONTRACT_ID,0)+5)="","",INDEX('DMIC List - master'!$P:$P,MATCH($B18,CONTRACT_ID,0)+5)),"") | H18: =IFERROR(IF(INDEX('DMIC List - master'!$Q:$Q,MATCH($B18,CONTRACT_ID,0)+5)="","",INDEX('DMIC List - master'!$Q:$Q,MATCH($B18,CONTRACT_ID,0)+5)),"") | I18: =IFERROR(IF(INDEX('DMIC List - master'!$U:$U,MATCH($B18,CONTRACT_ID,0)+5)="","",INDEX('DMIC List - master'!$U:$U,MATCH($B18,CONTRACT_ID,0)+5)),"") | P18: =IFERROR(IF($B18="","",IF(N18<>"",(N18-$P$2)/30,IF(K18<>"",(K18-$P$2)/30,""))),"") | AG18: =IFERROR(IF($B18="","",IF(INDEX('DMIC DMS Commissioning-master'!$Z$6:$Z$65,MATCH($B18,'DMIC DMS Commissioning-master'!$B$6:$B$65,0))=0,"",INDEX('DMIC DMS Commissioning-master'!$Z$6:$Z$65,MATCH($B18,'DMIC DMS Commissioning-master'!$B$6:$B$65,0)))),"")
B19: =IF('DMIC List - master'!B19="","",'DMIC List - master'!B19) | C19: =IFERROR(IF(INDEX('DMIC List - master'!$C:$C,MATCH($B19,CONTRACT_ID,0)+5)="","",INDEX('DMIC List - master'!$C:$C,MATCH($B19,CONTRACT_ID,0)+5)),"") | D19: =IFERROR(IF(INDEX('DMIC List - master'!$D:$D,MATCH($B19,CONTRACT_ID,0)+5)="","",INDEX('DMIC List - master'!$D:$D,MATCH($B19,CONTRACT_ID,0)+5)),"") | E19: =IFERROR(IF(INDEX('DMIC List - master'!$E:$E,MATCH($B19,CONTRACT_ID,0)+5)="","",INDEX('DMIC List - master'!$E:$E,MATCH($B19,CONTRACT_ID,0)+5)),"") | G19: =IFERROR(IF(INDEX('DMIC List - master'!$P:$P,MATCH($B19,CONTRACT_ID,0)+5)="","",INDEX('DMIC List - master'!$P:$P,MATCH($B19,CONTRACT_ID,0)+5)),"") | H19: =IFERROR(IF(INDEX('DMIC List - master'!$Q:$Q,MATCH($B19,CONTRACT_ID,0)+5)="","",INDEX('DMIC List - master'!$Q:$Q,MATCH($B19,CONTRACT_ID,0)+5)),"") | I19: =IFERROR(IF(INDEX('DMIC List - master'!$U:$U,MATCH($B19,CONTRACT_ID,0)+5)="","",INDEX('DMIC List - master'!$U:$U,MATCH($B19,CONTRACT_ID,0)+5)),"") | P19: =IFERROR(IF($B19="","",IF(N19<>"",(N19-$P$2)/30,IF(K19<>"",(K19-$P$2)/30,""))),"") | AG19: =IFERROR(IF($B19="","",IF(INDEX('DMIC DMS Commissioning-master'!$Z$6:$Z$65,MATCH($B19,'DMIC DMS Commissioning-master'!$B$6:$B$65,0))=0,"",INDEX('DMIC DMS Commissioning-master'!$Z$6:$Z$65,MATCH($B19,'DMIC DMS Commissioning-master'!$B$6:$B$65,0)))),"")
B20: =IF('DMIC List - master'!B20="","",'DMIC List - master'!B20) | C20: =IFERROR(IF(INDEX('DMIC List - master'!$C:$C,MATCH($B20,CONTRACT_ID,0)+5)="","",INDEX('DMIC List - master'!$C:$C,MATCH($B20,CONTRACT_ID,0)+5)),"") | D20: =IFERROR(IF(INDEX('DMIC List - master'!$D:$D,MATCH($B20,CONTRACT_ID,0)+5)="","",INDEX('DMIC List - master'!$D:$D,MATCH($B20,CONTRACT_ID,0)+5)),"") | E20: =IFERROR(IF(INDEX('DMIC List - master'!$E:$E,MATCH($B20,CONTRACT_ID,0)+5)="","",INDEX('DMIC List - master'!$E:$E,MATCH($B20,CONTRACT_ID,0)+5)),"") | G20: =IFERROR(IF(INDEX('DMIC List - master'!$P:$P,MATCH($B20,CONTRACT_ID,0)+5)="","",INDEX('DMIC List - master'!$P:$P,MATCH($B20,CONTRACT_ID,0)+5)),"") | H20: =IFERROR(IF(INDEX('DMIC List - master'!$Q:$Q,MATCH($B20,CONTRACT_ID,0)+5)="","",INDEX('DMIC List - master'!$Q:$Q,MATCH($B20,CONTRACT_ID,0)+5)),"") | I20: =IFERROR(IF(INDEX('DMIC List - master'!$U:$U,MATCH($B20,CONTRACT_ID,0)+5)="","",INDEX('DMIC List - master'!$U:$U,MATCH($B20,CONTRACT_ID,0)+5)),"") | P20: =IFERROR(IF($B20="","",IF(N20<>"",(N20-$P$2)/30,IF(K20<>"",(K20-$P$2)/30,""))),"") | AG20: =IFERROR(IF($B20="","",IF(INDEX('DMIC DMS Commissioning-master'!$Z$6:$Z$65,MATCH($B20,'DMIC DMS Commissioning-master'!$B$6:$B$65,0))=0,"",INDEX('DMIC DMS Commissioning-master'!$Z$6:$Z$65,MATCH($B20,'DMIC DMS Commissioning-master'!$B$6:$B$65,0)))),"")
... B65: =IF('DMIC List - master'!B65="","",'DMIC List - master'!B65) | C65: =IFERROR(IF(INDEX('DMIC List - master'!$C:$C,MATCH($B65,CONTRACT_ID,0)+5)="","",INDEX('DMIC List - master'!$C:$C,MATCH($B65,CONTRACT_ID,0)+5)),"") | D65: =IFERROR(IF(INDEX('DMIC List - master'!$D:$D,MATCH($B65,CONTRACT_ID,0)+5)="","",INDEX('DMIC List - master'!$D:$D,MATCH($B65,CONTRACT_ID,0)+5)),"") | E65: =IFERROR(IF(INDEX('DMIC List - master'!$E:$E,MATCH($B65,CONTRACT_ID,0)+5)="","",INDEX('DMIC List - master'!$E:$E,MATCH($B65,CONTRACT_ID,0)+5)),"") | G65: =IFERROR(IF(INDEX('DMIC List - master'!$P:$P,MATCH($B65,CONTRACT_ID,0)+5)="","",INDEX('DMIC List - master'!$P:$P,MATCH($B65,CONTRACT_ID,0)+5)),"") | H65: =IFERROR(IF(INDEX('DMIC List - master'!$Q:$Q,MATCH($B65,CONTRACT_ID,0)+5)="","",INDEX('DMIC List - master'!$Q:$Q,MATCH($B65,CONTRACT_ID,0)+5)),"") | I65: =IFERROR(IF(INDEX('DMIC List - master'!$U:$U,MATCH($B65,CONTRACT_ID,0)+5)="","",INDEX('DMIC List - master'!$U:$U,MATCH($B65,CONTRACT_ID,0)+5)),"") | P65: =IFERROR(IF($B65="","",IF(N65<>"",(N65-$P$2)/30,IF(K65<>"",(K65-$P$2)/30,""))),"") | AG65: =IFERROR(IF($B65="","",IF(INDEX('DMIC DMS Commissioning-master'!$Z$6:$Z$65,MATCH($B65,'DMIC DMS Commissioning-master'!$B$6:$B$65,0))=0,"",INDEX('DMIC DMS Commissioning-master'!$Z$6:$Z$65,MATCH($B65,'DMIC DMS Commissioning-master'!$B$6:$B$65,0)))),"")

Sheet DMIC DMS Commissioning-master
B2: Risk & Phase
B3: Contract identity is a live look-up from Contracts. Total Risk % is calculated from the 4 risk scores.
B4: Contract Information | G4: Key Personnel | K4: Capability & Complexity | N4: Phase | Q4: Risk relating to: | X4: Appendix / Systems
B5: Contract Number | C5: Area | D5: Contractor | E5: Description | G5: Commissioning Engineer | H5: Commissioning Manager | I5: DMIC Co-ordinator | K5: Contractor Capability Rating (10 = highest capability) | L5: Contract Complexity Rating (10 = most simple) | N5: Commissioning Start Date | O5: Current Phase of Contract | Q5: Schedule Risk | R5: Documentation Risk | S5: Integration / Collaboration Risk | T5: Team / Resource Risk | U5: Total Risk Percentage | V5: Risk Commentary | X5: Appendix 4 Revision | Y5: Commentary | Z5: Systems
B6: =IF('DMIC List - master'!B6="","",'DMIC List - master'!B6) | C6: =IFERROR(IF(INDEX('DMIC List - master'!$C:$C,MATCH($B6,CONTRACT_ID,0)+5)="","",INDEX('DMIC List - master'!$C:$C,MATCH($B6,CONTRACT_ID,0)+5)),"") | D6: =IFERROR(IF(INDEX('DMIC List - master'!$D:$D,MATCH($B6,CONTRACT_ID,0)+5)="","",INDEX('DMIC List - master'!$D:$D,MATCH($B6,CONTRACT_ID,0)+5)),"") | E6: =IFERROR(IF(INDEX('DMIC List - master'!$E:$E,MATCH($B6,CONTRACT_ID,0)+5)="","",INDEX('DMIC List - master'!$E:$E,MATCH($B6,CONTRACT_ID,0)+5)),"") | G6: =IFERROR(IF(INDEX('DMIC List - master'!$P:$P,MATCH($B6,CONTRACT_ID,0)+5)="","",INDEX('DMIC List - master'!$P:$P,MATCH($B6,CONTRACT_ID,0)+5)),"") | H6: =IFERROR(IF(INDEX('DMIC List - master'!$Q:$Q,MATCH($B6,CONTRACT_ID,0)+5)="","",INDEX('DMIC List - master'!$Q:$Q,MATCH($B6,CONTRACT_ID,0)+5)),"") | I6: =IFERROR(IF(INDEX('DMIC List - master'!$U:$U,MATCH($B6,CONTRACT_ID,0)+5)="","",INDEX('DMIC List - master'!$U:$U,MATCH($B6,CONTRACT_ID,0)+5)),"") | K6: =IFERROR(IF(OR($B6="",COUNTA(INDEX('Competency&Complexity'!$K:$K,MATCH($B6,CC_CONTRACT_ID,0)+5):INDEX('Competency&Complexity'!$P:$P,MATCH($B6,CC_CONTRACT_ID,0)+5))=0),"",ROUND((COUNTIF(INDEX('Competency&Complexity'!$K:$K,MATCH($B6,CC_CONTRACT_ID,0)+5):INDEX('Competency&Complexity'!$P:$P,MATCH($B6,CC_CONTRACT_ID,0)+5),"High")*2+COUNTIF(INDEX('Competency&Complexity'!$K:$K,MATCH($B6,CC_CONTRACT_ID,0)+5):INDEX('Competency&Complexity'!$P:$P,MATCH($B6,CC_CONTRACT_ID,0)+5),"Medium")*1)/12*10,1)),"") | L6: =IFERROR(IF(OR($B6="",COUNTA(INDEX('Competency&Complexity'!$R:$R,MATCH($B6,CC_CONTRACT_ID,0)+5):INDEX('Competency&Complexity'!$V:$V,MATCH($B6,CC_CONTRACT_ID,0)+5))=0),"",ROUND((COUNTIF(INDEX('Competency&Complexity'!$R:$R,MATCH($B6,CC_CONTRACT_ID,0)+5):INDEX('Competency&Complexity'!$V:$V,MATCH($B6,CC_CONTRACT_ID,0)+5),"Low")*2+COUNTIF(INDEX('Competency&Complexity'!$R:$R,MATCH($B6,CC_CONTRACT_ID,0)+5):INDEX('Competency&Complexity'!$V:$V,MATCH($B6,CC_CONTRACT_ID,0)+5),"Medium")*1)/10*10,1)),"") | N6: 46447 | O6: Commissioning Preparation | Q6: 2 | R6: 1 | S6: 2 | T6: 1 | U6: =IF($B6="","",IF(COUNT(Q6:T6)=0,"",(Q6+R6+S6+T6)/20)) | Z6: {=IFERROR(TEXTJOIN(", ",TRUE,IF(Systems!$B$6:$B$65=$B6,Systems!$C$6:$C$65,"")),"")}
B7: =IF('DMIC List - master'!B7="","",'DMIC List - master'!B7) | C7: =IFERROR(IF(INDEX('DMIC List - master'!$C:$C,MATCH($B7,CONTRACT_ID,0)+5)="","",INDEX('DMIC List - master'!$C:$C,MATCH($B7,CONTRACT_ID,0)+5)),"") | D7: =IFERROR(IF(INDEX('DMIC List - master'!$D:$D,MATCH($B7,CONTRACT_ID,0)+5)="","",INDEX('DMIC List - master'!$D:$D,MATCH($B7,CONTRACT_ID,0)+5)),"") | E7: =IFERROR(IF(INDEX('DMIC List - master'!$E:$E,MATCH($B7,CONTRACT_ID,0)+5)="","",INDEX('DMIC List - master'!$E:$E,MATCH($B7,CONTRACT_ID,0)+5)),"") | G7: =IFERROR(IF(INDEX('DMIC List - master'!$P:$P,MATCH($B7,CONTRACT_ID,0)+5)="","",INDEX('DMIC List - master'!$P:$P,MATCH($B7,CONTRACT_ID,0)+5)),"") | H7: =IFERROR(IF(INDEX('DMIC List - master'!$Q:$Q,MATCH($B7,CONTRACT_ID,0)+5)="","",INDEX('DMIC List - master'!$Q:$Q,MATCH($B7,CONTRACT_ID,0)+5)),"") | I7: =IFERROR(IF(INDEX('DMIC List - master'!$U:$U,MATCH($B7,CONTRACT_ID,0)+5)="","",INDEX('DMIC List - master'!$U:$U,MATCH($B7,CONTRACT_ID,0)+5)),"") | K7: =IFERROR(IF(OR($B7="",COUNTA(INDEX('Competency&Complexity'!$K:$K,MATCH($B7,CC_CONTRACT_ID,0)+5):INDEX('Competency&Complexity'!$P:$P,MATCH($B7,CC_CONTRACT_ID,0)+5))=0),"",ROUND((COUNTIF(INDEX('Competency&Complexity'!$K:$K,MATCH($B7,CC_CONTRACT_ID,0)+5):INDEX('Competency&Complexity'!$P:$P,MATCH($B7,CC_CONTRACT_ID,0)+5),"High")*2+COUNTIF(INDEX('Competency&Complexity'!$K:$K,MATCH($B7,CC_CONTRACT_ID,0)+5):INDEX('Competency&Complexity'!$P:$P,MATCH($B7,CC_CONTRACT_ID,0)+5),"Medium")*1)/12*10,1)),"") | L7: =IFERROR(IF(OR($B7="",COUNTA(INDEX('Competency&Complexity'!$R:$R,MATCH($B7,CC_CONTRACT_ID,0)+5):INDEX('Competency&Complexity'!$V:$V,MATCH($B7,CC_CONTRACT_ID,0)+5))=0),"",ROUND((COUNTIF(INDEX('Competency&Complexity'!$R:$R,MATCH($B7,CC_CONTRACT_ID,0)+5):INDEX('Competency&Complexity'!$V:$V,MATCH($B7,CC_CONTRACT_ID,0)+5),"Low")*2+COUNTIF(INDEX('Competency&Complexity'!$R:$R,MATCH($B7,CC_CONTRACT_ID,0)+5):INDEX('Competency&Complexity'!$V:$V,MATCH($B7,CC_CONTRACT_ID,0)+5),"Medium")*1)/10*10,1)),"") | N7: 46327 | O7: Commissioning | Q7: 4 | R7: 3 | S7: 4 | T7: 3 | U7: =IF($B7="","",IF(COUNT(Q7:T7)=0,"",(Q7+R7+S7+T7)/20)) | Z7: {=IFERROR(TEXTJOIN(", ",TRUE,IF(Systems!$B$6:$B$65=$B7,Systems!$C$6:$C$65,"")),"")}
B8: =IF('DMIC List - master'!B8="","",'DMIC List - master'!B8) | C8: =IFERROR(IF(INDEX('DMIC List - master'!$C:$C,MATCH($B8,CONTRACT_ID,0)+5)="","",INDEX('DMIC List - master'!$C:$C,MATCH($B8,CONTRACT_ID,0)+5)),"") | D8: =IFERROR(IF(INDEX('DMIC List - master'!$D:$D,MATCH($B8,CONTRACT_ID,0)+5)="","",INDEX('DMIC List - master'!$D:$D,MATCH($B8,CONTRACT_ID,0)+5)),"") | E8: =IFERROR(IF(INDEX('DMIC List - master'!$E:$E,MATCH($B8,CONTRACT_ID,0)+5)="","",INDEX('DMIC List - master'!$E:$E,MATCH($B8,CONTRACT_ID,0)+5)),"") | G8: =IFERROR(IF(INDEX('DMIC List - master'!$P:$P,MATCH($B8,CONTRACT_ID,0)+5)="","",INDEX('DMIC List - master'!$P:$P,MATCH($B8,CONTRACT_ID,0)+5)),"") | H8: =IFERROR(IF(INDEX('DMIC List - master'!$Q:$Q,MATCH($B8,CONTRACT_ID,0)+5)="","",INDEX('DMIC List - master'!$Q:$Q,MATCH($B8,CONTRACT_ID,0)+5)),"") | I8: =IFERROR(IF(INDEX('DMIC List - master'!$U:$U,MATCH($B8,CONTRACT_ID,0)+5)="","",INDEX('DMIC List - master'!$U:$U,MATCH($B8,CONTRACT_ID,0)+5)),"") | K8: =IFERROR(IF(OR($B8="",COUNTA(INDEX('Competency&Complexity'!$K:$K,MATCH($B8,CC_CONTRACT_ID,0)+5):INDEX('Competency&Complexity'!$P:$P,MATCH($B8,CC_CONTRACT_ID,0)+5))=0),"",ROUND((COUNTIF(INDEX('Competency&Complexity'!$K:$K,MATCH($B8,CC_CONTRACT_ID,0)+5):INDEX('Competency&Complexity'!$P:$P,MATCH($B8,CC_CONTRACT_ID,0)+5),"High")*2+COUNTIF(INDEX('Competency&Complexity'!$K:$K,MATCH($B8,CC_CONTRACT_ID,0)+5):INDEX('Competency&Complexity'!$P:$P,MATCH($B8,CC_CONTRACT_ID,0)+5),"Medium")*1)/12*10,1)),"") | L8: =IFERROR(IF(OR($B8="",COUNTA(INDEX('Competency&Complexity'!$R:$R,MATCH($B8,CC_CONTRACT_ID,0)+5):INDEX('Competency&Complexity'!$V:$V,MATCH($B8,CC_CONTRACT_ID,0)+5))=0),"",ROUND((COUNTIF(INDEX('Competency&Complexity'!$R:$R,MATCH($B8,CC_CONTRACT_ID,0)+5):INDEX('Competency&Complexity'!$V:$V,MATCH($B8,CC_CONTRACT_ID,0)+5),"Low")*2+COUNTIF(INDEX('Competency&Complexity'!$R:$R,MATCH($B8,CC_CONTRACT_ID,0)+5):INDEX('Competency&Complexity'!$V:$V,MATCH($B8,CC_CONTRACT_ID,0)+5),"Medium")*1)/10*10,1)),"") | N8: 46631 | O8: Design | Q8: 1 | R8: 1 | S8: 1 | T8: 1 | U8: =IF($B8="","",IF(COUNT(Q8:T8)=0,"",(Q8+R8+S8+T8)/20)) | Z8: {=IFERROR(TEXTJOIN(", ",TRUE,IF(Systems!$B$6:$B$65=$B8,Systems!$C$6:$C$65,"")),"")}
B9: =IF('DMIC List - master'!B9="","",'DMIC List - master'!B9) | C9: =IFERROR(IF(INDEX('DMIC List - master'!$C:$C,MATCH($B9,CONTRACT_ID,0)+5)="","",INDEX('DMIC List - master'!$C:$C,MATCH($B9,CONTRACT_ID,0)+5)),"") | D9: =IFERROR(IF(INDEX('DMIC List - master'!$D:$D,MATCH($B9,CONTRACT_ID,0)+5)="","",INDEX('DMIC List - master'!$D:$D,MATCH($B9,CONTRACT_ID,0)+5)),"") | E9: =IFERROR(IF(INDEX('DMIC List - master'!$E:$E,MATCH($B9,CONTRACT_ID,0)+5)="","",INDEX('DMIC List - master'!$E:$E,MATCH($B9,CONTRACT_ID,0)+5)),"") | G9: =IFERROR(IF(INDEX('DMIC List - master'!$P:$P,MATCH($B9,CONTRACT_ID,0)+5)="","",INDEX('DMIC List - master'!$P:$P,MATCH($B9,CONTRACT_ID,0)+5)),"") | H9: =IFERROR(IF(INDEX('DMIC List - master'!$Q:$Q,MATCH($B9,CONTRACT_ID,0)+5)="","",INDEX('DMIC List - master'!$Q:$Q,MATCH($B9,CONTRACT_ID,0)+5)),"") | I9: =IFERROR(IF(INDEX('DMIC List - master'!$U:$U,MATCH($B9,CONTRACT_ID,0)+5)="","",INDEX('DMIC List - master'!$U:$U,MATCH($B9,CONTRACT_ID,0)+5)),"") | K9: =IFERROR(IF(OR($B9="",COUNTA(INDEX('Competency&Complexity'!$K:$K,MATCH($B9,CC_CONTRACT_ID,0)+5):INDEX('Competency&Complexity'!$P:$P,MATCH($B9,CC_CONTRACT_ID,0)+5))=0),"",ROUND((COUNTIF(INDEX('Competency&Complexity'!$K:$K,MATCH($B9,CC_CONTRACT_ID,0)+5):INDEX('Competency&Complexity'!$P:$P,MATCH($B9,CC_CONTRACT_ID,0)+5),"High")*2+COUNTIF(INDEX('Competency&Complexity'!$K:$K,MATCH($B9,CC_CONTRACT_ID,0)+5):INDEX('Competency&Complexity'!$P:$P,MATCH($B9,CC_CONTRACT_ID,0)+5),"Medium")*1)/12*10,1)),"") | L9: =IFERROR(IF(OR($B9="",COUNTA(INDEX('Competency&Complexity'!$R:$R,MATCH($B9,CC_CONTRACT_ID,0)+5):INDEX('Competency&Complexity'!$V:$V,MATCH($B9,CC_CONTRACT_ID,0)+5))=0),"",ROUND((COUNTIF(INDEX('Competency&Complexity'!$R:$R,MATCH($B9,CC_CONTRACT_ID,0)+5):INDEX('Competency&Complexity'!$V:$V,MATCH($B9,CC_CONTRACT_ID,0)+5),"Low")*2+COUNTIF(INDEX('Competency&Complexity'!$R:$R,MATCH($B9,CC_CONTRACT_ID,0)+5):INDEX('Competency&Complexity'!$V:$V,MATCH($B9,CC_CONTRACT_ID,0)+5),"Medium")*1)/10*10,1)),"") | U9: =IF($B9="","",IF(COUNT(Q9:T9)=0,"",(Q9+R9+S9+T9)/20)) | Z9: {=IFERROR(TEXTJOIN(", ",TRUE,IF(Systems!$B$6:$B$65=$B9,Systems!$C$6:$C$65,"")),"")}
B10: =IF('DMIC List - master'!B10="","",'DMIC List - master'!B10) | C10: =IFERROR(IF(INDEX('DMIC List - master'!$C:$C,MATCH($B10,CONTRACT_ID,0)+5)="","",INDEX('DMIC List - master'!$C:$C,MATCH($B10,CONTRACT_ID,0)+5)),"") | D10: =IFERROR(IF(INDEX('DMIC List - master'!$D:$D,MATCH($B10,CONTRACT_ID,0)+5)="","",INDEX('DMIC List - master'!$D:$D,MATCH($B10,CONTRACT_ID,0)+5)),"") | E10: =IFERROR(IF(INDEX('DMIC List - master'!$E:$E,MATCH($B10,CONTRACT_ID,0)+5)="","",INDEX('DMIC List - master'!$E:$E,MATCH($B10,CONTRACT_ID,0)+5)),"") | G10: =IFERROR(IF(INDEX('DMIC List - master'!$P:$P,MATCH($B10,CONTRACT_ID,0)+5)="","",INDEX('DMIC List - master'!$P:$P,MATCH($B10,CONTRACT_ID,0)+5)),"") | H10: =IFERROR(IF(INDEX('DMIC List - master'!$Q:$Q,MATCH($B10,CONTRACT_ID,0)+5)="","",INDEX('DMIC List - master'!$Q:$Q,MATCH($B10,CONTRACT_ID,0)+5)),"") | I10: =IFERROR(IF(INDEX('DMIC List - master'!$U:$U,MATCH($B10,CONTRACT_ID,0)+5)="","",INDEX('DMIC List - master'!$U:$U,MATCH($B10,CONTRACT_ID,0)+5)),"") | K10: =IFERROR(IF(OR($B10="",COUNTA(INDEX('Competency&Complexity'!$K:$K,MATCH($B10,CC_CONTRACT_ID,0)+5):INDEX('Competency&Complexity'!$P:$P,MATCH($B10,CC_CONTRACT_ID,0)+5))=0),"",ROUND((COUNTIF(INDEX('Competency&Complexity'!$K:$K,MATCH($B10,CC_CONTRACT_ID,0)+5):INDEX('Competency&Complexity'!$P:$P,MATCH($B10,CC_CONTRACT_ID,0)+5),"High")*2+COUNTIF(INDEX('Competency&Complexity'!$K:$K,MATCH($B10,CC_CONTRACT_ID,0)+5):INDEX('Competency&Complexity'!$P:$P,MATCH($B10,CC_CONTRACT_ID,0)+5),"Medium")*1)/12*10,1)),"") | L10: =IFERROR(IF(OR($B10="",COUNTA(INDEX('Competency&Complexity'!$R:$R,MATCH($B10,CC_CONTRACT_ID,0)+5):INDEX('Competency&Complexity'!$V:$V,MATCH($B10,CC_CONTRACT_ID,0)+5))=0),"",ROUND((COUNTIF(INDEX('Competency&Complexity'!$R:$R,MATCH($B10,CC_CONTRACT_ID,0)+5):INDEX('Competency&Complexity'!$V:$V,MATCH($B10,CC_CONTRACT_ID,0)+5),"Low")*2+COUNTIF(INDEX('Competency&Complexity'!$R:$R,MATCH($B10,CC_CONTRACT_ID,0)+5):INDEX('Competency&Complexity'!$V:$V,MATCH($B10,CC_CONTRACT_ID,0)+5),"Medium")*1)/10*10,1)),"") | U10: =IF($B10="","",IF(COUNT(Q10:T10)=0,"",(Q10+R10+S10+T10)/20)) | Z10: {=IFERROR(TEXTJOIN(", ",TRUE,IF(Systems!$B$6:$B$65=$B10,Systems!$C$6:$C$65,"")),"")}
B11: =IF('DMIC List - master'!B11="","",'DMIC List - master'!B11) | C11: =IFERROR(IF(INDEX('DMIC List - master'!$C:$C,MATCH($B11,CONTRACT_ID,0)+5)="","",INDEX('DMIC List - master'!$C:$C,MATCH($B11,CONTRACT_ID,0)+5)),"") | D11: =IFERROR(IF(INDEX('DMIC List - master'!$D:$D,MATCH($B11,CONTRACT_ID,0)+5)="","",INDEX('DMIC List - master'!$D:$D,MATCH($B11,CONTRACT_ID,0)+5)),"") | E11: =IFERROR(IF(INDEX('DMIC List - master'!$E:$E,MATCH($B11,CONTRACT_ID,0)+5)="","",INDEX('DMIC List - master'!$E:$E,MATCH($B11,CONTRACT_ID,0)+5)),"") | G11: =IFERROR(IF(INDEX('DMIC List - master'!$P:$P,MATCH($B11,CONTRACT_ID,0)+5)="","",INDEX('DMIC List - master'!$P:$P,MATCH($B11,CONTRACT_ID,0)+5)),"") | H11: =IFERROR(IF(INDEX('DMIC List - master'!$Q:$Q,MATCH($B11,CONTRACT_ID,0)+5)="","",INDEX('DMIC List - master'!$Q:$Q,MATCH($B11,CONTRACT_ID,0)+5)),"") | I11: =IFERROR(IF(INDEX('DMIC List - master'!$U:$U,MATCH($B11,CONTRACT_ID,0)+5)="","",INDEX('DMIC List - master'!$U:$U,MATCH($B11,CONTRACT_ID,0)+5)),"") | K11: =IFERROR(IF(OR($B11="",COUNTA(INDEX('Competency&Complexity'!$K:$K,MATCH($B11,CC_CONTRACT_ID,0)+5):INDEX('Competency&Complexity'!$P:$P,MATCH($B11,CC_CONTRACT_ID,0)+5))=0),"",ROUND((COUNTIF(INDEX('Competency&Complexity'!$K:$K,MATCH($B11,CC_CONTRACT_ID,0)+5):INDEX('Competency&Complexity'!$P:$P,MATCH($B11,CC_CONTRACT_ID,0)+5),"High")*2+COUNTIF(INDEX('Competency&Complexity'!$K:$K,MATCH($B11,CC_CONTRACT_ID,0)+5):INDEX('Competency&Complexity'!$P:$P,MATCH($B11,CC_CONTRACT_ID,0)+5),"Medium")*1)/12*10,1)),"") | L11: =IFERROR(IF(OR($B11="",COUNTA(INDEX('Competency&Complexity'!$R:$R,MATCH($B11,CC_CONTRACT_ID,0)+5):INDEX('Competency&Complexity'!$V:$V,MATCH($B11,CC_CONTRACT_ID,0)+5))=0),"",ROUND((COUNTIF(INDEX('Competency&Complexity'!$R:$R,MATCH($B11,CC_CONTRACT_ID,0)+5):INDEX('Competency&Complexity'!$V:$V,MATCH($B11,CC_CONTRACT_ID,0)+5),"Low")*2+COUNTIF(INDEX('Competency&Complexity'!$R:$R,MATCH($B11,CC_CONTRACT_ID,0)+5):INDEX('Competency&Complexity'!$V:$V,MATCH($B11,CC_CONTRACT_ID,0)+5),"Medium")*1)/10*10,1)),"") | U11: =IF($B11="","",IF(COUNT(Q11:T11)=0,"",(Q11+R11+S11+T11)/20)) | Z11: {=IFERROR(TEXTJOIN(", ",TRUE,IF(Systems!$B$6:$B$65=$B11,Systems!$C$6:$C$65,"")),"")}
B12: =IF('DMIC List - master'!B12="","",'DMIC List - master'!B12) | C12: =IFERROR(IF(INDEX('DMIC List - master'!$C:$C,MATCH($B12,CONTRACT_ID,0)+5)="","",INDEX('DMIC List - master'!$C:$C,MATCH($B12,CONTRACT_ID,0)+5)),"") | D12: =IFERROR(IF(INDEX('DMIC List - master'!$D:$D,MATCH($B12,CONTRACT_ID,0)+5)="","",INDEX('DMIC List - master'!$D:$D,MATCH($B12,CONTRACT_ID,0)+5)),"") | E12: =IFERROR(IF(INDEX('DMIC List - master'!$E:$E,MATCH($B12,CONTRACT_ID,0)+5)="","",INDEX('DMIC List - master'!$E:$E,MATCH($B12,CONTRACT_ID,0)+5)),"") | G12: =IFERROR(IF(INDEX('DMIC List - master'!$P:$P,MATCH($B12,CONTRACT_ID,0)+5)="","",INDEX('DMIC List - master'!$P:$P,MATCH($B12,CONTRACT_ID,0)+5)),"") | H12: =IFERROR(IF(INDEX('DMIC List - master'!$Q:$Q,MATCH($B12,CONTRACT_ID,0)+5)="","",INDEX('DMIC List - master'!$Q:$Q,MATCH($B12,CONTRACT_ID,0)+5)),"") | I12: =IFERROR(IF(INDEX('DMIC List - master'!$U:$U,MATCH($B12,CONTRACT_ID,0)+5)="","",INDEX('DMIC List - master'!$U:$U,MATCH($B12,CONTRACT_ID,0)+5)),"") | K12: =IFERROR(IF(OR($B12="",COUNTA(INDEX('Competency&Complexity'!$K:$K,MATCH($B12,CC_CONTRACT_ID,0)+5):INDEX('Competency&Complexity'!$P:$P,MATCH($B12,CC_CONTRACT_ID,0)+5))=0),"",ROUND((COUNTIF(INDEX('Competency&Complexity'!$K:$K,MATCH($B12,CC_CONTRACT_ID,0)+5):INDEX('Competency&Complexity'!$P:$P,MATCH($B12,CC_CONTRACT_ID,0)+5),"High")*2+COUNTIF(INDEX('Competency&Complexity'!$K:$K,MATCH($B12,CC_CONTRACT_ID,0)+5):INDEX('Competency&Complexity'!$P:$P,MATCH($B12,CC_CONTRACT_ID,0)+5),"Medium")*1)/12*10,1)),"") | L12: =IFERROR(IF(OR($B12="",COUNTA(INDEX('Competency&Complexity'!$R:$R,MATCH($B12,CC_CONTRACT_ID,0)+5):INDEX('Competency&Complexity'!$V:$V,MATCH($B12,CC_CONTRACT_ID,0)+5))=0),"",ROUND((COUNTIF(INDEX('Competency&Complexity'!$R:$R,MATCH($B12,CC_CONTRACT_ID,0)+5):INDEX('Competency&Complexity'!$V:$V,MATCH($B12,CC_CONTRACT_ID,0)+5),"Low")*2+COUNTIF(INDEX('Competency&Complexity'!$R:$R,MATCH($B12,CC_CONTRACT_ID,0)+5):INDEX('Competency&Complexity'!$V:$V,MATCH($B12,CC_CONTRACT_ID,0)+5),"Medium")*1)/10*10,1)),"") | U12: =IF($B12="","",IF(COUNT(Q12:T12)=0,"",(Q12+R12+S12+T12)/20)) | Z12: {=IFERROR(TEXTJOIN(", ",TRUE,IF(Systems!$B$6:$B$65=$B12,Systems!$C$6:$C$65,"")),"")}
